Workbook

Sheet TW
B1: Fr | E1: Sa | H1: So | K1: Mo | N1: TW-Ges | O1: TW-BL | P1: TW-2L | Q1: 3er | R1: 2er | S1: 1er | T1: ZP
A2: Bächli | B2: =VALUE('34.TT'!$P$31) | D2: Bächli | E2: =VALUE('34.TT'!$P$33) | G2: Bächli | H2: =VALUE('34.TT'!$P$35) | J2: Bächli | K2: =VALUE('34.TT'!$P$37) | M2: Bächli | N2: =VALUE('34.TT'!Q39)+T2 | O2: =VALUE('34.TT'!N39) | P2: =VALUE('34.TT'!O39) | Q2: =COUNTIF('34.TT'!P6:P26,3) | R2: =COUNTIF('34.TT'!P6:P26,2) | S2: =COUNTIF('34.TT'!P6:P26,1)
A3: Bene | B3: =VALUE('34.TT'!$V$31) | D3: Bene | E3: =VALUE('34.TT'!$V$33) | G3: Bene | H3: =VALUE('34.TT'!$V$35) | J3: Bene | K3: =VALUE('34.TT'!$V$37) | M3: Bene | N3: =VALUE('34.TT'!W39)+T3 | O3: =VALUE('34.TT'!T39) | P3: =VALUE('34.TT'!U39) | Q3: =COUNTIF('34.TT'!V6:V26,3) | R3: =COUNTIF('34.TT'!V6:V26,2) | S3: =COUNTIF('34.TT'!V6:V26,1)
A4: Boller | B4: =VALUE('34.TT'!$AB$31) | D4: Boller | E4: =VALUE('34.TT'!$AB$33) | G4: Boller | H4: =VALUE('34.TT'!$AB$35) | J4: Boller | K4: =VALUE('34.TT'!$AB$37) | M4: Boller | N4: =VALUE('34.TT'!AC39)+T4 | O4: =VALUE('34.TT'!Z39) | P4: =VALUE('34.TT'!AA39) | Q4: =COUNTIF('34.TT'!AB6:AB26,3) | R4: =COUNTIF('34.TT'!AB6:AB26,2) | S4: =COUNTIF('34.TT'!AB6:AB26,1)
A5: Bussi | B5: =VALUE('34.TT'!$AH$31) | D5: Bussi | E5: =VALUE('34.TT'!$AH$33) | G5: Bussi | H5: =VALUE('34.TT'!$AH$35) | J5: Bussi | K5: =VALUE('34.TT'!$AH$37) | M5: Bussi | N5: =VALUE('34.TT'!AI39)+T5 | O5: =VALUE('34.TT'!AF39) | P5: =VALUE('34.TT'!AG39) | Q5: =COUNTIF('34.TT'!AH6:AH26,3) | R5: =COUNTIF('34.TT'!AH6:AH26,2) | S5: =COUNTIF('34.TT'!AH6:AH26,1)
A6: Christkind | B6: =VALUE('34.TT'!$AN$31) | D6: Christkind | E6: =VALUE('34.TT'!$AN$33) | G6: Christkind | H6: =VALUE('34.TT'!$AN$35) | J6: Christkind | K6: =VALUE('34.TT'!$AN$37) | M6: Christkind | N6: =VALUE('34.TT'!AO39)+T6 | O6: =VALUE('34.TT'!AL39) | P6: =VALUE('34.TT'!AM39) | Q6: =COUNTIF('34.TT'!AN6:AN26,3) | R6: =COUNTIF('34.TT'!AN6:AN26,2) | S6: =COUNTIF('34.TT'!AN6:AN26,1)
A7: Cordoba | B7: =VALUE('34.TT'!$AT$31) | D7: Cordoba | E7: =VALUE('34.TT'!$AT$33) | G7: Cordoba | H7: =VALUE('34.TT'!$AT$35) | J7: Cordoba | K7: =VALUE('34.TT'!$AT$37) | M7: Cordoba | N7: =VALUE('34.TT'!AU39)+T7 | O7: =VALUE('34.TT'!AR39) | P7: =VALUE('34.TT'!AS39) | Q7: =COUNTIF('34.TT'!AT6:AT26,3) | R7: =COUNTIF('34.TT'!AT6:AT26,2) | S7: =COUNTIF('34.TT'!AT6:AT26,1)
A8: Dellinger | B8: =VALUE('34.TT'!$AZ$31) | D8: Dellinger | E8: =VALUE('34.TT'!$AZ$33) | G8: Dellinger | H8: =VALUE('34.TT'!$AZ$35) | J8: Dellinger | K8: =VALUE('34.TT'!$AZ$37) | M8: Dellinger | N8: =VALUE('34.TT'!BA39)+T8 | O8: =VALUE('34.TT'!AX39) | P8: =VALUE('34.TT'!AY39) | Q8: =COUNTIF('34.TT'!AZ6:AZ26,3) | R8: =COUNTIF('34.TT'!AZ6:AZ26,2) | S8: =COUNTIF('34.TT'!AZ6:AZ26,1)
A9: DerHanseat | B9: =VALUE('34.TT'!$BF$31) | D9: DerHanseat | E9: =VALUE('34.TT'!$BF$33) | G9: DerHanseat | H9: =VALUE('34.TT'!$BF$35) | J9: DerHanseat | K9: =VALUE('34.TT'!$BF$37) | M9: DerHanseat | N9: =VALUE('34.TT'!BG39)+T9 | O9: =VALUE('34.TT'!BD39) | P9: =VALUE('34.TT'!BE39) | Q9: =COUNTIF('34.TT'!BF6:BF26,3) | R9: =COUNTIF('34.TT'!BF6:BF26,2) | S9: =COUNTIF('34.TT'!BF6:BF26,1)
A10: Dr. Rock | B10: =VALUE('34.TT'!$BL$31) | D10: Dr. Rock | E10: =VALUE('34.TT'!$BL$33) | G10: Dr. Rock | H10: =VALUE('34.TT'!$BL$35) | J10: Dr. Rock | K10: =VALUE('34.TT'!$BL$37) | M10: Dr. Rock | N10: =VALUE('34.TT'!BM39)+T10 | O10: =VALUE('34.TT'!BJ39) | P10: =VALUE('34.TT'!BK39) | Q10: =COUNTIF('34.TT'!BL6:BL26,3) | R10: =COUNTIF('34.TT'!BL6:BL26,2) | S10: =COUNTIF('34.TT'!BL6:BL26,1)
A11: Effe | B11: =VALUE('34.TT'!$BR$31) | D11: Effe | E11: =VALUE('34.TT'!$BR$33) | G11: Effe | H11: =VALUE('34.TT'!$BR$35) | J11: Effe | K11: =VALUE('34.TT'!$BR$37) | M11: Effe | N11: =VALUE('34.TT'!BS39)+T11 | O11: =VALUE('34.TT'!BP39) | P11: =VALUE('34.TT'!BQ39) | Q11: =COUNTIF('34.TT'!BR6:BR26,3) | R11: =COUNTIF('34.TT'!BR6:BR26,2) | S11: =COUNTIF('34.TT'!BR6:BR26,1)
A12: Ernst | B12: =VALUE('34.TT'!$BX$31) | D12: Ernst | E12: =VALUE('34.TT'!$BX$33) | G12: Ernst | H12: =VALUE('34.TT'!$BX$35) | J12: Ernst | K12: =VALUE('34.TT'!$BX$37) | M12: Ernst | N12: =VALUE('34.TT'!BY39)+T12 | O12: =VALUE('34.TT'!BV39) | P12: =VALUE('34.TT'!BW39) | Q12: =COUNTIF('34.TT'!BX6:BX26,3) | R12: =COUNTIF('34.TT'!BX6:BX26,2) | S12: =COUNTIF('34.TT'!BX6:BX26,1)
A13: Fips | B13: =VALUE('34.TT'!$CD$31) | D13: Fips | E13: =VALUE('34.TT'!$CD$33) | G13: Fips | H13: =VALUE('34.TT'!$CD$35) | J13: Fips | K13: =VALUE('34.TT'!$CD$37) | M13: Fips | N13: =VALUE('34.TT'!CE39)+T13 | O13: =VALUE('34.TT'!CB39) | P13: =VALUE('34.TT'!CC39) | Q13: =COUNTIF('34.TT'!CD6:CD26,3) | R13: =COUNTIF('34.TT'!CD6:CD26,2) | S13: =COUNTIF('34.TT'!CD6:CD26,1)
A14: Flipp | B14: =VALUE('34.TT'!$CJ$31) | D14: Flipp | E14: =VALUE('34.TT'!$CJ$33) | G14: Flipp | H14: =VALUE('34.TT'!$CJ$35) | J14: Flipp | K14: =VALUE('34.TT'!$CJ$37) | M14: Flipp | N14: =VALUE('34.TT'!CK39)+T14 | O14: =VALUE('34.TT'!CH39) | P14: =VALUE('34.TT'!CI39) | Q14: =COUNTIF('34.TT'!CJ6:CJ26,3) | R14: =COUNTIF('34.TT'!CJ6:CJ26,2) | S14: =COUNTIF('34.TT'!CJ6:CJ26,1)
A15: Focker | B15: =VALUE('34.TT'!$CP$31) | D15: Focker | E15: =VALUE('34.TT'!$CP$33) | G15: Focker | H15: =VALUE('34.TT'!$CP$35) | J15: Focker | K15: =VALUE('34.TT'!$CP$37) | M15: Focker | N15: =VALUE('34.TT'!CQ39)+T15 | O15: =VALUE('34.TT'!CN39) | P15: =VALUE('34.TT'!CO39) | Q15: =COUNTIF('34.TT'!CP6:CP26,3) | R15: =COUNTIF('34.TT'!CP6:CP26,2) | S15: =COUNTIF('34.TT'!CP6:CP26,1)
A16: Gazelle | B16: =VALUE('34.TT'!$CV$31) | D16: Gazelle | E16: =VALUE('34.TT'!$CV$33) | G16: Gazelle | H16: =VALUE('34.TT'!$CV$35) | J16: Gazelle | K16: =VALUE('34.TT'!$CV$37) | M16: Gazelle | N16: =VALUE('34.TT'!CW39)+T16 | O16: =VALUE('34.TT'!CT39) | P16: =VALUE('34.TT'!CU39) | Q16: =COUNTIF('34.TT'!CV6:CV26,3) | R16: =COUNTIF('34.TT'!CV6:CV26,2) | S16: =COUNTIF('34.TT'!CV6:CV26,1)
A17: Highländer | B17: =VALUE('34.TT'!$DB$31) | D17: Highländer | E17: =VALUE('34.TT'!$DB$33) | G17: Highländer | H17: =VALUE('34.TT'!$DB$35) | J17: Highländer | K17: =VALUE('34.TT'!$DB$37) | M17: Highländer | N17: =VALUE('34.TT'!DC39)+T17 | O17: =VALUE('34.TT'!CZ39) | P17: =VALUE('34.TT'!DA39) | Q17: =COUNTIF('34.TT'!DB6:DB26,3) | R17: =COUNTIF('34.TT'!DB6:DB26,2) | S17: =COUNTIF('34.TT'!DB6:DB26,1)
A18: Hoeness | B18: =VALUE('34.TT'!$DH$31) | D18: Hoeness | E18: =VALUE('34.TT'!$DH$33) | G18: Hoeness | H18: =VALUE('34.TT'!$DH$35) | J18: Hoeness | K18: =VALUE('34.TT'!$DH$37) | M18: Hoeness | N18: =VALUE('34.TT'!DI39)+T18 | O18: =VALUE('34.TT'!DF39) | P18: =VALUE('34.TT'!DG39) | Q18: =COUNTIF('34.TT'!DH6:DH26,3) | R18: =COUNTIF('34.TT'!DH6:DH26,2) | S18: =COUNTIF('34.TT'!DH6:DH26,1)
A19: Jay-Jay | B19: =VALUE('34.TT'!$DN$31) | D19: Jay-Jay | E19: =VALUE('34.TT'!$DN$33) | G19: Jay-Jay | H19: =VALUE('34.TT'!$DN$35) | J19: Jay-Jay | K19: =VALUE('34.TT'!$DN$37) | M19: Jay-Jay | N19: =VALUE('34.TT'!DO39)+T19 | O19: =VALUE('34.TT'!DL39) | P19: =VALUE('34.TT'!DM39) | Q19: =COUNTIF('34.TT'!DN6:DN26,3) | R19: =COUNTIF('34.TT'!DN6:DN26,2) | S19: =COUNTIF('34.TT'!DN6:DN26,1)
A20: Jukkel | B20: =VALUE('34.TT'!$DT$31) | D20: Jukkel | E20: =VALUE('34.TT'!$DT$33) | G20: Jukkel | H20: =VALUE('34.TT'!$DT$35) | J20: Jukkel | K20: =VALUE('34.TT'!$DT$37) | M20: Jukkel | N20: =VALUE('34.TT'!DU39)+T20 | O20: =VALUE('34.TT'!DR39) | P20: =VALUE('34.TT'!DS39) | Q20: =COUNTIF('34.TT'!DT6:DT26,3) | R20: =COUNTIF('34.TT'!DT6:DT26,2) | S20: =COUNTIF('34.TT'!DT6:DT26,1)
A21: kl.Schalke | B21: =VALUE('34.TT'!$DZ$31) | D21: kl.Schalke | E21: =VALUE('34.TT'!$DZ$33) | G21: kl.Schalke | H21: =VALUE('34.TT'!$DZ$35) | J21: kl.Schalke | K21: =VALUE('34.TT'!$DZ$37) | M21: kl.Schalke | N21: =VALUE('34.TT'!EA39)+T21 | O21: =VALUE('34.TT'!DX39) | P21: =VALUE('34.TT'!DY39) | Q21: =COUNTIF('34.TT'!DZ6:DZ26,3) | R21: =COUNTIF('34.TT'!DZ6:DZ26,2) | S21: =COUNTIF('34.TT'!DZ6:DZ26,1)
A22: Marilyn | B22: =VALUE('34.TT'!$EF$31) | D22: Marilyn | E22: =VALUE('34.TT'!$EF$33) | G22: Marilyn | H22: =VALUE('34.TT'!$EF$35) | J22: Marilyn | K22: =VALUE('34.TT'!$EF$37) | M22: Marilyn | N22: =VALUE('34.TT'!EG39)+T22 | O22: =VALUE('34.TT'!ED39) | P22: =VALUE('34.TT'!EE39) | Q22: =COUNTIF('34.TT'!EF6:EF26,3) | R22: =COUNTIF('34.TT'!EF6:EF26,2) | S22: =COUNTIF('34.TT'!EF6:EF26,1)
A23: Mazinho | B23: =VALUE('34.TT'!$EL$31) | D23: Mazinho | E23: =VALUE('34.TT'!$EL$33) | G23: Mazinho | H23: =VALUE('34.TT'!$EL$35) | J23: Mazinho | K23: =VALUE('34.TT'!$EL$37) | M23: Mazinho | N23: =VALUE('34.TT'!EM39)+T23 | O23: =VALUE('34.TT'!EJ39) | P23: =VALUE('34.TT'!EK39) | Q23: =COUNTIF('34.TT'!EL6:EL26,3) | R23: =COUNTIF('34.TT'!EL6:EL26,2) | S23: =COUNTIF('34.TT'!EL6:EL26,1)
A24: Parzival | B24: =VALUE('34.TT'!$ER$31) | D24: Parzival | E24: =VALUE('34.TT'!$ER$33) | G24: Parzival | H24: =VALUE('34.TT'!$ER$35) | J24: Parzival | K24: =VALUE('34.TT'!$ER$37) | M24: Parzival | N24: =VALUE('34.TT'!ES39)+T24 | O24: =VALUE('34.TT'!EP39) | P24: =VALUE('34.TT'!EQ39) | Q24: =COUNTIF('34.TT'!ER6:ER26,3) | R24: =COUNTIF('34.TT'!ER6:ER26,2) | S24: =COUNTIF('34.TT'!ER6:ER26,1)
A25: Rammway | B25: =VALUE('34.TT'!$EX$31) | D25: Rammway | E25: =VALUE('34.TT'!$EX$33) | G25: Rammway | H25: =VALUE('34.TT'!$EX$35) | J25: Rammway | K25: =VALUE('34.TT'!$EX$37) | M25: Rammway | N25: =VALUE('34.TT'!EY39)+T25 | O25: =VALUE('34.TT'!EV39) | P25: =VALUE('34.TT'!EW39) | Q25: =COUNTIF('34.TT'!EX6:EX26,3) | R25: =COUNTIF('34.TT'!EX6:EX26,2) | S25: =COUNTIF('34.TT'!EX6:EX26,1)
A26: Richy | B26: =VALUE('34.TT'!$FD$31) | D26: Richy | E26: =VALUE('34.TT'!$FD$33) | G26: Richy | H26: =VALUE('34.TT'!$FD$35) | J26: Richy | K26: =VALUE('34.TT'!$FD$37) | M26: Richy | N26: =VALUE('34.TT'!FE39)+T26 | O26: =VALUE('34.TT'!FB39) | P26: =VALUE('34.TT'!FC39) | Q26: =COUNTIF('34.TT'!FD6:FD26,3) | R26: =COUNTIF('34.TT'!FD6:FD26,2) | S26: =COUNTIF('34.TT'!FD6:FD26,1)
A27: Romax | B27: =VALUE('34.TT'!$FJ$31) | D27: Romax | E27: =VALUE('34.TT'!$FJ$33) | G27: Romax | H27: =VALUE('34.TT'!$FJ$35) | J27: Romax | K27: =VALUE('34.TT'!$FJ$37) | M27: Romax | N27: =VALUE('34.TT'!FK39)+T27 | O27: =VALUE('34.TT'!FH39) | P27: =VALUE('34.TT'!FI39) | Q27: =COUNTIF('34.TT'!FJ6:FJ26,3) | R27: =COUNTIF('34.TT'!FJ6:FJ26,2) | S27: =COUNTIF('34.TT'!FJ6:FJ26,1)
A28: Rörup | B28: =VALUE('34.TT'!$FP$31) | D28: Rörup | E28: =VALUE('34.TT'!$FP$33) | G28: Rörup | H28: =VALUE('34.TT'!$FP$35) | J28: Rörup | K28: =VALUE('34.TT'!$FP$37) | M28: Rörup | N28: =VALUE('34.TT'!FQ39)+T28 | O28: =VALUE('34.TT'!FN39) | P28: =VALUE('34.TT'!FO39) | Q28: =COUNTIF('34.TT'!FP6:FP26,3) | R28: =COUNTIF('34.TT'!FP6:FP26,2) | S28: =COUNTIF('34.TT'!FP6:FP26,1)
A29: Snake | B29: =VALUE('34.TT'!$FV$31) | D29: Snake | E29: =VALUE('34.TT'!$FV$33) | G29: Snake | H29: =VALUE('34.TT'!$FV$35) | J29: Snake | K29: =VALUE('34.TT'!$FV$37) | M29: Snake | N29: =VALUE('34.TT'!FW39)+T29 | O29: =VALUE('34.TT'!FT39) | P29: =VALUE('34.TT'!FU39) | Q29: =COUNTIF('34.TT'!FV6:FV26,3) | R29: =COUNTIF('34.TT'!FV6:FV26,2) | S29: =COUNTIF('34.TT'!FV6:FV26,1)
A30: Underduck | B30: =VALUE('34.TT'!$GB$31) | D30: Underduck | E30: =VALUE('34.TT'!$GB$33) | G30: Underduck | H30: =VALUE('34.TT'!$GB$35) | J30: Underduck | K30: =VALUE('34.TT'!$GB$37) | M30: Underduck | N30: =VALUE('34.TT'!GC39)+T30 | O30: =VALUE('34.TT'!FZ39) | P30: =VALUE('34.TT'!GA39) | Q30: =COUNTIF('34.TT'!GB6:GB26,3) | R30: =COUNTIF('34.TT'!GB6:GB26,2) | S30: =COUNTIF('34.TT'!GB6:GB26,1)
A31: Willi60 | B31: =VALUE('34.TT'!$GH$31) | D31: Willi60 | E31: =VALUE('34.TT'!$GH$33) | G31: Willi60 | H31: =VALUE('34.TT'!$GH$35) | J31: Willi60 | K31: =VALUE('34.TT'!$GH$37) | M31: Willi60 | N31: =VALUE('34.TT'!GI39)+T31 | O31: =VALUE('34.TT'!GF39) | P31: =VALUE('34.TT'!GG39) | Q31: =COUNTIF('34.TT'!GH6:GH26,3) | R31: =COUNTIF('34.TT'!GH6:GH26,2) | S31: =COUNTIF('34.TT'!GH6:GH26,1)
A32: Yeti | B32: =VALUE('34.TT'!$GN$31) | D32: Yeti | E32: =VALUE('34.TT'!$GN$33) | G32: Yeti | H32: =VALUE('34.TT'!$GN$35) | J32: Yeti | K32: =VALUE('34.TT'!$GN$37) | M32: Yeti | N32: =VALUE('34.TT'!GO39)+T32 | O32: =VALUE('34.TT'!GL39) | P32: =VALUE('34.TT'!GM39) | Q32: =COUNTIF('34.TT'!GN6:GN26,3) | R32: =COUNTIF('34.TT'!GN6:GN26,2) | S32: =COUNTIF('34.TT'!GN6:GN26,1)
A33: Yves | B33: =VALUE('34.TT'!$GT$31) | D33: Yves | E33: =VALUE('34.TT'!$GT$33) | G33: Yves | H33: =VALUE('34.TT'!$GT$35) | J33: Yves | K33: =VALUE('34.TT'!$GT37) | M33: Yves | N33: =VALUE('34.TT'!GU39)+T33 | O33: =VALUE('34.TT'!GR39) | P33: =VALUE('34.TT'!GS39) | Q33: =COUNTIF('34.TT'!GT6:GT26,3) | R33: =COUNTIF('34.TT'!GT6:GT26,2) | S33: =COUNTIF('34.TT'!GT6:GT26,1)
B34: =SUM(B2:B33) | E34: =SUM(E2:E33) | H34: =SUM(H2:H33) | K34: =SUM(K2:K33) | N34: =SUM(N2:N33) | O34: =SUM(O2:O33) | P34: =SUM(P2:P33) | Q34: =SUM(Q2:Q33) | R34: =SUM(R2:R33) | S34: =SUM(S2:S33)
B35: =(B34/32) | E35: =(E34/32) | H35: =(H34/32) | K35: =(K34/32) | N35: =(N34/32) | O35: =(O34/32) | P35: =(P34/32) | Q35: =(Q34/32) | R35: =(R34/32) | S35: =(S34/32)
N37: Zusatzpunkte händisch hier eintragen

Sheet 34.TT
B1: 34.TT
B3: 16.05. - 17.05. | D3: Name: | N3: Bächli | T3: Bene | Z3: Boller | AF3: Bussi | AL3: Christkind | AR3: Cordoba | AX3: Dellinger | BD3: derHanseat | BJ3: Dr. Rock | BP3: Effe | BV3: Ernst | CB3: Fips | CH3: Flipp | CN3: Focker | CT3: Gazelle | CZ3: Highländer | DF3: Hoeness | DL3: Jay-Jay | DR3: Jukkel | DX3: kl.Schalke | ED3: Marilyn | EJ3: Mazinho | EP3: Parzival | EV3: Rammway | FB3: Richy | FH3: Romax | FN3: Rörup | FT3: Snake | FZ3: Underduck | GF3: Willi60 | GL3: Yeti | GR3: Yves
B5: 1. Liga | D5: 34. Spieltag | E5: Ergeb. | I5: 3er | J5: 2er | K5: 1er | M5: Tipp | P5: Pkt. | S5: Tipp | V5: Pkt. | Y5: Tipp | AB5: Pkt. | AE5: Tipp | AH5: Pkt. | AK5: Tipp | AN5: Pkt. | AQ5: Tipp | AT5: Pkt. | AW5: Tipp | AZ5: Pkt. | BC5: Tipp | BF5: Pkt. | BI5: Tipp | BL5: Pkt. | BO5: Tipp | BR5: Pkt. | BU5: Tipp | BX5: Pkt. | CA5: Tipp | CD5: Pkt. | CG5: Tipp | CJ5: Pkt. | CM5: Tipp | CP5: Pkt. | CS5: Tipp | CV5: Pkt. | CY5: Tipp | DB5: Pkt. | DE5: Tipp | DH5: Pkt. | DK5: Tipp | DN5: Pkt. | DQ5: Tipp | DT5: Pkt. | DW5: Tipp | DZ5: Pkt. | EC5: Tipp | EF5: Pkt. | EI5: Tipp | EL5: Pkt. | EO5: Tipp | ER5: Pkt. | EU5: Tipp | EX5: Pkt. | FA5: Tipp | FD5: Pkt. | FG5: Tipp | FJ5: Pkt. | FM5: Tipp | FP5: Pkt. | FS5: Tipp | FV5: Pkt. | FY5: Tipp | GB5: Pkt. | GE5: Tipp | GH5: Pkt. | GK5: Tipp | GN5: Pkt. | GQ5: Tipp | GT5: Pkt.
C6: : | F6: : | I6: =COUNTIF(P6,3)+COUNTIF(V6,3)+COUNTIF(AB6,3)+COUNTIF(AH6,3)+COUNTIF(AN6,3)+COUNTIF(AT6,3)+COUNTIF(AZ6,3)+COUNTIF(BF6,3)+COUNTIF(BL6,3)+COUNTIF(BR6,3)+COUNTIF(BX6,3)+COUNTIF(CD6,3)+COUNTIF(CJ6,3)+COUNTIF(CP6,3)+COUNTIF(CV6,3)+COUNTIF(DB6,3)+COUNTIF(DH6,3)+COUNTIF(DN6,3)+COUNTIF(DT6,3)+COUNTIF(DZ6,3)+COUNTIF(EF6,3)+COUNTIF(EL6,3)+COUNTIF(ER6,3)+COUNTIF(EX6,3)+COUNTIF(FD6,3)+COUNTIF(FJ6,3)+COUNTIF(FP6,3)+COUNTIF(FV6,3)+COUNTIF(GB6,3)+COUNTIF(GH6,3)+COUNTIF(GN6,3)+COUNTIF(GT6,3) | J6: =COUNTIF(P6,2)+COUNTIF(V6,2)+COUNTIF(AB6,2)+COUNTIF(AH6,2)+COUNTIF(AN6,2)+COUNTIF(AT6,2)+COUNTIF(AZ6,2)+COUNTIF(BF6,2)+COUNTIF(BL6,2)+COUNTIF(BR6,2)+COUNTIF(BX6,2)+COUNTIF(CD6,2)+COUNTIF(CJ6,2)+COUNTIF(CP6,2)+COUNTIF(CV6,2)+COUNTIF(DB6,2)+COUNTIF(DH6,2)+COUNTIF(DN6,2)+COUNTIF(DT6,2)+COUNTIF(DZ6,2)+COUNTIF(EF6,2)+COUNTIF(EL6,2)+COUNTIF(ER6,2)+COUNTIF(EX6,2)+COUNTIF(FD6,2)+COUNTIF(FJ6,2)+COUNTIF(FP6,2)+COUNTIF(FV6,2)+COUNTIF(GB6,2)+COUNTIF(GH6,2)+COUNTIF(GN6,2)+COUNTIF(GT6,2) | K6: =COUNTIF(P6,1)+COUNTIF(V6,1)+COUNTIF(AB6,1)+COUNTIF(AH6,1)+COUNTIF(AN6,1)+COUNTIF(AT6,1)+COUNTIF(AZ6,1)+COUNTIF(BF6,1)+COUNTIF(BL6,1)+COUNTIF(BR6,1)+COUNTIF(BX6,1)+COUNTIF(CD6,1)+COUNTIF(CJ6,1)+COUNTIF(CP6,1)+COUNTIF(CV6,1)+COUNTIF(DB6,1)+COUNTIF(DH6,1)+COUNTIF(DN6,1)+COUNTIF(DT6,1)+COUNTIF(DZ6,1)+COUNTIF(EF6,1)+COUNTIF(EL6,1)+COUNTIF(ER6,1)+COUNTIF(EX6,1)+COUNTIF(FD6,1)+COUNTIF(FJ6,1)+COUNTIF(FP6,1)+COUNTIF(FV6,1)+COUNTIF(GB6,1)+COUNTIF(GH6,1)+COUNTIF(GN6,1)+COUNTIF(GT6,1) | N6: : | P6: =IF(ISBLANK($E6),"",(IF(ISBLANK(M6),0,IF((($E6=M6)*($G6=O6))*NOT(ISBLANK($E6)),1,0)+((($E6>$G6)*(M6>O6))+(($E6<$G6)*(M6<O6))+(($E6=$G6)*(M6=O6)))-ISBLANK($E6)*(M6=O6)+(($E6-$G6)=(M6-O6))))) | T6: : | V6: =IF(ISBLANK($E6),"",(IF(ISBLANK(S6),0,IF((($E6=S6)*($G6=U6))*NOT(ISBLANK($E6)),1,0)+((($E6>$G6)*(S6>U6))+(($E6<$G6)*(S6<U6))+(($E6=$G6)*(S6=U6)))-ISBLANK($E6)*(S6=U6)+(($E6-$G6)=(S6-U6))))) | Z6: : | AB6: =IF(ISBLANK($E6),"",(IF(ISBLANK(Y6),0,IF((($E6=Y6)*($G6=AA6))*NOT(ISBLANK($E6)),1,0)+((($E6>$G6)*(Y6>AA6))+(($E6<$G6)*(Y6<AA6))+(($E6=$G6)*(Y6=AA6)))-ISBLANK($E6)*(Y6=AA6)+(($E6-$G6)=(Y6-AA6))))) | AF6: : | AH6: =IF(ISBLANK($E6),"",(IF(ISBLANK(AE6),0,IF((($E6=AE6)*($G6=AG6))*NOT(ISBLANK($E6)),1,0)+((($E6>$G6)*(AE6>AG6))+(($E6<$G6)*(AE6<AG6))+(($E6=$G6)*(AE6=AG6)))-ISBLANK($E6)*(AE6=AG6)+(($E6-$G6)=(AE6-AG6))))) | AL6: : | AN6: =IF(ISBLANK($E6),"",(IF(ISBLANK(AK6),0,IF((($E6=AK6)*($G6=AM6))*NOT(ISBLANK($E6)),1,0)+((($E6>$G6)*(AK6>AM6))+(($E6<$G6)*(AK6<AM6))+(($E6=$G6)*(AK6=AM6)))-ISBLANK($E6)*(AK6=AM6)+(($E6-$G6)=(AK6-AM6))))) | AR6: : | AT6: =IF(ISBLANK($E6),"",(IF(ISBLANK(AQ6),0,IF((($E6=AQ6)*($G6=AS6))*NOT(ISBLANK($E6)),1,0)+((($E6>$G6)*(AQ6>AS6))+(($E6<$G6)*(AQ6<AS6))+(($E6=$G6)*(AQ6=AS6)))-ISBLANK($E6)*(AQ6=AS6)+(($E6-$G6)=(AQ6-AS6))))) | AX6: : | AZ6: =IF(ISBLANK($E6),"",(IF(ISBLANK(AW6),0,IF((($E6=AW6)*($G6=AY6))*NOT(ISBLANK($E6)),1,0)+((($E6>$G6)*(AW6>AY6))+(($E6<$G6)*(AW6<AY6))+(($E6=$G6)*(AW6=AY6)))-ISBLANK($E6)*(AW6=AY6)+(($E6-$G6)=(AW6-AY6))))) | BD6: : | BF6: =IF(ISBLANK($E6),"",(IF(ISBLANK(BC6),0,IF((($E6=BC6)*($G6=BE6))*NOT(ISBLANK($E6)),1,0)+((($E6>$G6)*(BC6>BE6))+(($E6<$G6)*(BC6<BE6))+(($E6=$G6)*(BC6=BE6)))-ISBLANK($E6)*(BC6=BE6)+(($E6-$G6)=(BC6-BE6))))) | BJ6: : | BL6: =IF(ISBLANK($E6),"",(IF(ISBLANK(BI6),0,IF((($E6=BI6)*($G6=BK6))*NOT(ISBLANK($E6)),1,0)+((($E6>$G6)*(BI6>BK6))+(($E6<$G6)*(BI6<BK6))+(($E6=$G6)*(BI6=BK6)))-ISBLANK($E6)*(BI6=BK6)+(($E6-$G6)=(BI6-BK6))))) | BP6: : | BR6: =IF(ISBLANK($E6),"",(IF(ISBLANK(BO6),0,IF((($E6=BO6)*($G6=BQ6))*NOT(ISBLANK($E6)),1,0)+((($E6>$G6)*(BO6>BQ6))+(($E6<$G6)*(BO6<BQ6))+(($E6=$G6)*(BO6=BQ6)))-ISBLANK($E6)*(BO6=BQ6)+(($E6-$G6)=(BO6-BQ6))))) | BV6: : | BX6: =IF(ISBLANK($E6),"",(IF(ISBLANK(BU6),0,IF((($E6=BU6)*($G6=BW6))*NOT(ISBLANK($E6)),1,0)+((($E6>$G6)*(BU6>BW6))+(($E6<$G6)*(BU6<BW6))+(($E6=$G6)*(BU6=BW6)))-ISBLANK($E6)*(BU6=BW6)+(($E6-$G6)=(BU6-BW6))))) | CB6: : | CD6: =IF(ISBLANK($E6),"",(IF(ISBLANK(CA6),0,IF((($E6=CA6)*($G6=CC6))*NOT(ISBLANK($E6)),1,0)+((($E6>$G6)*(CA6>CC6))+(($E6<$G6)*(CA6<CC6))+(($E6=$G6)*(CA6=CC6)))-ISBLANK($E6)*(CA6=CC6)+(($E6-$G6)=(CA6-CC6))))) | CH6: : | CJ6: =IF(ISBLANK($E6),"",(IF(ISBLANK(CG6),0,IF((($E6=CG6)*($G6=CI6))*NOT(ISBLANK($E6)),1,0)+((($E6>$G6)*(CG6>CI6))+(($E6<$G6)*(CG6<CI6))+(($E6=$G6)*(CG6=CI6)))-ISBLANK($E6)*(CG6=CI6)+(($E6-$G6)=(CG6-CI6))))) | CN6: : | CP6: =IF(ISBLANK($E6),"",(IF(ISBLANK(CM6),0,IF((($E6=CM6)*($G6=CO6))*NOT(ISBLANK($E6)),1,0)+((($E6>$G6)*(CM6>CO6))+(($E6<$G6)*(CM6<CO6))+(($E6=$G6)*(CM6=CO6)))-ISBLANK($E6)*(CM6=CO6)+(($E6-$G6)=(CM6-CO6))))) | CT6: : | CV6: =IF(ISBLANK($E6),"",(IF(ISBLANK(CS6),0,IF((($E6=CS6)*($G6=CU6))*NOT(ISBLANK($E6)),1,0)+((($E6>$G6)*(CS6>CU6))+(($E6<$G6)*(CS6<CU6))+(($E6=$G6)*(CS6=CU6)))-ISBLANK($E6)*(CS6=CU6)+(($E6-$G6)=(CS6-CU6))))) | CZ6: : | DB6: =IF(ISBLANK($E6),"",(IF(ISBLANK(CY6),0,IF((($E6=CY6)*($G6=DA6))*NOT(ISBLANK($E6)),1,0)+((($E6>$G6)*(CY6>DA6))+(($E6<$G6)*(CY6<DA6))+(($E6=$G6)*(CY6=DA6)))-ISBLANK($E6)*(CY6=DA6)+(($E6-$G6)=(CY6-DA6))))) | DF6: : | DH6: =IF(ISBLANK($E6),"",(IF(ISBLANK(DE6),0,IF((($E6=DE6)*($G6=DG6))*NOT(ISBLANK($E6)),1,0)+((($E6>$G6)*(DE6>DG6))+(($E6<$G6)*(DE6<DG6))+(($E6=$G6)*(DE6=DG6)))-ISBLANK($E6)*(DE6=DG6)+(($E6-$G6)=(DE6-DG6))))) | DL6: : | DN6: =IF(ISBLANK($E6),"",(IF(ISBLANK(DK6),0,IF((($E6=DK6)*($G6=DM6))*NOT(ISBLANK($E6)),1,0)+((($E6>$G6)*(DK6>DM6))+(($E6<$G6)*(DK6<DM6))+(($E6=$G6)*(DK6=DM6)))-ISBLANK($E6)*(DK6=DM6)+(($E6-$G6)=(DK6-DM6))))) | DR6: : | DT6: =IF(ISBLANK($E6),"",(IF(ISBLANK(DQ6),0,IF((($E6=DQ6)*($G6=DS6))*NOT(ISBLANK($E6)),1,0)+((($E6>$G6)*(DQ6>DS6))+(($E6<$G6)*(DQ6<DS6))+(($E6=$G6)*(DQ6=DS6)))-ISBLANK($E6)*(DQ6=DS6)+(($E6-$G6)=(DQ6-DS6))))) | DX6: : | DZ6: =IF(ISBLANK($E6),"",(IF(ISBLANK(DW6),0,IF((($E6=DW6)*($G6=DY6))*NOT(ISBLANK($E6)),1,0)+((($E6>$G6)*(DW6>DY6))+(($E6<$G6)*(DW6<DY6))+(($E6=$G6)*(DW6=DY6)))-ISBLANK($E6)*(DW6=DY6)+(($E6-$G6)=(DW6-DY6))))) | ED6: : | EF6: =IF(ISBLANK($E6),"",(IF(ISBLANK(EC6),0,IF((($E6=EC6)*($G6=EE6))*NOT(ISBLANK($E6)),1,0)+((($E6>$G6)*(EC6>EE6))+(($E6<$G6)*(EC6<EE6))+(($E6=$G6)*(EC6=EE6)))-ISBLANK($E6)*(EC6=EE6)+(($E6-$G6)=(EC6-EE6))))) | EJ6: : | EL6: =IF(ISBLANK($E6),"",(IF(ISBLANK(EI6),0,IF((($E6=EI6)*($G6=EK6))*NOT(ISBLANK($E6)),1,0)+((($E6>$G6)*(EI6>EK6))+(($E6<$G6)*(EI6<EK6))+(($E6=$G6)*(EI6=EK6)))-ISBLANK($E6)*(EI6=EK6)+(($E6-$G6)=(EI6-EK6))))) | EP6: : | ER6: =IF(ISBLANK($E6),"",(IF(ISBLANK(EO6),0,IF((($E6=EO6)*($G6=EQ6))*NOT(ISBLANK($E6)),1,0)+((($E6>$G6)*(EO6>EQ6))+(($E6<$G6)*(EO6<EQ6))+(($E6=$G6)*(EO6=EQ6)))-ISBLANK($E6)*(EO6=EQ6)+(($E6-$G6)=(EO6-EQ6))))) | EV6: : | EX6: =IF(ISBLANK($E6),"",(IF(ISBLANK(EU6),0,IF((($E6=EU6)*($G6=EW6))*NOT(ISBLANK($E6)),1,0)+((($E6>$G6)*(EU6>EW6))+(($E6<$G6)*(EU6<EW6))+(($E6=$G6)*(EU6=EW6)))-ISBLANK($E6)*(EU6=EW6)+(($E6-$G6)=(EU6-EW6))))) | FB6: : | FD6: =IF(ISBLANK($E6),"",(IF(ISBLANK(FA6),0,IF((($E6=FA6)*($G6=FC6))*NOT(ISBLANK($E6)),1,0)+((($E6>$G6)*(FA6>FC6))+(($E6<$G6)*(FA6<FC6))+(($E6=$G6)*(FA6=FC6)))-ISBLANK($E6)*(FA6=FC6)+(($E6-$G6)=(FA6-FC6))))) | FH6: : | FJ6: =IF(ISBLANK($E6),"",(IF(ISBLANK(FG6),0,IF((($E6=FG6)*($G6=FI6))*NOT(ISBLANK($E6)),1,0)+((($E6>$G6)*(FG6>FI6))+(($E6<$G6)*(FG6<FI6))+(($E6=$G6)*(FG6=FI6)))-ISBLANK($E6)*(FG6=FI6)+(($E6-$G6)=(FG6-FI6))))) | FN6: : | FP6: =IF(ISBLANK($E6),"",(IF(ISBLANK(FM6),0,IF((($E6=FM6)*($G6=FO6))*NOT(ISBLANK($E6)),1,0)+((($E6>$G6)*(FM6>FO6))+(($E6<$G6)*(FM6<FO6))+(($E6=$G6)*(FM6=FO6)))-ISBLANK($E6)*(FM6=FO6)+(($E6-$G6)=(FM6-FO6))))) | FT6: : | FV6: =IF(ISBLANK($E6),"",(IF(ISBLANK(FS6),0,IF((($E6=FS6)*($G6=FU6))*NOT(ISBLANK($E6)),1,0)+((($E6>$G6)*(FS6>FU6))+(($E6<$G6)*(FS6<FU6))+(($E6=$G6)*(FS6=FU6)))-ISBLANK($E6)*(FS6=FU6)+(($E6-$G6)=(FS6-FU6))))) | FZ6: : | GB6: =IF(ISBLANK($E6),"",(IF(ISBLANK(FY6),0,IF((($E6=FY6)*($G6=GA6))*NOT(ISBLANK($E6)),1,0)+((($E6>$G6)*(FY6>GA6))+(($E6<$G6)*(FY6<GA6))+(($E6=$G6)*(FY6=GA6)))-ISBLANK($E6)*(FY6=GA6)+(($E6-$G6)=(FY6-GA6))))) | GF6: : | GH6: =IF(ISBLANK($E6),"",(IF(ISBLANK(GE6),0,IF((($E6=GE6)*($G6=GG6))*NOT(ISBLANK($E6)),1,0)+((($E6>$G6)*(GE6>GG6))+(($E6<$G6)*(GE6<GG6))+(($E6=$G6)*(GE6=GG6)))-ISBLANK($E6)*(GE6=GG6)+(($E6-$G6)=(GE6-GG6))))) | GL6: : | GN6: =IF(ISBLANK($E6),"",(IF(ISBLANK(GK6),0,IF((($E6=GK6)*($G6=GM6))*NOT(ISBLANK($E6)),1,0)+((($E6>$G6)*(GK6>GM6))+(($E6<$G6)*(GK6<GM6))+(($E6=$G6)*(GK6=GM6)))-ISBLANK($E6)*(GK6=GM6)+(($E6-$G6)=(GK6-GM6))))) | GR6: : | GT6: =IF(ISBLANK($E6),"",(IF(ISBLANK(GQ6),0,IF((($E6=GQ6)*($G6=GS6))*NOT(ISBLANK($E6)),1,0)+((($E6>$G6)*(GQ6>GS6))+(($E6<$G6)*(GQ6<GS6))+(($E6=$G6)*(GQ6=GS6)))-ISBLANK($E6)*(GQ6=GS6)+(($E6-$G6)=(GQ6-GS6)))))
C7: : | F7: : | I7: =COUNTIF(P7,3)+COUNTIF(V7,3)+COUNTIF(AB7,3)+COUNTIF(AH7,3)+COUNTIF(AN7,3)+COUNTIF(AT7,3)+COUNTIF(AZ7,3)+COUNTIF(BF7,3)+COUNTIF(BL7,3)+COUNTIF(BR7,3)+COUNTIF(BX7,3)+COUNTIF(CD7,3)+COUNTIF(CJ7,3)+COUNTIF(CP7,3)+COUNTIF(CV7,3)+COUNTIF(DB7,3)+COUNTIF(DH7,3)+COUNTIF(DN7,3)+COUNTIF(DT7,3)+COUNTIF(DZ7,3)+COUNTIF(EF7,3)+COUNTIF(EL7,3)+COUNTIF(ER7,3)+COUNTIF(EX7,3)+COUNTIF(FD7,3)+COUNTIF(FJ7,3)+COUNTIF(FP7,3)+COUNTIF(FV7,3)+COUNTIF(GB7,3)+COUNTIF(GH7,3)+COUNTIF(GN7,3)+COUNTIF(GT7,3) | J7: =COUNTIF(P7,2)+COUNTIF(V7,2)+COUNTIF(AB7,2)+COUNTIF(AH7,2)+COUNTIF(AN7,2)+COUNTIF(AT7,2)+COUNTIF(AZ7,2)+COUNTIF(BF7,2)+COUNTIF(BL7,2)+COUNTIF(BR7,2)+COUNTIF(BX7,2)+COUNTIF(CD7,2)+COUNTIF(CJ7,2)+COUNTIF(CP7,2)+COUNTIF(CV7,2)+COUNTIF(DB7,2)+COUNTIF(DH7,2)+COUNTIF(DN7,2)+COUNTIF(DT7,2)+COUNTIF(DZ7,2)+COUNTIF(EF7,2)+COUNTIF(EL7,2)+COUNTIF(ER7,2)+COUNTIF(EX7,2)+COUNTIF(FD7,2)+COUNTIF(FJ7,2)+COUNTIF(FP7,2)+COUNTIF(FV7,2)+COUNTIF(GB7,2)+COUNTIF(GH7,2)+COUNTIF(GN7,2)+COUNTIF(GT7,2) | K7: =COUNTIF(P7,1)+COUNTIF(V7,1)+COUNTIF(AB7,1)+COUNTIF(AH7,1)+COUNTIF(AN7,1)+COUNTIF(AT7,1)+COUNTIF(AZ7,1)+COUNTIF(BF7,1)+COUNTIF(BL7,1)+COUNTIF(BR7,1)+COUNTIF(BX7,1)+COUNTIF(CD7,1)+COUNTIF(CJ7,1)+COUNTIF(CP7,1)+COUNTIF(CV7,1)+COUNTIF(DB7,1)+COUNTIF(DH7,1)+COUNTIF(DN7,1)+COUNTIF(DT7,1)+COUNTIF(DZ7,1)+COUNTIF(EF7,1)+COUNTIF(EL7,1)+COUNTIF(ER7,1)+COUNTIF(EX7,1)+COUNTIF(FD7,1)+COUNTIF(FJ7,1)+COUNTIF(FP7,1)+COUNTIF(FV7,1)+COUNTIF(GB7,1)+COUNTIF(GH7,1)+COUNTIF(GN7,1)+COUNTIF(GT7,1) | N7: : | P7: =IF(ISBLANK($E7),"",(IF(ISBLANK(M7),0,IF((($E7=M7)*($G7=O7))*NOT(ISBLANK($E7)),1,0)+((($E7>$G7)*(M7>O7))+(($E7<$G7)*(M7<O7))+(($E7=$G7)*(M7=O7)))-ISBLANK($E7)*(M7=O7)+(($E7-$G7)=(M7-O7))))) | T7: : | V7: =IF(ISBLANK($E7),"",(IF(ISBLANK(S7),0,IF((($E7=S7)*($G7=U7))*NOT(ISBLANK($E7)),1,0)+((($E7>$G7)*(S7>U7))+(($E7<$G7)*(S7<U7))+(($E7=$G7)*(S7=U7)))-ISBLANK($E7)*(S7=U7)+(($E7-$G7)=(S7-U7))))) | Z7: : | AB7: =IF(ISBLANK($E7),"",(IF(ISBLANK(Y7),0,IF((($E7=Y7)*($G7=AA7))*NOT(ISBLANK($E7)),1,0)+((($E7>$G7)*(Y7>AA7))+(($E7<$G7)*(Y7<AA7))+(($E7=$G7)*(Y7=AA7)))-ISBLANK($E7)*(Y7=AA7)+(($E7-$G7)=(Y7-AA7))))) | AF7: : | AH7: =IF(ISBLANK($E7),"",(IF(ISBLANK(AE7),0,IF((($E7=AE7)*($G7=AG7))*NOT(ISBLANK($E7)),1,0)+((($E7>$G7)*(AE7>AG7))+(($E7<$G7)*(AE7<AG7))+(($E7=$G7)*(AE7=AG7)))-ISBLANK($E7)*(AE7=AG7)+(($E7-$G7)=(AE7-AG7))))) | AL7: : | AN7: =IF(ISBLANK($E7),"",(IF(ISBLANK(AK7),0,IF((($E7=AK7)*($G7=AM7))*NOT(ISBLANK($E7)),1,0)+((($E7>$G7)*(AK7>AM7))+(($E7<$G7)*(AK7<AM7))+(($E7=$G7)*(AK7=AM7)))-ISBLANK($E7)*(AK7=AM7)+(($E7-$G7)=(AK7-AM7))))) | AR7: : | AT7: =IF(ISBLANK($E7),"",(IF(ISBLANK(AQ7),0,IF((($E7=AQ7)*($G7=AS7))*NOT(ISBLANK($E7)),1,0)+((($E7>$G7)*(AQ7>AS7))+(($E7<$G7)*(AQ7<AS7))+(($E7=$G7)*(AQ7=AS7)))-ISBLANK($E7)*(AQ7=AS7)+(($E7-$G7)=(AQ7-AS7))))) | AX7: : | AZ7: =IF(ISBLANK($E7),"",(IF(ISBLANK(AW7),0,IF((($E7=AW7)*($G7=AY7))*NOT(ISBLANK($E7)),1,0)+((($E7>$G7)*(AW7>AY7))+(($E7<$G7)*(AW7<AY7))+(($E7=$G7)*(AW7=AY7)))-ISBLANK($E7)*(AW7=AY7)+(($E7-$G7)=(AW7-AY7))))) | BD7: : | BF7: =IF(ISBLANK($E7),"",(IF(ISBLANK(BC7),0,IF((($E7=BC7)*($G7=BE7))*NOT(ISBLANK($E7)),1,0)+((($E7>$G7)*(BC7>BE7))+(($E7<$G7)*(BC7<BE7))+(($E7=$G7)*(BC7=BE7)))-ISBLANK($E7)*(BC7=BE7)+(($E7-$G7)=(BC7-BE7))))) | BJ7: : | BL7: =IF(ISBLANK($E7),"",(IF(ISBLANK(BI7),0,IF((($E7=BI7)*($G7=BK7))*NOT(ISBLANK($E7)),1,0)+((($E7>$G7)*(BI7>BK7))+(($E7<$G7)*(BI7<BK7))+(($E7=$G7)*(BI7=BK7)))-ISBLANK($E7)*(BI7=BK7)+(($E7-$G7)=(BI7-BK7))))) | BP7: : | BR7: =IF(ISBLANK($E7),"",(IF(ISBLANK(BO7),0,IF((($E7=BO7)*($G7=BQ7))*NOT(ISBLANK($E7)),1,0)+((($E7>$G7)*(BO7>BQ7))+(($E7<$G7)*(BO7<BQ7))+(($E7=$G7)*(BO7=BQ7)))-ISBLANK($E7)*(BO7=BQ7)+(($E7-$G7)=(BO7-BQ7))))) | BV7: : | BX7: =IF(ISBLANK($E7),"",(IF(ISBLANK(BU7),0,IF((($E7=BU7)*($G7=BW7))*NOT(ISBLANK($E7)),1,0)+((($E7>$G7)*(BU7>BW7))+(($E7<$G7)*(BU7<BW7))+(($E7=$G7)*(BU7=BW7)))-ISBLANK($E7)*(BU7=BW7)+(($E7-$G7)=(BU7-BW7))))) | CB7: : | CD7: =IF(ISBLANK($E7),"",(IF(ISBLANK(CA7),0,IF((($E7=CA7)*($G7=CC7))*NOT(ISBLANK($E7)),1,0)+((($E7>$G7)*(CA7>CC7))+(($E7<$G7)*(CA7<CC7))+(($E7=$G7)*(CA7=CC7)))-ISBLANK($E7)*(CA7=CC7)+(($E7-$G7)=(CA7-CC7))))) | CH7: : | CJ7: =IF(ISBLANK($E7),"",(IF(ISBLANK(CG7),0,IF((($E7=CG7)*($G7=CI7))*NOT(ISBLANK($E7)),1,0)+((($E7>$G7)*(CG7>CI7))+(($E7<$G7)*(CG7<CI7))+(($E7=$G7)*(CG7=CI7)))-ISBLANK($E7)*(CG7=CI7)+(($E7-$G7)=(CG7-CI7))))) | CN7: : | CP7: =IF(ISBLANK($E7),"",(IF(ISBLANK(CM7),0,IF((($E7=CM7)*($G7=CO7))*NOT(ISBLANK($E7)),1,0)+((($E7>$G7)*(CM7>CO7))+(($E7<$G7)*(CM7<CO7))+(($E7=$G7)*(CM7=CO7)))-ISBLANK($E7)*(CM7=CO7)+(($E7-$G7)=(CM7-CO7))))) | CT7: : | CV7: =IF(ISBLANK($E7),"",(IF(ISBLANK(CS7),0,IF((($E7=CS7)*($G7=CU7))*NOT(ISBLANK($E7)),1,0)+((($E7>$G7)*(CS7>CU7))+(($E7<$G7)*(CS7<CU7))+(($E7=$G7)*(CS7=CU7)))-ISBLANK($E7)*(CS7=CU7)+(($E7-$G7)=(CS7-CU7))))) | CZ7: : | DB7: =IF(ISBLANK($E7),"",(IF(ISBLANK(CY7),0,IF((($E7=CY7)*($G7=DA7))*NOT(ISBLANK($E7)),1,0)+((($E7>$G7)*(CY7>DA7))+(($E7<$G7)*(CY7<DA7))+(($E7=$G7)*(CY7=DA7)))-ISBLANK($E7)*(CY7=DA7)+(($E7-$G7)=(CY7-DA7))))) | DF7: : | DH7: =IF(ISBLANK($E7),"",(IF(ISBLANK(DE7),0,IF((($E7=DE7)*($G7=DG7))*NOT(ISBLANK($E7)),1,0)+((($E7>$G7)*(DE7>DG7))+(($E7<$G7)*(DE7<DG7))+(($E7=$G7)*(DE7=DG7)))-ISBLANK($E7)*(DE7=DG7)+(($E7-$G7)=(DE7-DG7))))) | DL7: : | DN7: =IF(ISBLANK($E7),"",(IF(ISBLANK(DK7),0,IF((($E7=DK7)*($G7=DM7))*NOT(ISBLANK($E7)),1,0)+((($E7>$G7)*(DK7>DM7))+(($E7<$G7)*(DK7<DM7))+(($E7=$G7)*(DK7=DM7)))-ISBLANK($E7)*(DK7=DM7)+(($E7-$G7)=(DK7-DM7))))) | DR7: : | DT7: =IF(ISBLANK($E7),"",(IF(ISBLANK(DQ7),0,IF((($E7=DQ7)*($G7=DS7))*NOT(ISBLANK($E7)),1,0)+((($E7>$G7)*(DQ7>DS7))+(($E7<$G7)*(DQ7<DS7))+(($E7=$G7)*(DQ7=DS7)))-ISBLANK($E7)*(DQ7=DS7)+(($E7-$G7)=(DQ7-DS7))))) | DX7: : | DZ7: =IF(ISBLANK($E7),"",(IF(ISBLANK(DW7),0,IF((($E7=DW7)*($G7=DY7))*NOT(ISBLANK($E7)),1,0)+((($E7>$G7)*(DW7>DY7))+(($E7<$G7)*(DW7<DY7))+(($E7=$G7)*(DW7=DY7)))-ISBLANK($E7)*(DW7=DY7)+(($E7-$G7)=(DW7-DY7))))) | ED7: : | EF7: =IF(ISBLANK($E7),"",(IF(ISBLANK(EC7),0,IF((($E7=EC7)*($G7=EE7))*NOT(ISBLANK($E7)),1,0)+((($E7>$G7)*(EC7>EE7))+(($E7<$G7)*(EC7<EE7))+(($E7=$G7)*(EC7=EE7)))-ISBLANK($E7)*(EC7=EE7)+(($E7-$G7)=(EC7-EE7))))) | EJ7: : | EL7: =IF(ISBLANK($E7),"",(IF(ISBLANK(EI7),0,IF((($E7=EI7)*($G7=EK7))*NOT(ISBLANK($E7)),1,0)+((($E7>$G7)*(EI7>EK7))+(($E7<$G7)*(EI7<EK7))+(($E7=$G7)*(EI7=EK7)))-ISBLANK($E7)*(EI7=EK7)+(($E7-$G7)=(EI7-EK7))))) | EP7: : | ER7: =IF(ISBLANK($E7),"",(IF(ISBLANK(EO7),0,IF((($E7=EO7)*($G7=EQ7))*NOT(ISBLANK($E7)),1,0)+((($E7>$G7)*(EO7>EQ7))+(($E7<$G7)*(EO7<EQ7))+(($E7=$G7)*(EO7=EQ7)))-ISBLANK($E7)*(EO7=EQ7)+(($E7-$G7)=(EO7-EQ7))))) | EV7: : | EX7: =IF(ISBLANK($E7),"",(IF(ISBLANK(EU7),0,IF((($E7=EU7)*($G7=EW7))*NOT(ISBLANK($E7)),1,0)+((($E7>$G7)*(EU7>EW7))+(($E7<$G7)*(EU7<EW7))+(($E7=$G7)*(EU7=EW7)))-ISBLANK($E7)*(EU7=EW7)+(($E7-$G7)=(EU7-EW7))))) | FB7: : | FD7: =IF(ISBLANK($E7),"",(IF(ISBLANK(FA7),0,IF((($E7=FA7)*($G7=FC7))*NOT(ISBLANK($E7)),1,0)+((($E7>$G7)*(FA7>FC7))+(($E7<$G7)*(FA7<FC7))+(($E7=$G7)*(FA7=FC7)))-ISBLANK($E7)*(FA7=FC7)+(($E7-$G7)=(FA7-FC7))))) | FH7: : | FJ7: =IF(ISBLANK($E7),"",(IF(ISBLANK(FG7),0,IF((($E7=FG7)*($G7=FI7))*NOT(ISBLANK($E7)),1,0)+((($E7>$G7)*(FG7>FI7))+(($E7<$G7)*(FG7<FI7))+(($E7=$G7)*(FG7=FI7)))-ISBLANK($E7)*(FG7=FI7)+(($E7-$G7)=(FG7-FI7))))) | FN7: : | FP7: =IF(ISBLANK($E7),"",(IF(ISBLANK(FM7),0,IF((($E7=FM7)*($G7=FO7))*NOT(ISBLANK($E7)),1,0)+((($E7>$G7)*(FM7>FO7))+(($E7<$G7)*(FM7<FO7))+(($E7=$G7)*(FM7=FO7)))-ISBLANK($E7)*(FM7=FO7)+(($E7-$G7)=(FM7-FO7))))) | FT7: : | FV7: =IF(ISBLANK($E7),"",(IF(ISBLANK(FS7),0,IF((($E7=FS7)*($G7=FU7))*NOT(ISBLANK($E7)),1,0)+((($E7>$G7)*(FS7>FU7))+(($E7<$G7)*(FS7<FU7))+(($E7=$G7)*(FS7=FU7)))-ISBLANK($E7)*(FS7=FU7)+(($E7-$G7)=(FS7-FU7))))) | FZ7: : | GB7: =IF(ISBLANK($E7),"",(IF(ISBLANK(FY7),0,IF((($E7=FY7)*($G7=GA7))*NOT(ISBLANK($E7)),1,0)+((($E7>$G7)*(FY7>GA7))+(($E7<$G7)*(FY7<GA7))+(($E7=$G7)*(FY7=GA7)))-ISBLANK($E7)*(FY7=GA7)+(($E7-$G7)=(FY7-GA7))))) | GF7: : | GH7: =IF(ISBLANK($E7),"",(IF(ISBLANK(GE7),0,IF((($E7=GE7)*($G7=GG7))*NOT(ISBLANK($E7)),1,0)+((($E7>$G7)*(GE7>GG7))+(($E7<$G7)*(GE7<GG7))+(($E7=$G7)*(GE7=GG7)))-ISBLANK($E7)*(GE7=GG7)+(($E7-$G7)=(GE7-GG7))))) | GL7: : | GN7: =IF(ISBLANK($E7),"",(IF(ISBLANK(GK7),0,IF((($E7=GK7)*($G7=GM7))*NOT(ISBLANK($E7)),1,0)+((($E7>$G7)*(GK7>GM7))+(($E7<$G7)*(GK7<GM7))+(($E7=$G7)*(GK7=GM7)))-ISBLANK($E7)*(GK7=GM7)+(($E7-$G7)=(GK7-GM7))))) | GR7: : | GT7: =IF(ISBLANK($E7),"",(IF(ISBLANK(GQ7),0,IF((($E7=GQ7)*($G7=GS7))*NOT(ISBLANK($E7)),1,0)+((($E7>$G7)*(GQ7>GS7))+(($E7<$G7)*(GQ7<GS7))+(($E7=$G7)*(GQ7=GS7)))-ISBLANK($E7)*(GQ7=GS7)+(($E7-$G7)=(GQ7-GS7)))))
C8: : | F8: : | I8: =COUNTIF(P8,3)+COUNTIF(V8,3)+COUNTIF(AB8,3)+COUNTIF(AH8,3)+COUNTIF(AN8,3)+COUNTIF(AT8,3)+COUNTIF(AZ8,3)+COUNTIF(BF8,3)+COUNTIF(BL8,3)+COUNTIF(BR8,3)+COUNTIF(BX8,3)+COUNTIF(CD8,3)+COUNTIF(CJ8,3)+COUNTIF(CP8,3)+COUNTIF(CV8,3)+COUNTIF(DB8,3)+COUNTIF(DH8,3)+COUNTIF(DN8,3)+COUNTIF(DT8,3)+COUNTIF(DZ8,3)+COUNTIF(EF8,3)+COUNTIF(EL8,3)+COUNTIF(ER8,3)+COUNTIF(EX8,3)+COUNTIF(FD8,3)+COUNTIF(FJ8,3)+COUNTIF(FP8,3)+COUNTIF(FV8,3)+COUNTIF(GB8,3)+COUNTIF(GH8,3)+COUNTIF(GN8,3)+COUNTIF(GT8,3) | J8: =COUNTIF(P8,2)+COUNTIF(V8,2)+COUNTIF(AB8,2)+COUNTIF(AH8,2)+COUNTIF(AN8,2)+COUNTIF(AT8,2)+COUNTIF(AZ8,2)+COUNTIF(BF8,2)+COUNTIF(BL8,2)+COUNTIF(BR8,2)+COUNTIF(BX8,2)+COUNTIF(CD8,2)+COUNTIF(CJ8,2)+COUNTIF(CP8,2)+COUNTIF(CV8,2)+COUNTIF(DB8,2)+COUNTIF(DH8,2)+COUNTIF(DN8,2)+COUNTIF(DT8,2)+COUNTIF(DZ8,2)+COUNTIF(EF8,2)+COUNTIF(EL8,2)+COUNTIF(ER8,2)+COUNTIF(EX8,2)+COUNTIF(FD8,2)+COUNTIF(FJ8,2)+COUNTIF(FP8,2)+COUNTIF(FV8,2)+COUNTIF(GB8,2)+COUNTIF(GH8,2)+COUNTIF(GN8,2)+COUNTIF(GT8,2) | K8: =COUNTIF(P8,1)+COUNTIF(V8,1)+COUNTIF(AB8,1)+COUNTIF(AH8,1)+COUNTIF(AN8,1)+COUNTIF(AT8,1)+COUNTIF(AZ8,1)+COUNTIF(BF8,1)+COUNTIF(BL8,1)+COUNTIF(BR8,1)+COUNTIF(BX8,1)+COUNTIF(CD8,1)+COUNTIF(CJ8,1)+COUNTIF(CP8,1)+COUNTIF(CV8,1)+COUNTIF(DB8,1)+COUNTIF(DH8,1)+COUNTIF(DN8,1)+COUNTIF(DT8,1)+COUNTIF(DZ8,1)+COUNTIF(EF8,1)+COUNTIF(EL8,1)+COUNTIF(ER8,1)+COUNTIF(EX8,1)+COUNTIF(FD8,1)+COUNTIF(FJ8,1)+COUNTIF(FP8,1)+COUNTIF(FV8,1)+COUNTIF(GB8,1)+COUNTIF(GH8,1)+COUNTIF(GN8,1)+COUNTIF(GT8,1) | N8: : | P8: =IF(ISBLANK($E8),"",(IF(ISBLANK(M8),0,IF((($E8=M8)*($G8=O8))*NOT(ISBLANK($E8)),1,0)+((($E8>$G8)*(M8>O8))+(($E8<$G8)*(M8<O8))+(($E8=$G8)*(M8=O8)))-ISBLANK($E8)*(M8=O8)+(($E8-$G8)=(M8-O8))))) | T8: : | V8: =IF(ISBLANK($E8),"",(IF(ISBLANK(S8),0,IF((($E8=S8)*($G8=U8))*NOT(ISBLANK($E8)),1,0)+((($E8>$G8)*(S8>U8))+(($E8<$G8)*(S8<U8))+(($E8=$G8)*(S8=U8)))-ISBLANK($E8)*(S8=U8)+(($E8-$G8)=(S8-U8))))) | Z8: : | AB8: =IF(ISBLANK($E8),"",(IF(ISBLANK(Y8),0,IF((($E8=Y8)*($G8=AA8))*NOT(ISBLANK($E8)),1,0)+((($E8>$G8)*(Y8>AA8))+(($E8<$G8)*(Y8<AA8))+(($E8=$G8)*(Y8=AA8)))-ISBLANK($E8)*(Y8=AA8)+(($E8-$G8)=(Y8-AA8))))) | AF8: : | AH8: =IF(ISBLANK($E8),"",(IF(ISBLANK(AE8),0,IF((($E8=AE8)*($G8=AG8))*NOT(ISBLANK($E8)),1,0)+((($E8>$G8)*(AE8>AG8))+(($E8<$G8)*(AE8<AG8))+(($E8=$G8)*(AE8=AG8)))-ISBLANK($E8)*(AE8=AG8)+(($E8-$G8)=(AE8-AG8))))) | AL8: : | AN8: =IF(ISBLANK($E8),"",(IF(ISBLANK(AK8),0,IF((($E8=AK8)*($G8=AM8))*NOT(ISBLANK($E8)),1,0)+((($E8>$G8)*(AK8>AM8))+(($E8<$G8)*(AK8<AM8))+(($E8=$G8)*(AK8=AM8)))-ISBLANK($E8)*(AK8=AM8)+(($E8-$G8)=(AK8-AM8))))) | AR8: : | AT8: =IF(ISBLANK($E8),"",(IF(ISBLANK(AQ8),0,IF((($E8=AQ8)*($G8=AS8))*NOT(ISBLANK($E8)),1,0)+((($E8>$G8)*(AQ8>AS8))+(($E8<$G8)*(AQ8<AS8))+(($E8=$G8)*(AQ8=AS8)))-ISBLANK($E8)*(AQ8=AS8)+(($E8-$G8)=(AQ8-AS8))))) | AX8: : | AZ8: =IF(ISBLANK($E8),"",(IF(ISBLANK(AW8),0,IF((($E8=AW8)*($G8=AY8))*NOT(ISBLANK($E8)),1,0)+((($E8>$G8)*(AW8>AY8))+(($E8<$G8)*(AW8<AY8))+(($E8=$G8)*(AW8=AY8)))-ISBLANK($E8)*(AW8=AY8)+(($E8-$G8)=(AW8-AY8))))) | BD8: : | BF8: =IF(ISBLANK($E8),"",(IF(ISBLANK(BC8),0,IF((($E8=BC8)*($G8=BE8))*NOT(ISBLANK($E8)),1,0)+((($E8>$G8)*(BC8>BE8))+(($E8<$G8)*(BC8<BE8))+(($E8=$G8)*(BC8=BE8)))-ISBLANK($E8)*(BC8=BE8)+(($E8-$G8)=(BC8-BE8))))) | BJ8: : | BL8: =IF(ISBLANK($E8),"",(IF(ISBLANK(BI8),0,IF((($E8=BI8)*($G8=BK8))*NOT(ISBLANK($E8)),1,0)+((($E8>$G8)*(BI8>BK8))+(($E8<$G8)*(BI8<BK8))+(($E8=$G8)*(BI8=BK8)))-ISBLANK($E8)*(BI8=BK8)+(($E8-$G8)=(BI8-BK8))))) | BP8: : | BR8: =IF(ISBLANK($E8),"",(IF(ISBLANK(BO8),0,IF((($E8=BO8)*($G8=BQ8))*NOT(ISBLANK($E8)),1,0)+((($E8>$G8)*(BO8>BQ8))+(($E8<$G8)*(BO8<BQ8))+(($E8=$G8)*(BO8=BQ8)))-ISBLANK($E8)*(BO8=BQ8)+(($E8-$G8)=(BO8-BQ8))))) | BV8: : | BX8: =IF(ISBLANK($E8),"",(IF(ISBLANK(BU8),0,IF((($E8=BU8)*($G8=BW8))*NOT(ISBLANK($E8)),1,0)+((($E8>$G8)*(BU8>BW8))+(($E8<$G8)*(BU8<BW8))+(($E8=$G8)*(BU8=BW8)))-ISBLANK($E8)*(BU8=BW8)+(($E8-$G8)=(BU8-BW8))))) | CB8: : | CD8: =IF(ISBLANK($E8),"",(IF(ISBLANK(CA8),0,IF((($E8=CA8)*($G8=CC8))*NOT(ISBLANK($E8)),1,0)+((($E8>$G8)*(CA8>CC8))+(($E8<$G8)*(CA8<CC8))+(($E8=$G8)*(CA8=CC8)))-ISBLANK($E8)*(CA8=CC8)+(($E8-$G8)=(CA8-CC8))))) | CH8: : | CJ8: =IF(ISBLANK($E8),"",(IF(ISBLANK(CG8),0,IF((($E8=CG8)*($G8=CI8))*NOT(ISBLANK($E8)),1,0)+((($E8>$G8)*(CG8>CI8))+(($E8<$G8)*(CG8<CI8))+(($E8=$G8)*(CG8=CI8)))-ISBLANK($E8)*(CG8=CI8)+(($E8-$G8)=(CG8-CI8))))) | CN8: : | CP8: =IF(ISBLANK($E8),"",(IF(ISBLANK(CM8),0,IF((($E8=CM8)*($G8=CO8))*NOT(ISBLANK($E8)),1,0)+((($E8>$G8)*(CM8>CO8))+(($E8<$G8)*(CM8<CO8))+(($E8=$G8)*(CM8=CO8)))-ISBLANK($E8)*(CM8=CO8)+(($E8-$G8)=(CM8-CO8))))) | CT8: : | CV8: =IF(ISBLANK($E8),"",(IF(ISBLANK(CS8),0,IF((($E8=CS8)*($G8=CU8))*NOT(ISBLANK($E8)),1,0)+((($E8>$G8)*(CS8>CU8))+(($E8<$G8)*(CS8<CU8))+(($E8=$G8)*(CS8=CU8)))-ISBLANK($E8)*(CS8=CU8)+(($E8-$G8)=(CS8-CU8))))) | CZ8: : | DB8: =IF(ISBLANK($E8),"",(IF(ISBLANK(CY8),0,IF((($E8=CY8)*($G8=DA8))*NOT(ISBLANK($E8)),1,0)+((($E8>$G8)*(CY8>DA8))+(($E8<$G8)*(CY8<DA8))+(($E8=$G8)*(CY8=DA8)))-ISBLANK($E8)*(CY8=DA8)+(($E8-$G8)=(CY8-DA8))))) | DF8: : | DH8: =IF(ISBLANK($E8),"",(IF(ISBLANK(DE8),0,IF((($E8=DE8)*($G8=DG8))*NOT(ISBLANK($E8)),1,0)+((($E8>$G8)*(DE8>DG8))+(($E8<$G8)*(DE8<DG8))+(($E8=$G8)*(DE8=DG8)))-ISBLANK($E8)*(DE8=DG8)+(($E8-$G8)=(DE8-DG8))))) | DL8: : | DN8: =IF(ISBLANK($E8),"",(IF(ISBLANK(DK8),0,IF((($E8=DK8)*($G8=DM8))*NOT(ISBLANK($E8)),1,0)+((($E8>$G8)*(DK8>DM8))+(($E8<$G8)*(DK8<DM8))+(($E8=$G8)*(DK8=DM8)))-ISBLANK($E8)*(DK8=DM8)+(($E8-$G8)=(DK8-DM8))))) | DR8: : | DT8: =IF(ISBLANK($E8),"",(IF(ISBLANK(DQ8),0,IF((($E8=DQ8)*($G8=DS8))*NOT(ISBLANK($E8)),1,0)+((($E8>$G8)*(DQ8>DS8))+(($E8<$G8)*(DQ8<DS8))+(($E8=$G8)*(DQ8=DS8)))-ISBLANK($E8)*(DQ8=DS8)+(($E8-$G8)=(DQ8-DS8))))) | DX8: : | DZ8: =IF(ISBLANK($E8),"",(IF(ISBLANK(DW8),0,IF((($E8=DW8)*($G8=DY8))*NOT(ISBLANK($E8)),1,0)+((($E8>$G8)*(DW8>DY8))+(($E8<$G8)*(DW8<DY8))+(($E8=$G8)*(DW8=DY8)))-ISBLANK($E8)*(DW8=DY8)+(($E8-$G8)=(DW8-DY8))))) | ED8: : | EF8: =IF(ISBLANK($E8),"",(IF(ISBLANK(EC8),0,IF((($E8=EC8)*($G8=EE8))*NOT(ISBLANK($E8)),1,0)+((($E8>$G8)*(EC8>EE8))+(($E8<$G8)*(EC8<EE8))+(($E8=$G8)*(EC8=EE8)))-ISBLANK($E8)*(EC8=EE8)+(($E8-$G8)=(EC8-EE8))))) | EJ8: : | EL8: =IF(ISBLANK($E8),"",(IF(ISBLANK(EI8),0,IF((($E8=EI8)*($G8=EK8))*NOT(ISBLANK($E8)),1,0)+((($E8>$G8)*(EI8>EK8))+(($E8<$G8)*(EI8<EK8))+(($E8=$G8)*(EI8=EK8)))-ISBLANK($E8)*(EI8=EK8)+(($E8-$G8)=(EI8-EK8))))) | EP8: : | ER8: =IF(ISBLANK($E8),"",(IF(ISBLANK(EO8),0,IF((($E8=EO8)*($G8=EQ8))*NOT(ISBLANK($E8)),1,0)+((($E8>$G8)*(EO8>EQ8))+(($E8<$G8)*(EO8<EQ8))+(($E8=$G8)*(EO8=EQ8)))-ISBLANK($E8)*(EO8=EQ8)+(($E8-$G8)=(EO8-EQ8))))) | EV8: : | EX8: =IF(ISBLANK($E8),"",(IF(ISBLANK(EU8),0,IF((($E8=EU8)*($G8=EW8))*NOT(ISBLANK($E8)),1,0)+((($E8>$G8)*(EU8>EW8))+(($E8<$G8)*(EU8<EW8))+(($E8=$G8)*(EU8=EW8)))-ISBLANK($E8)*(EU8=EW8)+(($E8-$G8)=(EU8-EW8))))) | FB8: : | FD8: =IF(ISBLANK($E8),"",(IF(ISBLANK(FA8),0,IF((($E8=FA8)*($G8=FC8))*NOT(ISBLANK($E8)),1,0)+((($E8>$G8)*(FA8>FC8))+(($E8<$G8)*(FA8<FC8))+(($E8=$G8)*(FA8=FC8)))-ISBLANK($E8)*(FA8=FC8)+(($E8-$G8)=(FA8-FC8))))) | FH8: : | FJ8: =IF(ISBLANK($E8),"",(IF(ISBLANK(FG8),0,IF((($E8=FG8)*($G8=FI8))*NOT(ISBLANK($E8)),1,0)+((($E8>$G8)*(FG8>FI8))+(($E8<$G8)*(FG8<FI8))+(($E8=$G8)*(FG8=FI8)))-ISBLANK($E8)*(FG8=FI8)+(($E8-$G8)=(FG8-FI8))))) | FN8: : | FP8: =IF(ISBLANK($E8),"",(IF(ISBLANK(FM8),0,IF((($E8=FM8)*($G8=FO8))*NOT(ISBLANK($E8)),1,0)+((($E8>$G8)*(FM8>FO8))+(($E8<$G8)*(FM8<FO8))+(($E8=$G8)*(FM8=FO8)))-ISBLANK($E8)*(FM8=FO8)+(($E8-$G8)=(FM8-FO8))))) | FT8: : | FV8: =IF(ISBLANK($E8),"",(IF(ISBLANK(FS8),0,IF((($E8=FS8)*($G8=FU8))*NOT(ISBLANK($E8)),1,0)+((($E8>$G8)*(FS8>FU8))+(($E8<$G8)*(FS8<FU8))+(($E8=$G8)*(FS8=FU8)))-ISBLANK($E8)*(FS8=FU8)+(($E8-$G8)=(FS8-FU8))))) | FZ8: : | GB8: =IF(ISBLANK($E8),"",(IF(ISBLANK(FY8),0,IF((($E8=FY8)*($G8=GA8))*NOT(ISBLANK($E8)),1,0)+((($E8>$G8)*(FY8>GA8))+(($E8<$G8)*(FY8<GA8))+(($E8=$G8)*(FY8=GA8)))-ISBLANK($E8)*(FY8=GA8)+(($E8-$G8)=(FY8-GA8))))) | GF8: : | GH8: =IF(ISBLANK($E8),"",(IF(ISBLANK(GE8),0,IF((($E8=GE8)*($G8=GG8))*NOT(ISBLANK($E8)),1,0)+((($E8>$G8)*(GE8>GG8))+(($E8<$G8)*(GE8<GG8))+(($E8=$G8)*(GE8=GG8)))-ISBLANK($E8)*(GE8=GG8)+(($E8-$G8)=(GE8-GG8))))) | GL8: : | GN8: =IF(ISBLANK($E8),"",(IF(ISBLANK(GK8),0,IF((($E8=GK8)*($G8=GM8))*NOT(ISBLANK($E8)),1,0)+((($E8>$G8)*(GK8>GM8))+(($E8<$G8)*(GK8<GM8))+(($E8=$G8)*(GK8=GM8)))-ISBLANK($E8)*(GK8=GM8)+(($E8-$G8)=(GK8-GM8))))) | GR8: : | GT8: =IF(ISBLANK($E8),"",(IF(ISBLANK(GQ8),0,IF((($E8=GQ8)*($G8=GS8))*NOT(ISBLANK($E8)),1,0)+((($E8>$G8)*(GQ8>GS8))+(($E8<$G8)*(GQ8<GS8))+(($E8=$G8)*(GQ8=GS8)))-ISBLANK($E8)*(GQ8=GS8)+(($E8-$G8)=(GQ8-GS8)))))
C9: : | F9: : | I9: =COUNTIF(P9,3)+COUNTIF(V9,3)+COUNTIF(AB9,3)+COUNTIF(AH9,3)+COUNTIF(AN9,3)+COUNTIF(AT9,3)+COUNTIF(AZ9,3)+COUNTIF(BF9,3)+COUNTIF(BL9,3)+COUNTIF(BR9,3)+COUNTIF(BX9,3)+COUNTIF(CD9,3)+COUNTIF(CJ9,3)+COUNTIF(CP9,3)+COUNTIF(CV9,3)+COUNTIF(DB9,3)+COUNTIF(DH9,3)+COUNTIF(DN9,3)+COUNTIF(DT9,3)+COUNTIF(DZ9,3)+COUNTIF(EF9,3)+COUNTIF(EL9,3)+COUNTIF(ER9,3)+COUNTIF(EX9,3)+COUNTIF(FD9,3)+COUNTIF(FJ9,3)+COUNTIF(FP9,3)+COUNTIF(FV9,3)+COUNTIF(GB9,3)+COUNTIF(GH9,3)+COUNTIF(GN9,3)+COUNTIF(GT9,3) | J9: =COUNTIF(P9,2)+COUNTIF(V9,2)+COUNTIF(AB9,2)+COUNTIF(AH9,2)+COUNTIF(AN9,2)+COUNTIF(AT9,2)+COUNTIF(AZ9,2)+COUNTIF(BF9,2)+COUNTIF(BL9,2)+COUNTIF(BR9,2)+COUNTIF(BX9,2)+COUNTIF(CD9,2)+COUNTIF(CJ9,2)+COUNTIF(CP9,2)+COUNTIF(CV9,2)+COUNTIF(DB9,2)+COUNTIF(DH9,2)+COUNTIF(DN9,2)+COUNTIF(DT9,2)+COUNTIF(DZ9,2)+COUNTIF(EF9,2)+COUNTIF(EL9,2)+COUNTIF(ER9,2)+COUNTIF(EX9,2)+COUNTIF(FD9,2)+COUNTIF(FJ9,2)+COUNTIF(FP9,2)+COUNTIF(FV9,2)+COUNTIF(GB9,2)+COUNTIF(GH9,2)+COUNTIF(GN9,2)+COUNTIF(GT9,2) | K9: =COUNTIF(P9,1)+COUNTIF(V9,1)+COUNTIF(AB9,1)+COUNTIF(AH9,1)+COUNTIF(AN9,1)+COUNTIF(AT9,1)+COUNTIF(AZ9,1)+COUNTIF(BF9,1)+COUNTIF(BL9,1)+COUNTIF(BR9,1)+COUNTIF(BX9,1)+COUNTIF(CD9,1)+COUNTIF(CJ9,1)+COUNTIF(CP9,1)+COUNTIF(CV9,1)+COUNTIF(DB9,1)+COUNTIF(DH9,1)+COUNTIF(DN9,1)+COUNTIF(DT9,1)+COUNTIF(DZ9,1)+COUNTIF(EF9,1)+COUNTIF(EL9,1)+COUNTIF(ER9,1)+COUNTIF(EX9,1)+COUNTIF(FD9,1)+COUNTIF(FJ9,1)+COUNTIF(FP9,1)+COUNTIF(FV9,1)+COUNTIF(GB9,1)+COUNTIF(GH9,1)+COUNTIF(GN9,1)+COUNTIF(GT9,1) | N9: : | P9: =IF(ISBLANK($E9),"",(IF(ISBLANK(M9),0,IF((($E9=M9)*($G9=O9))*NOT(ISBLANK($E9)),1,0)+((($E9>$G9)*(M9>O9))+(($E9<$G9)*(M9<O9))+(($E9=$G9)*(M9=O9)))-ISBLANK($E9)*(M9=O9)+(($E9-$G9)=(M9-O9))))) | T9: : | V9: =IF(ISBLANK($E9),"",(IF(ISBLANK(S9),0,IF((($E9=S9)*($G9=U9))*NOT(ISBLANK($E9)),1,0)+((($E9>$G9)*(S9>U9))+(($E9<$G9)*(S9<U9))+(($E9=$G9)*(S9=U9)))-ISBLANK($E9)*(S9=U9)+(($E9-$G9)=(S9-U9))))) | Z9: : | AB9: =IF(ISBLANK($E9),"",(IF(ISBLANK(Y9),0,IF((($E9=Y9)*($G9=AA9))*NOT(ISBLANK($E9)),1,0)+((($E9>$G9)*(Y9>AA9))+(($E9<$G9)*(Y9<AA9))+(($E9=$G9)*(Y9=AA9)))-ISBLANK($E9)*(Y9=AA9)+(($E9-$G9)=(Y9-AA9))))) | AF9: : | AH9: =IF(ISBLANK($E9),"",(IF(ISBLANK(AE9),0,IF((($E9=AE9)*($G9=AG9))*NOT(ISBLANK($E9)),1,0)+((($E9>$G9)*(AE9>AG9))+(($E9<$G9)*(AE9<AG9))+(($E9=$G9)*(AE9=AG9)))-ISBLANK($E9)*(AE9=AG9)+(($E9-$G9)=(AE9-AG9))))) | AL9: : | AN9: =IF(ISBLANK($E9),"",(IF(ISBLANK(AK9),0,IF((($E9=AK9)*($G9=AM9))*NOT(ISBLANK($E9)),1,0)+((($E9>$G9)*(AK9>AM9))+(($E9<$G9)*(AK9<AM9))+(($E9=$G9)*(AK9=AM9)))-ISBLANK($E9)*(AK9=AM9)+(($E9-$G9)=(AK9-AM9))))) | AR9: : | AT9: =IF(ISBLANK($E9),"",(IF(ISBLANK(AQ9),0,IF((($E9=AQ9)*($G9=AS9))*NOT(ISBLANK($E9)),1,0)+((($E9>$G9)*(AQ9>AS9))+(($E9<$G9)*(AQ9<AS9))+(($E9=$G9)*(AQ9=AS9)))-ISBLANK($E9)*(AQ9=AS9)+(($E9-$G9)=(AQ9-AS9))))) | AX9: : | AZ9: =IF(ISBLANK($E9),"",(IF(ISBLANK(AW9),0,IF((($E9=AW9)*($G9=AY9))*NOT(ISBLANK($E9)),1,0)+((($E9>$G9)*(AW9>AY9))+(($E9<$G9)*(AW9<AY9))+(($E9=$G9)*(AW9=AY9)))-ISBLANK($E9)*(AW9=AY9)+(($E9-$G9)=(AW9-AY9))))) | BD9: : | BF9: =IF(ISBLANK($E9),"",(IF(ISBLANK(BC9),0,IF((($E9=BC9)*($G9=BE9))*NOT(ISBLANK($E9)),1,0)+((($E9>$G9)*(BC9>BE9))+(($E9<$G9)*(BC9<BE9))+(($E9=$G9)*(BC9=BE9)))-ISBLANK($E9)*(BC9=BE9)+(($E9-$G9)=(BC9-BE9))))) | BJ9: : | BL9: =IF(ISBLANK($E9),"",(IF(ISBLANK(BI9),0,IF((($E9=BI9)*($G9=BK9))*NOT(ISBLANK($E9)),1,0)+((($E9>$G9)*(BI9>BK9))+(($E9<$G9)*(BI9<BK9))+(($E9=$G9)*(BI9=BK9)))-ISBLANK($E9)*(BI9=BK9)+(($E9-$G9)=(BI9-BK9))))) | BP9: : | BR9: =IF(ISBLANK($E9),"",(IF(ISBLANK(BO9),0,IF((($E9=BO9)*($G9=BQ9))*NOT(ISBLANK($E9)),1,0)+((($E9>$G9)*(BO9>BQ9))+(($E9<$G9)*(BO9<BQ9))+(($E9=$G9)*(BO9=BQ9)))-ISBLANK($E9)*(BO9=BQ9)+(($E9-$G9)=(BO9-BQ9))))) | BV9: : | BX9: =IF(ISBLANK($E9),"",(IF(ISBLANK(BU9),0,IF((($E9=BU9)*($G9=BW9))*NOT(ISBLANK($E9)),1,0)+((($E9>$G9)*(BU9>BW9))+(($E9<$G9)*(BU9<BW9))+(($E9=$G9)*(BU9=BW9)))-ISBLANK($E9)*(BU9=BW9)+(($E9-$G9)=(BU9-BW9))))) | CB9: : | CD9: =IF(ISBLANK($E9),"",(IF(ISBLANK(CA9),0,IF((($E9=CA9)*($G9=CC9))*NOT(ISBLANK($E9)),1,0)+((($E9>$G9)*(CA9>CC9))+(($E9<$G9)*(CA9<CC9))+(($E9=$G9)*(CA9=CC9)))-ISBLANK($E9)*(CA9=CC9)+(($E9-$G9)=(CA9-CC9))))) | CH9: : | CJ9: =IF(ISBLANK($E9),"",(IF(ISBLANK(CG9),0,IF((($E9=CG9)*($G9=CI9))*NOT(ISBLANK($E9)),1,0)+((($E9>$G9)*(CG9>CI9))+(($E9<$G9)*(CG9<CI9))+(($E9=$G9)*(CG9=CI9)))-ISBLANK($E9)*(CG9=CI9)+(($E9-$G9)=(CG9-CI9))))) | CN9: : | CP9: =IF(ISBLANK($E9),"",(IF(ISBLANK(CM9),0,IF((($E9=CM9)*($G9=CO9))*NOT(ISBLANK($E9)),1,0)+((($E9>$G9)*(CM9>CO9))+(($E9<$G9)*(CM9<CO9))+(($E9=$G9)*(CM9=CO9)))-ISBLANK($E9)*(CM9=CO9)+(($E9-$G9)=(CM9-CO9))))) | CT9: : | CV9: =IF(ISBLANK($E9),"",(IF(ISBLANK(CS9),0,IF((($E9=CS9)*($G9=CU9))*NOT(ISBLANK($E9)),1,0)+((($E9>$G9)*(CS9>CU9))+(($E9<$G9)*(CS9<CU9))+(($E9=$G9)*(CS9=CU9)))-ISBLANK($E9)*(CS9=CU9)+(($E9-$G9)=(CS9-CU9))))) | CZ9: : | DB9: =IF(ISBLANK($E9),"",(IF(ISBLANK(CY9),0,IF((($E9=CY9)*($G9=DA9))*NOT(ISBLANK($E9)),1,0)+((($E9>$G9)*(CY9>DA9))+(($E9<$G9)*(CY9<DA9))+(($E9=$G9)*(CY9=DA9)))-ISBLANK($E9)*(CY9=DA9)+(($E9-$G9)=(CY9-DA9))))) | DF9: : | DH9: =IF(ISBLANK($E9),"",(IF(ISBLANK(DE9),0,IF((($E9=DE9)*($G9=DG9))*NOT(ISBLANK($E9)),1,0)+((($E9>$G9)*(DE9>DG9))+(($E9<$G9)*(DE9<DG9))+(($E9=$G9)*(DE9=DG9)))-ISBLANK($E9)*(DE9=DG9)+(($E9-$G9)=(DE9-DG9))))) | DL9: : | DN9: =IF(ISBLANK($E9),"",(IF(ISBLANK(DK9),0,IF((($E9=DK9)*($G9=DM9))*NOT(ISBLANK($E9)),1,0)+((($E9>$G9)*(DK9>DM9))+(($E9<$G9)*(DK9<DM9))+(($E9=$G9)*(DK9=DM9)))-ISBLANK($E9)*(DK9=DM9)+(($E9-$G9)=(DK9-DM9))))) | DR9: : | DT9: =IF(ISBLANK($E9),"",(IF(ISBLANK(DQ9),0,IF((($E9=DQ9)*($G9=DS9))*NOT(ISBLANK($E9)),1,0)+((($E9>$G9)*(DQ9>DS9))+(($E9<$G9)*(DQ9<DS9))+(($E9=$G9)*(DQ9=DS9)))-ISBLANK($E9)*(DQ9=DS9)+(($E9-$G9)=(DQ9-DS9))))) | DX9: : | DZ9: =IF(ISBLANK($E9),"",(IF(ISBLANK(DW9),0,IF((($E9=DW9)*($G9=DY9))*NOT(ISBLANK($E9)),1,0)+((($E9>$G9)*(DW9>DY9))+(($E9<$G9)*(DW9<DY9))+(($E9=$G9)*(DW9=DY9)))-ISBLANK($E9)*(DW9=DY9)+(($E9-$G9)=(DW9-DY9))))) | ED9: : | EF9: =IF(ISBLANK($E9),"",(IF(ISBLANK(EC9),0,IF((($E9=EC9)*($G9=EE9))*NOT(ISBLANK($E9)),1,0)+((($E9>$G9)*(EC9>EE9))+(($E9<$G9)*(EC9<EE9))+(($E9=$G9)*(EC9=EE9)))-ISBLANK($E9)*(EC9=EE9)+(($E9-$G9)=(EC9-EE9))))) | EJ9: : | EL9: =IF(ISBLANK($E9),"",(IF(ISBLANK(EI9),0,IF((($E9=EI9)*($G9=EK9))*NOT(ISBLANK($E9)),1,0)+((($E9>$G9)*(EI9>EK9))+(($E9<$G9)*(EI9<EK9))+(($E9=$G9)*(EI9=EK9)))-ISBLANK($E9)*(EI9=EK9)+(($E9-$G9)=(EI9-EK9))))) | EP9: : | ER9: =IF(ISBLANK($E9),"",(IF(ISBLANK(EO9),0,IF((($E9=EO9)*($G9=EQ9))*NOT(ISBLANK($E9)),1,0)+((($E9>$G9)*(EO9>EQ9))+(($E9<$G9)*(EO9<EQ9))+(($E9=$G9)*(EO9=EQ9)))-ISBLANK($E9)*(EO9=EQ9)+(($E9-$G9)=(EO9-EQ9))))) | EV9: : | EX9: =IF(ISBLANK($E9),"",(IF(ISBLANK(EU9),0,IF((($E9=EU9)*($G9=EW9))*NOT(ISBLANK($E9)),1,0)+((($E9>$G9)*(EU9>EW9))+(($E9<$G9)*(EU9<EW9))+(($E9=$G9)*(EU9=EW9)))-ISBLANK($E9)*(EU9=EW9)+(($E9-$G9)=(EU9-EW9))))) | FB9: : | FD9: =IF(ISBLANK($E9),"",(IF(ISBLANK(FA9),0,IF((($E9=FA9)*($G9=FC9))*NOT(ISBLANK($E9)),1,0)+((($E9>$G9)*(FA9>FC9))+(($E9<$G9)*(FA9<FC9))+(($E9=$G9)*(FA9=FC9)))-ISBLANK($E9)*(FA9=FC9)+(($E9-$G9)=(FA9-FC9))))) | FH9: : | FJ9: =IF(ISBLANK($E9),"",(IF(ISBLANK(FG9),0,IF((($E9=FG9)*($G9=FI9))*NOT(ISBLANK($E9)),1,0)+((($E9>$G9)*(FG9>FI9))+(($E9<$G9)*(FG9<FI9))+(($E9=$G9)*(FG9=FI9)))-ISBLANK($E9)*(FG9=FI9)+(($E9-$G9)=(FG9-FI9))))) | FN9: : | FP9: =IF(ISBLANK($E9),"",(IF(ISBLANK(FM9),0,IF((($E9=FM9)*($G9=FO9))*NOT(ISBLANK($E9)),1,0)+((($E9>$G9)*(FM9>FO9))+(($E9<$G9)*(FM9<FO9))+(($E9=$G9)*(FM9=FO9)))-ISBLANK($E9)*(FM9=FO9)+(($E9-$G9)=(FM9-FO9))))) | FT9: : | FV9: =IF(ISBLANK($E9),"",(IF(ISBLANK(FS9),0,IF((($E9=FS9)*($G9=FU9))*NOT(ISBLANK($E9)),1,0)+((($E9>$G9)*(FS9>FU9))+(($E9<$G9)*(FS9<FU9))+(($E9=$G9)*(FS9=FU9)))-ISBLANK($E9)*(FS9=FU9)+(($E9-$G9)=(FS9-FU9))))) | FZ9: : | GB9: =IF(ISBLANK($E9),"",(IF(ISBLANK(FY9),0,IF((($E9=FY9)*($G9=GA9))*NOT(ISBLANK($E9)),1,0)+((($E9>$G9)*(FY9>GA9))+(($E9<$G9)*(FY9<GA9))+(($E9=$G9)*(FY9=GA9)))-ISBLANK($E9)*(FY9=GA9)+(($E9-$G9)=(FY9-GA9))))) | GF9: : | GH9: =IF(ISBLANK($E9),"",(IF(ISBLANK(GE9),0,IF((($E9=GE9)*($G9=GG9))*NOT(ISBLANK($E9)),1,0)+((($E9>$G9)*(GE9>GG9))+(($E9<$G9)*(GE9<GG9))+(($E9=$G9)*(GE9=GG9)))-ISBLANK($E9)*(GE9=GG9)+(($E9-$G9)=(GE9-GG9))))) | GL9: : | GN9: =IF(ISBLANK($E9),"",(IF(ISBLANK(GK9),0,IF((($E9=GK9)*($G9=GM9))*NOT(ISBLANK($E9)),1,0)+((($E9>$G9)*(GK9>GM9))+(($E9<$G9)*(GK9<GM9))+(($E9=$G9)*(GK9=GM9)))-ISBLANK($E9)*(GK9=GM9)+(($E9-$G9)=(GK9-GM9))))) | GR9: : | GT9: =IF(ISBLANK($E9),"",(IF(ISBLANK(GQ9),0,IF((($E9=GQ9)*($G9=GS9))*NOT(ISBLANK($E9)),1,0)+((($E9>$G9)*(GQ9>GS9))+(($E9<$G9)*(GQ9<GS9))+(($E9=$G9)*(GQ9=GS9)))-ISBLANK($E9)*(GQ9=GS9)+(($E9-$G9)=(GQ9-GS9)))))
C10: : | F10: : | I10: =COUNTIF(P10,3)+COUNTIF(V10,3)+COUNTIF(AB10,3)+COUNTIF(AH10,3)+COUNTIF(AN10,3)+COUNTIF(AT10,3)+COUNTIF(AZ10,3)+COUNTIF(BF10,3)+COUNTIF(BL10,3)+COUNTIF(BR10,3)+COUNTIF(BX10,3)+COUNTIF(CD10,3)+COUNTIF(CJ10,3)+COUNTIF(CP10,3)+COUNTIF(CV10,3)+COUNTIF(DB10,3)+COUNTIF(DH10,3)+COUNTIF(DN10,3)+COUNTIF(DT10,3)+COUNTIF(DZ10,3)+COUNTIF(EF10,3)+COUNTIF(EL10,3)+COUNTIF(ER10,3)+COUNTIF(EX10,3)+COUNTIF(FD10,3)+COUNTIF(FJ10,3)+COUNTIF(FP10,3)+COUNTIF(FV10,3)+COUNTIF(GB10,3)+COUNTIF(GH10,3)+COUNTIF(GN10,3)+COUNTIF(GT10,3) | J10: =COUNTIF(P10,2)+COUNTIF(V10,2)+COUNTIF(AB10,2)+COUNTIF(AH10,2)+COUNTIF(AN10,2)+COUNTIF(AT10,2)+COUNTIF(AZ10,2)+COUNTIF(BF10,2)+COUNTIF(BL10,2)+COUNTIF(BR10,2)+COUNTIF(BX10,2)+COUNTIF(CD10,2)+COUNTIF(CJ10,2)+COUNTIF(CP10,2)+COUNTIF(CV10,2)+COUNTIF(DB10,2)+COUNTIF(DH10,2)+COUNTIF(DN10,2)+COUNTIF(DT10,2)+COUNTIF(DZ10,2)+COUNTIF(EF10,2)+COUNTIF(EL10,2)+COUNTIF(ER10,2)+COUNTIF(EX10,2)+COUNTIF(FD10,2)+COUNTIF(FJ10,2)+COUNTIF(FP10,2)+COUNTIF(FV10,2)+COUNTIF(GB10,2)+COUNTIF(GH10,2)+COUNTIF(GN10,2)+COUNTIF(GT10,2) | K10: =COUNTIF(P10,1)+COUNTIF(V10,1)+COUNTIF(AB10,1)+COUNTIF(AH10,1)+COUNTIF(AN10,1)+COUNTIF(AT10,1)+COUNTIF(AZ10,1)+COUNTIF(BF10,1)+COUNTIF(BL10,1)+COUNTIF(BR10,1)+COUNTIF(BX10,1)+COUNTIF(CD10,1)+COUNTIF(CJ10,1)+COUNTIF(CP10,1)+COUNTIF(CV10,1)+COUNTIF(DB10,1)+COUNTIF(DH10,1)+COUNTIF(DN10,1)+COUNTIF(DT10,1)+COUNTIF(DZ10,1)+COUNTIF(EF10,1)+COUNTIF(EL10,1)+COUNTIF(ER10,1)+COUNTIF(EX10,1)+COUNTIF(FD10,1)+COUNTIF(FJ10,1)+COUNTIF(FP10,1)+COUNTIF(FV10,1)+COUNTIF(GB10,1)+COUNTIF(GH10,1)+COUNTIF(GN10,1)+COUNTIF(GT10,1) | N10: : | P10: =IF(ISBLANK($E10),"",(IF(ISBLANK(M10),0,IF((($E10=M10)*($G10=O10))*NOT(ISBLANK($E10)),1,0)+((($E10>$G10)*(M10>O10))+(($E10<$G10)*(M10<O10))+(($E10=$G10)*(M10=O10)))-ISBLANK($E10)*(M10=O10)+(($E10-$G10)=(M10-O10))))) | T10: : | V10: =IF(ISBLANK($E10),"",(IF(ISBLANK(S10),0,IF((($E10=S10)*($G10=U10))*NOT(ISBLANK($E10)),1,0)+((($E10>$G10)*(S10>U10))+(($E10<$G10)*(S10<U10))+(($E10=$G10)*(S10=U10)))-ISBLANK($E10)*(S10=U10)+(($E10-$G10)=(S10-U10))))) | Z10: : | AB10: =IF(ISBLANK($E10),"",(IF(ISBLANK(Y10),0,IF((($E10=Y10)*($G10=AA10))*NOT(ISBLANK($E10)),1,0)+((($E10>$G10)*(Y10>AA10))+(($E10<$G10)*(Y10<AA10))+(($E10=$G10)*(Y10=AA10)))-ISBLANK($E10)*(Y10=AA10)+(($E10-$G10)=(Y10-AA10))))) | AF10: : | AH10: =IF(ISBLANK($E10),"",(IF(ISBLANK(AE10),0,IF((($E10=AE10)*($G10=AG10))*NOT(ISBLANK($E10)),1,0)+((($E10>$G10)*(AE10>AG10))+(($E10<$G10)*(AE10<AG10))+(($E10=$G10)*(AE10=AG10)))-ISBLANK($E10)*(AE10=AG10)+(($E10-$G10)=(AE10-AG10))))) | AL10: : | AN10: =IF(ISBLANK($E10),"",(IF(ISBLANK(AK10),0,IF((($E10=AK10)*($G10=AM10))*NOT(ISBLANK($E10)),1,0)+((($E10>$G10)*(AK10>AM10))+(($E10<$G10)*(AK10<AM10))+(($E10=$G10)*(AK10=AM10)))-ISBLANK($E10)*(AK10=AM10)+(($E10-$G10)=(AK10-AM10))))) | AR10: : | AT10: =IF(ISBLANK($E10),"",(IF(ISBLANK(AQ10),0,IF((($E10=AQ10)*($G10=AS10))*NOT(ISBLANK($E10)),1,0)+((($E10>$G10)*(AQ10>AS10))+(($E10<$G10)*(AQ10<AS10))+(($E10=$G10)*(AQ10=AS10)))-ISBLANK($E10)*(AQ10=AS10)+(($E10-$G10)=(AQ10-AS10))))) | AX10: : | AZ10: =IF(ISBLANK($E10),"",(IF(ISBLANK(AW10),0,IF((($E10=AW10)*($G10=AY10))*NOT(ISBLANK($E10)),1,0)+((($E10>$G10)*(AW10>AY10))+(($E10<$G10)*(AW10<AY10))+(($E10=$G10)*(AW10=AY10)))-ISBLANK($E10)*(AW10=AY10)+(($E10-$G10)=(AW10-AY10))))) | BD10: : | BF10: =IF(ISBLANK($E10),"",(IF(ISBLANK(BC10),0,IF((($E10=BC10)*($G10=BE10))*NOT(ISBLANK($E10)),1,0)+((($E10>$G10)*(BC10>BE10))+(($E10<$G10)*(BC10<BE10))+(($E10=$G10)*(BC10=BE10)))-ISBLANK($E10)*(BC10=BE10)+(($E10-$G10)=(BC10-BE10))))) | BJ10: : | BL10: =IF(ISBLANK($E10),"",(IF(ISBLANK(BI10),0,IF((($E10=BI10)*($G10=BK10))*NOT(ISBLANK($E10)),1,0)+((($E10>$G10)*(BI10>BK10))+(($E10<$G10)*(BI10<BK10))+(($E10=$G10)*(BI10=BK10)))-ISBLANK($E10)*(BI10=BK10)+(($E10-$G10)=(BI10-BK10))))) | BP10: : | BR10: =IF(ISBLANK($E10),"",(IF(ISBLANK(BO10),0,IF((($E10=BO10)*($G10=BQ10))*NOT(ISBLANK($E10)),1,0)+((($E10>$G10)*(BO10>BQ10))+(($E10<$G10)*(BO10<BQ10))+(($E10=$G10)*(BO10=BQ10)))-ISBLANK($E10)*(BO10=BQ10)+(($E10-$G10)=(BO10-BQ10))))) | BV10: : | BX10: =IF(ISBLANK($E10),"",(IF(ISBLANK(BU10),0,IF((($E10=BU10)*($G10=BW10))*NOT(ISBLANK($E10)),1,0)+((($E10>$G10)*(BU10>BW10))+(($E10<$G10)*(BU10<BW10))+(($E10=$G10)*(BU10=BW10)))-ISBLANK($E10)*(BU10=BW10)+(($E10-$G10)=(BU10-BW10))))) | CB10: : | CD10: =IF(ISBLANK($E10),"",(IF(ISBLANK(CA10),0,IF((($E10=CA10)*($G10=CC10))*NOT(ISBLANK($E10)),1,0)+((($E10>$G10)*(CA10>CC10))+(($E10<$G10)*(CA10<CC10))+(($E10=$G10)*(CA10=CC10)))-ISBLANK($E10)*(CA10=CC10)+(($E10-$G10)=(CA10-CC10))))) | CH10: : | CJ10: =IF(ISBLANK($E10),"",(IF(ISBLANK(CG10),0,IF((($E10=CG10)*($G10=CI10))*NOT(ISBLANK($E10)),1,0)+((($E10>$G10)*(CG10>CI10))+(($E10<$G10)*(CG10<CI10))+(($E10=$G10)*(CG10=CI10)))-ISBLANK($E10)*(CG10=CI10)+(($E10-$G10)=(CG10-CI10))))) | CN10: : | CP10: =IF(ISBLANK($E10),"",(IF(ISBLANK(CM10),0,IF((($E10=CM10)*($G10=CO10))*NOT(ISBLANK($E10)),1,0)+((($E10>$G10)*(CM10>CO10))+(($E10<$G10)*(CM10<CO10))+(($E10=$G10)*(CM10=CO10)))-ISBLANK($E10)*(CM10=CO10)+(($E10-$G10)=(CM10-CO10))))) | CT10: : | CV10: =IF(ISBLANK($E10),"",(IF(ISBLANK(CS10),0,IF((($E10=CS10)*($G10=CU10))*NOT(ISBLANK($E10)),1,0)+((($E10>$G10)*(CS10>CU10))+(($E10<$G10)*(CS10<CU10))+(($E10=$G10)*(CS10=CU10)))-ISBLANK($E10)*(CS10=CU10)+(($E10-$G10)=(CS10-CU10))))) | CZ10: : | DB10: =IF(ISBLANK($E10),"",(IF(ISBLANK(CY10),0,IF((($E10=CY10)*($G10=DA10))*NOT(ISBLANK($E10)),1,0)+((($E10>$G10)*(CY10>DA10))+(($E10<$G10)*(CY10<DA10))+(($E10=$G10)*(CY10=DA10)))-ISBLANK($E10)*(CY10=DA10)+(($E10-$G10)=(CY10-DA10))))) | DF10: : | DH10: =IF(ISBLANK($E10),"",(IF(ISBLANK(DE10),0,IF((($E10=DE10)*($G10=DG10))*NOT(ISBLANK($E10)),1,0)+((($E10>$G10)*(DE10>DG10))+(($E10<$G10)*(DE10<DG10))+(($E10=$G10)*(DE10=DG10)))-ISBLANK($E10)*(DE10=DG10)+(($E10-$G10)=(DE10-DG10))))) | DL10: : | DN10: =IF(ISBLANK($E10),"",(IF(ISBLANK(DK10),0,IF((($E10=DK10)*($G10=DM10))*NOT(ISBLANK($E10)),1,0)+((($E10>$G10)*(DK10>DM10))+(($E10<$G10)*(DK10<DM10))+(($E10=$G10)*(DK10=DM10)))-ISBLANK($E10)*(DK10=DM10)+(($E10-$G10)=(DK10-DM10))))) | DR10: : | DT10: =IF(ISBLANK($E10),"",(IF(ISBLANK(DQ10),0,IF((($E10=DQ10)*($G10=DS10))*NOT(ISBLANK($E10)),1,0)+((($E10>$G10)*(DQ10>DS10))+(($E10<$G10)*(DQ10<DS10))+(($E10=$G10)*(DQ10=DS10)))-ISBLANK($E10)*(DQ10=DS10)+(($E10-$G10)=(DQ10-DS10))))) | DX10: : | DZ10: =IF(ISBLANK($E10),"",(IF(ISBLANK(DW10),0,IF((($E10=DW10)*($G10=DY10))*NOT(ISBLANK($E10)),1,0)+((($E10>$G10)*(DW10>DY10))+(($E10<$G10)*(DW10<DY10))+(($E10=$G10)*(DW10=DY10)))-ISBLANK($E10)*(DW10=DY10)+(($E10-$G10)=(DW10-DY10))))) | ED10: : | EF10: =IF(ISBLANK($E10),"",(IF(ISBLANK(EC10),0,IF((($E10=EC10)*($G10=EE10))*NOT(ISBLANK($E10)),1,0)+((($E10>$G10)*(EC10>EE10))+(($E10<$G10)*(EC10<EE10))+(($E10=$G10)*(EC10=EE10)))-ISBLANK($E10)*(EC10=EE10)+(($E10-$G10)=(EC10-EE10))))) | EJ10: : | EL10: =IF(ISBLANK($E10),"",(IF(ISBLANK(EI10),0,IF((($E10=EI10)*($G10=EK10))*NOT(ISBLANK($E10)),1,0)+((($E10>$G10)*(EI10>EK10))+(($E10<$G10)*(EI10<EK10))+(($E10=$G10)*(EI10=EK10)))-ISBLANK($E10)*(EI10=EK10)+(($E10-$G10)=(EI10-EK10))))) | EP10: : | ER10: =IF(ISBLANK($E10),"",(IF(ISBLANK(EO10),0,IF((($E10=EO10)*($G10=EQ10))*NOT(ISBLANK($E10)),1,0)+((($E10>$G10)*(EO10>EQ10))+(($E10<$G10)*(EO10<EQ10))+(($E10=$G10)*(EO10=EQ10)))-ISBLANK($E10)*(EO10=EQ10)+(($E10-$G10)=(EO10-EQ10))))) | EV10: : | EX10: =IF(ISBLANK($E10),"",(IF(ISBLANK(EU10),0,IF((($E10=EU10)*($G10=EW10))*NOT(ISBLANK($E10)),1,0)+((($E10>$G10)*(EU10>EW10))+(($E10<$G10)*(EU10<EW10))+(($E10=$G10)*(EU10=EW10)))-ISBLANK($E10)*(EU10=EW10)+(($E10-$G10)=(EU10-EW10))))) | FB10: : | FD10: =IF(ISBLANK($E10),"",(IF(ISBLANK(FA10),0,IF((($E10=FA10)*($G10=FC10))*NOT(ISBLANK($E10)),1,0)+((($E10>$G10)*(FA10>FC10))+(($E10<$G10)*(FA10<FC10))+(($E10=$G10)*(FA10=FC10)))-ISBLANK($E10)*(FA10=FC10)+(($E10-$G10)=(FA10-FC10))))) | FH10: : | FJ10: =IF(ISBLANK($E10),"",(IF(ISBLANK(FG10),0,IF((($E10=FG10)*($G10=FI10))*NOT(ISBLANK($E10)),1,0)+((($E10>$G10)*(FG10>FI10))+(($E10<$G10)*(FG10<FI10))+(($E10=$G10)*(FG10=FI10)))-ISBLANK($E10)*(FG10=FI10)+(($E10-$G10)=(FG10-FI10))))) | FN10: : | FP10: =IF(ISBLANK($E10),"",(IF(ISBLANK(FM10),0,IF((($E10=FM10)*($G10=FO10))*NOT(ISBLANK($E10)),1,0)+((($E10>$G10)*(FM10>FO10))+(($E10<$G10)*(FM10<FO10))+(($E10=$G10)*(FM10=FO10)))-ISBLANK($E10)*(FM10=FO10)+(($E10-$G10)=(FM10-FO10))))) | FT10: : | FV10: =IF(ISBLANK($E10),"",(IF(ISBLANK(FS10),0,IF((($E10=FS10)*($G10=FU10))*NOT(ISBLANK($E10)),1,0)+((($E10>$G10)*(FS10>FU10))+(($E10<$G10)*(FS10<FU10))+(($E10=$G10)*(FS10=FU10)))-ISBLANK($E10)*(FS10=FU10)+(($E10-$G10)=(FS10-FU10))))) | FZ10: : | GB10: =IF(ISBLANK($E10),"",(IF(ISBLANK(FY10),0,IF((($E10=FY10)*($G10=GA10))*NOT(ISBLANK($E10)),1,0)+((($E10>$G10)*(FY10>GA10))+(($E10<$G10)*(FY10<GA10))+(($E10=$G10)*(FY10=GA10)))-ISBLANK($E10)*(FY10=GA10)+(($E10-$G10)=(FY10-GA10))))) | GF10: : | GH10: =IF(ISBLANK($E10),"",(IF(ISBLANK(GE10),0,IF((($E10=GE10)*($G10=GG10))*NOT(ISBLANK($E10)),1,0)+((($E10>$G10)*(GE10>GG10))+(($E10<$G10)*(GE10<GG10))+(($E10=$G10)*(GE10=GG10)))-ISBLANK($E10)*(GE10=GG10)+(($E10-$G10)=(GE10-GG10))))) | GL10: : | GN10: =IF(ISBLANK($E10),"",(IF(ISBLANK(GK10),0,IF((($E10=GK10)*($G10=GM10))*NOT(ISBLANK($E10)),1,0)+((($E10>$G10)*(GK10>GM10))+(($E10<$G10)*(GK10<GM10))+(($E10=$G10)*(GK10=GM10)))-ISBLANK($E10)*(GK10=GM10)+(($E10-$G10)=(GK10-GM10))))) | GR10: : | GT10: =IF(ISBLANK($E10),"",(IF(ISBLANK(GQ10),0,IF((($E10=GQ10)*($G10=GS10))*NOT(ISBLANK($E10)),1,0)+((($E10>$G10)*(GQ10>GS10))+(($E10<$G10)*(GQ10<GS10))+(($E10=$G10)*(GQ10=GS10)))-ISBLANK($E10)*(GQ10=GS10)+(($E10-$G10)=(GQ10-GS10)))))
