Workbook

Sheet TW
B1: Fr | E1: Sa | H1: So | K1: Mo | N1: TW-Ges | O1: TW-BL | P1: TW-2L | Q1: 3er | R1: 2er | S1: 1er | T1: ZP
A2: Bächli | B2: =VALUE('17.TT'!$P$31) -> 7 | D2: Bächli | E2: =VALUE('17.TT'!$P$33) -> 1 | G2: Bächli | H2: =VALUE('17.TT'!$P$35) -> 8 | J2: Bächli | K2: =VALUE('17.TT'!$P$37) -> 5 | M2: Bächli | N2: =VALUE('17.TT'!Q39)+T2 -> 21 | O2: =VALUE('17.TT'!N39) -> 21 | P2: =VALUE('17.TT'!O39) -> 0 | Q2: =COUNTIF('17.TT'!P6:P26,3) -> 3 | R2: =COUNTIF('17.TT'!P6:P26,2) -> 4 | S2: =COUNTIF('17.TT'!P6:P26,1) -> 4
A3: Bene | B3: =VALUE('17.TT'!$V$31) -> 2 | D3: Bene | E3: =VALUE('17.TT'!$V$33) -> 2 | G3: Bene | H3: =VALUE('17.TT'!$V$35) -> 7 | J3: Bene | K3: =VALUE('17.TT'!$V$37) -> 8 | M3: Bene | N3: =VALUE('17.TT'!W39)+T3 -> 19 | O3: =VALUE('17.TT'!T39) -> 19 | P3: =VALUE('17.TT'!U39) -> 0 | Q3: =COUNTIF('17.TT'!V6:V26,3) -> 3 | R3: =COUNTIF('17.TT'!V6:V26,2) -> 1 | S3: =COUNTIF('17.TT'!V6:V26,1) -> 8
A4: Boller | B4: =VALUE('17.TT'!$AB$31) -> 8 | D4: Boller | E4: =VALUE('17.TT'!$AB$33) -> 2 | G4: Boller | H4: =VALUE('17.TT'!$AB$35) -> 6 | J4: Boller | K4: =VALUE('17.TT'!$AB$37) -> 5 | M4: Boller | N4: =VALUE('17.TT'!AC39)+T4 -> 21 | O4: =VALUE('17.TT'!Z39) -> 21 | P4: =VALUE('17.TT'!AA39) -> 0 | Q4: =COUNTIF('17.TT'!AB6:AB26,3) -> 3 | R4: =COUNTIF('17.TT'!AB6:AB26,2) -> 3 | S4: =COUNTIF('17.TT'!AB6:AB26,1) -> 6
A5: Bussi | B5: =VALUE('17.TT'!$AH$31) -> 0 | D5: Bussi | E5: =VALUE('17.TT'!$AH$33) -> 2 | G5: Bussi | H5: =VALUE('17.TT'!$AH$35) -> 8 | J5: Bussi | K5: =VALUE('17.TT'!$AH$37) -> 3 | M5: Bussi | N5: =VALUE('17.TT'!AI39)+T5 -> 13 | O5: =VALUE('17.TT'!AF39) -> 13 | P5: =VALUE('17.TT'!AG39) -> 0 | Q5: =COUNTIF('17.TT'!AH6:AH26,3) -> 1 | R5: =COUNTIF('17.TT'!AH6:AH26,2) -> 2 | S5: =COUNTIF('17.TT'!AH6:AH26,1) -> 6
A6: Christkind | B6: =VALUE('17.TT'!$AN$31) -> 12 | D6: Christkind | E6: =VALUE('17.TT'!$AN$33) -> 2 | G6: Christkind | H6: =VALUE('17.TT'!$AN$35) -> 8 | J6: Christkind | K6: =VALUE('17.TT'!$AN$37) -> 7 | M6: Christkind | N6: =VALUE('17.TT'!AO39)+T6 -> 29 | O6: =VALUE('17.TT'!AL39) -> 29 | P6: =VALUE('17.TT'!AM39) -> 0 | Q6: =COUNTIF('17.TT'!AN6:AN26,3) -> 5 | R6: =COUNTIF('17.TT'!AN6:AN26,2) -> 5 | S6: =COUNTIF('17.TT'!AN6:AN26,1) -> 4
A7: Cordoba | B7: =VALUE('17.TT'!$AT$31) -> 3 | D7: Cordoba | E7: =VALUE('17.TT'!$AT$33) -> 2 | G7: Cordoba | H7: =VALUE('17.TT'!$AT$35) -> 4 | J7: Cordoba | K7: =VALUE('17.TT'!$AT$37) -> 8 | M7: Cordoba | N7: =VALUE('17.TT'!AU39)+T7 -> 17 | O7: =VALUE('17.TT'!AR39) -> 17 | P7: =VALUE('17.TT'!AS39) -> 0 | Q7: =COUNTIF('17.TT'!AT6:AT26,3) -> 3 | R7: =COUNTIF('17.TT'!AT6:AT26,2) -> 1 | S7: =COUNTIF('17.TT'!AT6:AT26,1) -> 6
A8: Dellinger | B8: =VALUE('17.TT'!$AZ$31) -> 3 | D8: Dellinger | E8: =VALUE('17.TT'!$AZ$33) -> 1 | G8: Dellinger | H8: =VALUE('17.TT'!$AZ$35) -> 5 | J8: Dellinger | K8: =VALUE('17.TT'!$AZ$37) -> 10 | M8: Dellinger | N8: =VALUE('17.TT'!BA39)+T8 -> 19 | O8: =VALUE('17.TT'!AX39) -> 19 | P8: =VALUE('17.TT'!AY39) -> 0 | Q8: =COUNTIF('17.TT'!AZ6:AZ26,3) -> 2 | R8: =COUNTIF('17.TT'!AZ6:AZ26,2) -> 4 | S8: =COUNTIF('17.TT'!AZ6:AZ26,1) -> 5
A9: DerHanseat | B9: =VALUE('17.TT'!$BF$31) -> 0 | D9: DerHanseat | E9: =VALUE('17.TT'!$BF$33) -> 2 | G9: DerHanseat | H9: =VALUE('17.TT'!$BF$35) -> 6 | J9: DerHanseat | K9: =VALUE('17.TT'!$BF$37) -> 5 | M9: DerHanseat | N9: =VALUE('17.TT'!BG39)+T9 -> 13 | O9: =VALUE('17.TT'!BD39) -> 13 | P9: =VALUE('17.TT'!BE39) -> 0 | Q9: =COUNTIF('17.TT'!BF6:BF26,3) -> 2 | R9: =COUNTIF('17.TT'!BF6:BF26,2) -> 1 | S9: =COUNTIF('17.TT'!BF6:BF26,1) -> 5
A10: Dr. Rock | B10: =VALUE('17.TT'!$BL$31) -> 6 | D10: Dr. Rock | E10: =VALUE('17.TT'!$BL$33) -> 2 | G10: Dr. Rock | H10: =VALUE('17.TT'!$BL$35) -> 4 | J10: Dr. Rock | K10: =VALUE('17.TT'!$BL$37) -> 7 | M10: Dr. Rock | N10: =VALUE('17.TT'!BM39)+T10 -> 19 | O10: =VALUE('17.TT'!BJ39) -> 19 | P10: =VALUE('17.TT'!BK39) -> 0 | Q10: =COUNTIF('17.TT'!BL6:BL26,3) -> 1 | R10: =COUNTIF('17.TT'!BL6:BL26,2) -> 3 | S10: =COUNTIF('17.TT'!BL6:BL26,1) -> 10
A11: Effe | B11: =VALUE('17.TT'!$BR$31) -> 4 | D11: Effe | E11: =VALUE('17.TT'!$BR$33) -> 2 | G11: Effe | H11: =VALUE('17.TT'!$BR$35) -> 7 | J11: Effe | K11: =VALUE('17.TT'!$BR$37) -> 4 | M11: Effe | N11: =VALUE('17.TT'!BS39)+T11 -> 17 | O11: =VALUE('17.TT'!BP39) -> 17 | P11: =VALUE('17.TT'!BQ39) -> 0 | Q11: =COUNTIF('17.TT'!BR6:BR26,3) -> 1 | R11: =COUNTIF('17.TT'!BR6:BR26,2) -> 2 | S11: =COUNTIF('17.TT'!BR6:BR26,1) -> 10
A12: Ernst | B12: =VALUE('17.TT'!$BX$31) -> 6 | D12: Ernst | E12: =VALUE('17.TT'!$BX$33) -> 2 | G12: Ernst | H12: =VALUE('17.TT'!$BX$35) -> 4 | J12: Ernst | K12: =VALUE('17.TT'!$BX$37) -> 7 | M12: Ernst | N12: =VALUE('17.TT'!BY39)+T12 -> 19 | O12: =VALUE('17.TT'!BV39) -> 19 | P12: =VALUE('17.TT'!BW39) -> 0 | Q12: =COUNTIF('17.TT'!BX6:BX26,3) -> 3 | R12: =COUNTIF('17.TT'!BX6:BX26,2) -> 1 | S12: =COUNTIF('17.TT'!BX6:BX26,1) -> 8
A13: Fips | B13: =VALUE('17.TT'!$CD$31) -> 6 | D13: Fips | E13: =VALUE('17.TT'!$CD$33) -> 2 | G13: Fips | H13: =VALUE('17.TT'!$CD$35) -> 5 | J13: Fips | K13: =VALUE('17.TT'!$CD$37) -> 3 | M13: Fips | N13: =VALUE('17.TT'!CE39)+T13 -> 16 | O13: =VALUE('17.TT'!CB39) -> 16 | P13: =VALUE('17.TT'!CC39) -> 0 | Q13: =COUNTIF('17.TT'!CD6:CD26,3) -> 1 | R13: =COUNTIF('17.TT'!CD6:CD26,2) -> 3 | S13: =COUNTIF('17.TT'!CD6:CD26,1) -> 7
A14: Flipp | B14: =VALUE('17.TT'!$CJ$31) -> 4 | D14: Flipp | E14: =VALUE('17.TT'!$CJ$33) -> 1 | G14: Flipp | H14: =VALUE('17.TT'!$CJ$35) -> 7 | J14: Flipp | K14: =VALUE('17.TT'!$CJ$37) -> 7 | M14: Flipp | N14: =VALUE('17.TT'!CK39)+T14 -> 19 | O14: =VALUE('17.TT'!CH39) -> 19 | P14: =VALUE('17.TT'!CI39) -> 0 | Q14: =COUNTIF('17.TT'!CJ6:CJ26,3) -> 2 | R14: =COUNTIF('17.TT'!CJ6:CJ26,2) -> 3 | S14: =COUNTIF('17.TT'!CJ6:CJ26,1) -> 7
A15: Focker | B15: =VALUE('17.TT'!$CP$31) -> 2 | D15: Focker | E15: =VALUE('17.TT'!$CP$33) -> 2 | G15: Focker | H15: =VALUE('17.TT'!$CP$35) -> 5 | J15: Focker | K15: =VALUE('17.TT'!$CP$37) -> 6 | M15: Focker | N15: =VALUE('17.TT'!CQ39)+T15 -> 15 | O15: =VALUE('17.TT'!CN39) -> 15 | P15: =VALUE('17.TT'!CO39) -> 0 | Q15: =COUNTIF('17.TT'!CP6:CP26,3) -> 1 | R15: =COUNTIF('17.TT'!CP6:CP26,2) -> 3 | S15: =COUNTIF('17.TT'!CP6:CP26,1) -> 6
A16: Gazelle | B16: =VALUE('17.TT'!$CV$31) -> 3 | D16: Gazelle | E16: =VALUE('17.TT'!$CV$33) -> 2 | G16: Gazelle | H16: =VALUE('17.TT'!$CV$35) -> 8 | J16: Gazelle | K16: =VALUE('17.TT'!$CV$37) -> 7 | M16: Gazelle | N16: =VALUE('17.TT'!CW39)+T16 -> 20 | O16: =VALUE('17.TT'!CT39) -> 20 | P16: =VALUE('17.TT'!CU39) -> 0 | Q16: =COUNTIF('17.TT'!CV6:CV26,3) -> 2 | R16: =COUNTIF('17.TT'!CV6:CV26,2) -> 3 | S16: =COUNTIF('17.TT'!CV6:CV26,1) -> 8
A17: Highländer | B17: =VALUE('17.TT'!$DB$31) -> 2 | D17: Highländer | E17: =VALUE('17.TT'!$DB$33) -> 2 | G17: Highländer | H17: =VALUE('17.TT'!$DB$35) -> 6 | J17: Highländer | K17: =VALUE('17.TT'!$DB$37) -> 6 | M17: Highländer | N17: =VALUE('17.TT'!DC39)+T17 -> 16 | O17: =VALUE('17.TT'!CZ39) -> 16 | P17: =VALUE('17.TT'!DA39) -> 0 | Q17: =COUNTIF('17.TT'!DB6:DB26,3) -> 1 | R17: =COUNTIF('17.TT'!DB6:DB26,2) -> 2 | S17: =COUNTIF('17.TT'!DB6:DB26,1) -> 9
A18: Hoeness | B18: =VALUE('17.TT'!$DH$31) -> 5 | D18: Hoeness | E18: =VALUE('17.TT'!$DH$33) -> 1 | G18: Hoeness | H18: =VALUE('17.TT'!$DH$35) -> 7 | J18: Hoeness | K18: =VALUE('17.TT'!$DH$37) -> 6 | M18: Hoeness | N18: =VALUE('17.TT'!DI39)+T18 -> 19 | O18: =VALUE('17.TT'!DF39) -> 19 | P18: =VALUE('17.TT'!DG39) -> 0 | Q18: =COUNTIF('17.TT'!DH6:DH26,3) -> 2 | R18: =COUNTIF('17.TT'!DH6:DH26,2) -> 4 | S18: =COUNTIF('17.TT'!DH6:DH26,1) -> 5
A19: Jay-Jay | B19: =VALUE('17.TT'!$DN$31) -> 4 | D19: Jay-Jay | E19: =VALUE('17.TT'!$DN$33) -> 1 | G19: Jay-Jay | H19: =VALUE('17.TT'!$DN$35) -> 8 | J19: Jay-Jay | K19: =VALUE('17.TT'!$DN$37) -> 10 | M19: Jay-Jay | N19: =VALUE('17.TT'!DO39)+T19 -> 23 | O19: =VALUE('17.TT'!DL39) -> 23 | P19: =VALUE('17.TT'!DM39) -> 0 | Q19: =COUNTIF('17.TT'!DN6:DN26,3) -> 4 | R19: =COUNTIF('17.TT'!DN6:DN26,2) -> 3 | S19: =COUNTIF('17.TT'!DN6:DN26,1) -> 5
A20: Jukkel | B20: =VALUE('17.TT'!$DT$31) -> 3 | D20: Jukkel | E20: =VALUE('17.TT'!$DT$33) -> 2 | G20: Jukkel | H20: =VALUE('17.TT'!$DT$35) -> 7 | J20: Jukkel | K20: =VALUE('17.TT'!$DT$37) -> 10 | M20: Jukkel | N20: =VALUE('17.TT'!DU39)+T20 -> 22 | O20: =VALUE('17.TT'!DR39) -> 22 | P20: =VALUE('17.TT'!DS39) -> 0 | Q20: =COUNTIF('17.TT'!DT6:DT26,3) -> 3 | R20: =COUNTIF('17.TT'!DT6:DT26,2) -> 4 | S20: =COUNTIF('17.TT'!DT6:DT26,1) -> 5
A21: kl.Schalke | B21: =VALUE('17.TT'!$DZ$31) -> 3 | D21: kl.Schalke | E21: =VALUE('17.TT'!$DZ$33) -> 2 | G21: kl.Schalke | H21: =VALUE('17.TT'!$DZ$35) -> 8 | J21: kl.Schalke | K21: =VALUE('17.TT'!$DZ$37) -> 8 | M21: kl.Schalke | N21: =VALUE('17.TT'!EA39)+T21 -> 21 | O21: =VALUE('17.TT'!DX39) -> 21 | P21: =VALUE('17.TT'!DY39) -> 0 | Q21: =COUNTIF('17.TT'!DZ6:DZ26,3) -> 4 | R21: =COUNTIF('17.TT'!DZ6:DZ26,2) -> 2 | S21: =COUNTIF('17.TT'!DZ6:DZ26,1) -> 5
A22: Marilyn | B22: =VALUE('17.TT'!$EF$31) -> 4 | D22: Marilyn | E22: =VALUE('17.TT'!$EF$33) -> 2 | G22: Marilyn | H22: =VALUE('17.TT'!$EF$35) -> 9 | J22: Marilyn | K22: =VALUE('17.TT'!$EF$37) -> 7 | M22: Marilyn | N22: =VALUE('17.TT'!EG39)+T22 -> 22 | O22: =VALUE('17.TT'!ED39) -> 22 | P22: =VALUE('17.TT'!EE39) -> 0 | Q22: =COUNTIF('17.TT'!EF6:EF26,3) -> 4 | R22: =COUNTIF('17.TT'!EF6:EF26,2) -> 2 | S22: =COUNTIF('17.TT'!EF6:EF26,1) -> 6
A23: Mazinho | B23: =VALUE('17.TT'!$EL$31) -> 8 | D23: Mazinho | E23: =VALUE('17.TT'!$EL$33) -> 2 | G23: Mazinho | H23: =VALUE('17.TT'!$EL$35) -> 3 | J23: Mazinho | K23: =VALUE('17.TT'!$EL$37) -> 9 | M23: Mazinho | N23: =VALUE('17.TT'!EM39)+T23 -> 22 | O23: =VALUE('17.TT'!EJ39) -> 22 | P23: =VALUE('17.TT'!EK39) -> 0 | Q23: =COUNTIF('17.TT'!EL6:EL26,3) -> 3 | R23: =COUNTIF('17.TT'!EL6:EL26,2) -> 4 | S23: =COUNTIF('17.TT'!EL6:EL26,1) -> 5
A24: Parzival | B24: =VALUE('17.TT'!$ER$31) -> 4 | D24: Parzival | E24: =VALUE('17.TT'!$ER$33) -> 2 | G24: Parzival | H24: =VALUE('17.TT'!$ER$35) -> 3 | J24: Parzival | K24: =VALUE('17.TT'!$ER$37) -> 5 | M24: Parzival | N24: =VALUE('17.TT'!ES39)+T24 -> 14 | O24: =VALUE('17.TT'!EP39) -> 14 | P24: =VALUE('17.TT'!EQ39) -> 0 | Q24: =COUNTIF('17.TT'!ER6:ER26,3) -> 2 | R24: =COUNTIF('17.TT'!ER6:ER26,2) -> 1 | S24: =COUNTIF('17.TT'!ER6:ER26,1) -> 6
A25: Rammway | B25: =VALUE('17.TT'!$EX$31) -> 6 | D25: Rammway | E25: =VALUE('17.TT'!$EX$33) -> 2 | G25: Rammway | H25: =VALUE('17.TT'!$EX$35) -> 8 | J25: Rammway | K25: =VALUE('17.TT'!$EX$37) -> 8 | M25: Rammway | N25: =VALUE('17.TT'!EY39)+T25 -> 24 | O25: =VALUE('17.TT'!EV39) -> 24 | P25: =VALUE('17.TT'!EW39) -> 0 | Q25: =COUNTIF('17.TT'!EX6:EX26,3) -> 3 | R25: =COUNTIF('17.TT'!EX6:EX26,2) -> 4 | S25: =COUNTIF('17.TT'!EX6:EX26,1) -> 7
A26: Richy | B26: =VALUE('17.TT'!$FD$31) -> 13 | D26: Richy | E26: =VALUE('17.TT'!$FD$33) -> 2 | G26: Richy | H26: =VALUE('17.TT'!$FD$35) -> 8 | J26: Richy | K26: =VALUE('17.TT'!$FD$37) -> 2 | M26: Richy | N26: =VALUE('17.TT'!FE39)+T26 -> 25 | O26: =VALUE('17.TT'!FB39) -> 25 | P26: =VALUE('17.TT'!FC39) -> 0 | Q26: =COUNTIF('17.TT'!FD6:FD26,3) -> 3 | R26: =COUNTIF('17.TT'!FD6:FD26,2) -> 5 | S26: =COUNTIF('17.TT'!FD6:FD26,1) -> 6
A27: Romax | B27: =VALUE('17.TT'!$FJ$31) -> 1 | D27: Romax | E27: =VALUE('17.TT'!$FJ$33) -> 2 | G27: Romax | H27: =VALUE('17.TT'!$FJ$35) -> 8 | J27: Romax | K27: =VALUE('17.TT'!$FJ$37) -> 10 | M27: Romax | N27: =VALUE('17.TT'!FK39)+T27 -> 21 | O27: =VALUE('17.TT'!FH39) -> 21 | P27: =VALUE('17.TT'!FI39) -> 0 | Q27: =COUNTIF('17.TT'!FJ6:FJ26,3) -> 3 | R27: =COUNTIF('17.TT'!FJ6:FJ26,2) -> 3 | S27: =COUNTIF('17.TT'!FJ6:FJ26,1) -> 6
A28: Rörup | B28: =VALUE('17.TT'!$FP$31) -> 11 | D28: Rörup | E28: =VALUE('17.TT'!$FP$33) -> 2 | G28: Rörup | H28: =VALUE('17.TT'!$FP$35) -> 3 | J28: Rörup | K28: =VALUE('17.TT'!$FP$37) -> 6 | M28: Rörup | N28: =VALUE('17.TT'!FQ39)+T28 -> 22 | O28: =VALUE('17.TT'!FN39) -> 22 | P28: =VALUE('17.TT'!FO39) -> 0 | Q28: =COUNTIF('17.TT'!FP6:FP26,3) -> 4 | R28: =COUNTIF('17.TT'!FP6:FP26,2) -> 2 | S28: =COUNTIF('17.TT'!FP6:FP26,1) -> 6
A29: Snake | B29: =VALUE('17.TT'!$FV$31) -> 8 | D29: Snake | E29: =VALUE('17.TT'!$FV$33) -> 2 | G29: Snake | H29: =VALUE('17.TT'!$FV$35) -> 7 | J29: Snake | K29: =VALUE('17.TT'!$FV$37) -> 8 | M29: Snake | N29: =VALUE('17.TT'!FW39)+T29 -> 25 | O29: =VALUE('17.TT'!FT39) -> 25 | P29: =VALUE('17.TT'!FU39) -> 0 | Q29: =COUNTIF('17.TT'!FV6:FV26,3) -> 3 | R29: =COUNTIF('17.TT'!FV6:FV26,2) -> 4 | S29: =COUNTIF('17.TT'!FV6:FV26,1) -> 8
A30: Underduck | B30: =VALUE('17.TT'!$GB$31) -> 6 | D30: Underduck | E30: =VALUE('17.TT'!$GB$33) -> 2 | G30: Underduck | H30: =VALUE('17.TT'!$GB$35) -> 1 | J30: Underduck | K30: =VALUE('17.TT'!$GB$37) -> 8 | M30: Underduck | N30: =VALUE('17.TT'!GC39)+T30 -> 17 | O30: =VALUE('17.TT'!FZ39) -> 17 | P30: =VALUE('17.TT'!GA39) -> 0 | Q30: =COUNTIF('17.TT'!GB6:GB26,3) -> 4 | R30: =COUNTIF('17.TT'!GB6:GB26,2) -> 0 | S30: =COUNTIF('17.TT'!GB6:GB26,1) -> 5
A31: Willi60 | B31: =VALUE('17.TT'!$GH$31) -> 1 | D31: Willi60 | E31: =VALUE('17.TT'!$GH$33) -> 1 | G31: Willi60 | H31: =VALUE('17.TT'!$GH$35) -> 8 | J31: Willi60 | K31: =VALUE('17.TT'!$GH$37) -> 8 | M31: Willi60 | N31: =VALUE('17.TT'!GI39)+T31 -> 18 | O31: =VALUE('17.TT'!GF39) -> 18 | P31: =VALUE('17.TT'!GG39) -> 0 | Q31: =COUNTIF('17.TT'!GH6:GH26,3) -> 3 | R31: =COUNTIF('17.TT'!GH6:GH26,2) -> 2 | S31: =COUNTIF('17.TT'!GH6:GH26,1) -> 5
A32: Yeti | B32: =VALUE('17.TT'!$GN$31) -> 10 | D32: Yeti | E32: =VALUE('17.TT'!$GN$33) -> 2 | G32: Yeti | H32: =VALUE('17.TT'!$GN$35) -> 3 | J32: Yeti | K32: =VALUE('17.TT'!$GN$37) -> 5 | M32: Yeti | N32: =VALUE('17.TT'!GO39)+T32 -> 20 | O32: =VALUE('17.TT'!GL39) -> 20 | P32: =VALUE('17.TT'!GM39) -> 0 | Q32: =COUNTIF('17.TT'!GN6:GN26,3) -> 3 | R32: =COUNTIF('17.TT'!GN6:GN26,2) -> 3 | S32: =COUNTIF('17.TT'!GN6:GN26,1) -> 5
A33: Yves | B33: =VALUE('17.TT'!$GT$31) -> 5 | D33: Yves | E33: =VALUE('17.TT'!$GT$33) -> 2 | G33: Yves | H33: =VALUE('17.TT'!$GT$35) -> 4 | J33: Yves | K33: =VALUE('17.TT'!$GT37) -> 8 | M33: Yves | N33: =VALUE('17.TT'!GU39)+T33 -> 19 | O33: =VALUE('17.TT'!GR39) -> 19 | P33: =VALUE('17.TT'!GS39) -> 0 | Q33: =COUNTIF('17.TT'!GT6:GT26,3) -> 2 | R33: =COUNTIF('17.TT'!GT6:GT26,2) -> 3 | S33: =COUNTIF('17.TT'!GT6:GT26,1) -> 7
B34: =SUM(B2:B33) -> 160 | E34: =SUM(E2:E33) -> 58 | H34: =SUM(H2:H33) -> 193 | K34: =SUM(K2:K33) -> 216 | N34: =SUM(N2:N33) -> 627 | O34: =SUM(O2:O33) -> 627 | P34: =SUM(P2:P33) -> 0 | Q34: =SUM(Q2:Q33) -> 84 | R34: =SUM(R2:R33) -> 87 | S34: =SUM(S2:S33) -> 201
B35: =(B34/32) -> 5 | E35: =(E34/32) -> 1.8125 | H35: =(H34/32) -> 6.03125 | K35: =(K34/32) -> 6.75 | N35: =(N34/32) -> 19.59375 | O35: =(O34/32) -> 19.59375 | P35: =(P34/32) -> 0 | Q35: =(Q34/32) -> 2.625 | R35: =(R34/32) -> 2.71875 | S35: =(S34/32) -> 6.28125
N37: Zusatzpunkte händisch hier eintragen

Sheet 17.TT
B1: 17.TT
B3: 09.01.-11.01./13.01.-14.01. | D3: Name: | N3: Bächli | T3: Bene | Z3: Boller | AF3: Bussi | AL3: Christkind | AR3: Cordoba | AX3: Dellinger | BD3: derHanseat | BJ3: Dr. Rock | BP3: Effe | BV3: Ernst | CB3: Fips | CH3: Flipp | CN3: Focker | CT3: Gazelle | CZ3: Highländer | DF3: Hoeness | DL3: Jay-Jay | DR3: Jukkel | DX3: kl.Schalke | ED3: Marilyn | EJ3: Mazinho | EP3: Parzival | EV3: Rammway | FB3: Richy | FH3: Romax | FN3: Rörup | FT3: Snake | FZ3: Underduck | GF3: Willi60 | GL3: Yeti | GR3: Yves
B4: 09.01. - 11.01.
B5: 1. Liga | D5: 16. Spieltag | E5: Ergeb. | I5: 3er | J5: 2er | K5: 1er | M5: Tipp | P5: Pkt. | S5: Tipp | V5: Pkt. | Y5: Tipp | AB5: Pkt. | AE5: Tipp | AH5: Pkt. | AK5: Tipp | AN5: Pkt. | AQ5: Tipp | AT5: Pkt. | AW5: Tipp | AZ5: Pkt. | BC5: Tipp | BF5: Pkt. | BI5: Tipp | BL5: Pkt. | BO5: Tipp | BR5: Pkt. | BU5: Tipp | BX5: Pkt. | CA5: Tipp | CD5: Pkt. | CG5: Tipp | CJ5: Pkt. | CM5: Tipp | CP5: Pkt. | CS5: Tipp | CV5: Pkt. | CY5: Tipp | DB5: Pkt. | DE5: Tipp | DH5: Pkt. | DK5: Tipp | DN5: Pkt. | DQ5: Tipp | DT5: Pkt. | DW5: Tipp | DZ5: Pkt. | EC5: Tipp | EF5: Pkt. | EI5: Tipp | EL5: Pkt. | EO5: Tipp | ER5: Pkt. | EU5: Tipp | EX5: Pkt. | FA5: Tipp | FD5: Pkt. | FG5: Tipp | FJ5: Pkt. | FM5: Tipp | FP5: Pkt. | FS5: Tipp | FV5: Pkt. | FY5: Tipp | GB5: Pkt. | GE5: Tipp | GH5: Pkt. | GK5: Tipp | GN5: Pkt. | GQ5: Tipp | GT5: Pkt.
A6: sa | B6: Werder Bremen | C6: : | D6: TSG Hoffenheim | E6: 0 | F6: : | G6: 2 | I6: =COUNTIF(P6,3)+COUNTIF(V6,3)+COUNTIF(AB6,3)+COUNTIF(AH6,3)+COUNTIF(AN6,3)+COUNTIF(AT6,3)+COUNTIF(AZ6,3)+COUNTIF(BF6,3)+COUNTIF(BL6,3)+COUNTIF(BR6,3)+COUNTIF(BX6,3)+COUNTIF(CD6,3)+COUNTIF(CJ6,3)+COUNTIF(CP6,3)+COUNTIF(CV6,3)+COUNTIF(DB6,3)+COUNTIF(DH6,3)+COUNTIF(DN6,3)+COUNTIF(DT6,3)+COUNTIF(DZ6,3)+COUNTIF(EF6,3)+COUNTIF(EL6,3)+COUNTIF(ER6,3)+COUNTIF(EX6,3)+COUNTIF(FD6,3)+COUNTIF(FJ6,3)+COUNTIF(FP6,3)+COUNTIF(FV6,3)+COUNTIF(GB6,3)+COUNTIF(GH6,3)+COUNTIF(GN6,3)+COUNTIF(GT6,3) -> 0 | J6: =COUNTIF(P6,2)+COUNTIF(V6,2)+COUNTIF(AB6,2)+COUNTIF(AH6,2)+COUNTIF(AN6,2)+COUNTIF(AT6,2)+COUNTIF(AZ6,2)+COUNTIF(BF6,2)+COUNTIF(BL6,2)+COUNTIF(BR6,2)+COUNTIF(BX6,2)+COUNTIF(CD6,2)+COUNTIF(CJ6,2)+COUNTIF(CP6,2)+COUNTIF(CV6,2)+COUNTIF(DB6,2)+COUNTIF(DH6,2)+COUNTIF(DN6,2)+COUNTIF(DT6,2)+COUNTIF(DZ6,2)+COUNTIF(EF6,2)+COUNTIF(EL6,2)+COUNTIF(ER6,2)+COUNTIF(EX6,2)+COUNTIF(FD6,2)+COUNTIF(FJ6,2)+COUNTIF(FP6,2)+COUNTIF(FV6,2)+COUNTIF(GB6,2)+COUNTIF(GH6,2)+COUNTIF(GN6,2)+COUNTIF(GT6,2) -> 1 | K6: =COUNTIF(P6,1)+COUNTIF(V6,1)+COUNTIF(AB6,1)+COUNTIF(AH6,1)+COUNTIF(AN6,1)+COUNTIF(AT6,1)+COUNTIF(AZ6,1)+COUNTIF(BF6,1)+COUNTIF(BL6,1)+COUNTIF(BR6,1)+COUNTIF(BX6,1)+COUNTIF(CD6,1)+COUNTIF(CJ6,1)+COUNTIF(CP6,1)+COUNTIF(CV6,1)+COUNTIF(DB6,1)+COUNTIF(DH6,1)+COUNTIF(DN6,1)+COUNTIF(DT6,1)+COUNTIF(DZ6,1)+COUNTIF(EF6,1)+COUNTIF(EL6,1)+COUNTIF(ER6,1)+COUNTIF(EX6,1)+COUNTIF(FD6,1)+COUNTIF(FJ6,1)+COUNTIF(FP6,1)+COUNTIF(FV6,1)+COUNTIF(GB6,1)+COUNTIF(GH6,1)+COUNTIF(GN6,1)+COUNTIF(GT6,1) -> 14 | M6: 1 | N6: : | O6: 1 | P6: =IF(ISBLANK($E6),"",(IF(ISBLANK(M6),0,IF((($E6=M6)*($G6=O6))*NOT(ISBLANK($E6)),1,0)+((($E6>$G6)*(M6>O6))+(($E6<$G6)*(M6<O6))+(($E6=$G6)*(M6=O6)))-ISBLANK($E6)*(M6=O6)+(($E6-$G6)=(M6-O6))))) -> 0 | S6: 1 | T6: : | U6: 2 | V6: =IF(ISBLANK($E6),"",(IF(ISBLANK(S6),0,IF((($E6=S6)*($G6=U6))*NOT(ISBLANK($E6)),1,0)+((($E6>$G6)*(S6>U6))+(($E6<$G6)*(S6<U6))+(($E6=$G6)*(S6=U6)))-ISBLANK($E6)*(S6=U6)+(($E6-$G6)=(S6-U6))))) -> 1 | Y6: 1 | Z6: : | AA6: 3 | AB6: =IF(ISBLANK($E6),"",(IF(ISBLANK(Y6),0,IF((($E6=Y6)*($G6=AA6))*NOT(ISBLANK($E6)),1,0)+((($E6>$G6)*(Y6>AA6))+(($E6<$G6)*(Y6<AA6))+(($E6=$G6)*(Y6=AA6)))-ISBLANK($E6)*(Y6=AA6)+(($E6-$G6)=(Y6-AA6))))) -> 2 | AE6: 2 | AF6: : | AG6: 1 | AH6: =IF(ISBLANK($E6),"",(IF(ISBLANK(AE6),0,IF((($E6=AE6)*($G6=AG6))*NOT(ISBLANK($E6)),1,0)+((($E6>$G6)*(AE6>AG6))+(($E6<$G6)*(AE6<AG6))+(($E6=$G6)*(AE6=AG6)))-ISBLANK($E6)*(AE6=AG6)+(($E6-$G6)=(AE6-AG6))))) -> 0 | AK6: 2 | AL6: : | AM6: 2 | AN6: =IF(ISBLANK($E6),"",(IF(ISBLANK(AK6),0,IF((($E6=AK6)*($G6=AM6))*NOT(ISBLANK($E6)),1,0)+((($E6>$G6)*(AK6>AM6))+(($E6<$G6)*(AK6<AM6))+(($E6=$G6)*(AK6=AM6)))-ISBLANK($E6)*(AK6=AM6)+(($E6-$G6)=(AK6-AM6))))) -> 0 | AQ6: 2 | AR6: : | AS6: 1 | AT6: =IF(ISBLANK($E6),"",(IF(ISBLANK(AQ6),0,IF((($E6=AQ6)*($G6=AS6))*NOT(ISBLANK($E6)),1,0)+((($E6>$G6)*(AQ6>AS6))+(($E6<$G6)*(AQ6<AS6))+(($E6=$G6)*(AQ6=AS6)))-ISBLANK($E6)*(AQ6=AS6)+(($E6-$G6)=(AQ6-AS6))))) -> 0 | AW6: 1 | AX6: : | AY6: 1 | AZ6: =IF(ISBLANK($E6),"",(IF(ISBLANK(AW6),0,IF((($E6=AW6)*($G6=AY6))*NOT(ISBLANK($E6)),1,0)+((($E6>$G6)*(AW6>AY6))+(($E6<$G6)*(AW6<AY6))+(($E6=$G6)*(AW6=AY6)))-ISBLANK($E6)*(AW6=AY6)+(($E6-$G6)=(AW6-AY6))))) -> 0 | BC6: 2 | BD6: : | BE6: 2 | BF6: =IF(ISBLANK($E6),"",(IF(ISBLANK(BC6),0,IF((($E6=BC6)*($G6=BE6))*NOT(ISBLANK($E6)),1,0)+((($E6>$G6)*(BC6>BE6))+(($E6<$G6)*(BC6<BE6))+(($E6=$G6)*(BC6=BE6)))-ISBLANK($E6)*(BC6=BE6)+(($E6-$G6)=(BC6-BE6))))) -> 0 | BI6: 1 | BJ6: : | BK6: 2 | BL6: =IF(ISBLANK($E6),"",(IF(ISBLANK(BI6),0,IF((($E6=BI6)*($G6=BK6))*NOT(ISBLANK($E6)),1,0)+((($E6>$G6)*(BI6>BK6))+(($E6<$G6)*(BI6<BK6))+(($E6=$G6)*(BI6=BK6)))-ISBLANK($E6)*(BI6=BK6)+(($E6-$G6)=(BI6-BK6))))) -> 1 | BO6: 0 | BP6: : | BQ6: 1 | BR6: =IF(ISBLANK($E6),"",(IF(ISBLANK(BO6),0,IF((($E6=BO6)*($G6=BQ6))*NOT(ISBLANK($E6)),1,0)+((($E6>$G6)*(BO6>BQ6))+(($E6<$G6)*(BO6<BQ6))+(($E6=$G6)*(BO6=BQ6)))-ISBLANK($E6)*(BO6=BQ6)+(($E6-$G6)=(BO6-BQ6))))) -> 1 | BU6: 2 | BV6: : | BW6: 2 | BX6: =IF(ISBLANK($E6),"",(IF(ISBLANK(BU6),0,IF((($E6=BU6)*($G6=BW6))*NOT(ISBLANK($E6)),1,0)+((($E6>$G6)*(BU6>BW6))+(($E6<$G6)*(BU6<BW6))+(($E6=$G6)*(BU6=BW6)))-ISBLANK($E6)*(BU6=BW6)+(($E6-$G6)=(BU6-BW6))))) -> 0 | CA6: 1 | CB6: : | CC6: 2 | CD6: =IF(ISBLANK($E6),"",(IF(ISBLANK(CA6),0,IF((($E6=CA6)*($G6=CC6))*NOT(ISBLANK($E6)),1,0)+((($E6>$G6)*(CA6>CC6))+(($E6<$G6)*(CA6<CC6))+(($E6=$G6)*(CA6=CC6)))-ISBLANK($E6)*(CA6=CC6)+(($E6-$G6)=(CA6-CC6))))) -> 1 | CG6: 1 | CH6: : | CI6: 2 | CJ6: =IF(ISBLANK($E6),"",(IF(ISBLANK(CG6),0,IF((($E6=CG6)*($G6=CI6))*NOT(ISBLANK($E6)),1,0)+((($E6>$G6)*(CG6>CI6))+(($E6<$G6)*(CG6<CI6))+(($E6=$G6)*(CG6=CI6)))-ISBLANK($E6)*(CG6=CI6)+(($E6-$G6)=(CG6-CI6))))) -> 1 | CM6: 1 | CN6: : | CO6: 2 | CP6: =IF(ISBLANK($E6),"",(IF(ISBLANK(CM6),0,IF((($E6=CM6)*($G6=CO6))*NOT(ISBLANK($E6)),1,0)+((($E6>$G6)*(CM6>CO6))+(($E6<$G6)*(CM6<CO6))+(($E6=$G6)*(CM6=CO6)))-ISBLANK($E6)*(CM6=CO6)+(($E6-$G6)=(CM6-CO6))))) -> 1 | CS6: 2 | CT6: : | CU6: 2 | CV6: =IF(ISBLANK($E6),"",(IF(ISBLANK(CS6),0,IF((($E6=CS6)*($G6=CU6))*NOT(ISBLANK($E6)),1,0)+((($E6>$G6)*(CS6>CU6))+(($E6<$G6)*(CS6<CU6))+(($E6=$G6)*(CS6=CU6)))-ISBLANK($E6)*(CS6=CU6)+(($E6-$G6)=(CS6-CU6))))) -> 0 | CY6: 1 | CZ6: : | DA6: 2 | DB6: =IF(ISBLANK($E6),"",(IF(ISBLANK(CY6),0,IF((($E6=CY6)*($G6=DA6))*NOT(ISBLANK($E6)),1,0)+((($E6>$G6)*(CY6>DA6))+(($E6<$G6)*(CY6<DA6))+(($E6=$G6)*(CY6=DA6)))-ISBLANK($E6)*(CY6=DA6)+(($E6-$G6)=(CY6-DA6))))) -> 1 | DE6: 1 | DF6: : | DG6: 2 | DH6: =IF(ISBLANK($E6),"",(IF(ISBLANK(DE6),0,IF((($E6=DE6)*($G6=DG6))*NOT(ISBLANK($E6)),1,0)+((($E6>$G6)*(DE6>DG6))+(($E6<$G6)*(DE6<DG6))+(($E6=$G6)*(DE6=DG6)))-ISBLANK($E6)*(DE6=DG6)+(($E6-$G6)=(DE6-DG6))))) -> 1 | DK6: 1 | DL6: : | DM6: 2 | DN6: =IF(ISBLANK($E6),"",(IF(ISBLANK(DK6),0,IF((($E6=DK6)*($G6=DM6))*NOT(ISBLANK($E6)),1,0)+((($E6>$G6)*(DK6>DM6))+(($E6<$G6)*(DK6<DM6))+(($E6=$G6)*(DK6=DM6)))-ISBLANK($E6)*(DK6=DM6)+(($E6-$G6)=(DK6-DM6))))) -> 1 | DQ6: 1 | DR6: : | DS6: 1 | DT6: =IF(ISBLANK($E6),"",(IF(ISBLANK(DQ6),0,IF((($E6=DQ6)*($G6=DS6))*NOT(ISBLANK($E6)),1,0)+((($E6>$G6)*(DQ6>DS6))+(($E6<$G6)*(DQ6<DS6))+(($E6=$G6)*(DQ6=DS6)))-ISBLANK($E6)*(DQ6=DS6)+(($E6-$G6)=(DQ6-DS6))))) -> 0 | DW6: 2 | DX6: : | DY6: 1 | DZ6: =IF(ISBLANK($E6),"",(IF(ISBLANK(DW6),0,IF((($E6=DW6)*($G6=DY6))*NOT(ISBLANK($E6)),1,0)+((($E6>$G6)*(DW6>DY6))+(($E6<$G6)*(DW6<DY6))+(($E6=$G6)*(DW6=DY6)))-ISBLANK($E6)*(DW6=DY6)+(($E6-$G6)=(DW6-DY6))))) -> 0 | EC6: 0 | ED6: : | EE6: 1 | EF6: =IF(ISBLANK($E6),"",(IF(ISBLANK(EC6),0,IF((($E6=EC6)*($G6=EE6))*NOT(ISBLANK($E6)),1,0)+((($E6>$G6)*(EC6>EE6))+(($E6<$G6)*(EC6<EE6))+(($E6=$G6)*(EC6=EE6)))-ISBLANK($E6)*(EC6=EE6)+(($E6-$G6)=(EC6-EE6))))) -> 1 | EI6: 1 | EJ6: : | EK6: 2 | EL6: =IF(ISBLANK($E6),"",(IF(ISBLANK(EI6),0,IF((($E6=EI6)*($G6=EK6))*NOT(ISBLANK($E6)),1,0)+((($E6>$G6)*(EI6>EK6))+(($E6<$G6)*(EI6<EK6))+(($E6=$G6)*(EI6=EK6)))-ISBLANK($E6)*(EI6=EK6)+(($E6-$G6)=(EI6-EK6))))) -> 1 | EO6: 1 | EP6: : | EQ6: 2 | ER6: =IF(ISBLANK($E6),"",(IF(ISBLANK(EO6),0,IF((($E6=EO6)*($G6=EQ6))*NOT(ISBLANK($E6)),1,0)+((($E6>$G6)*(EO6>EQ6))+(($E6<$G6)*(EO6<EQ6))+(($E6=$G6)*(EO6=EQ6)))-ISBLANK($E6)*(EO6=EQ6)+(($E6-$G6)=(EO6-EQ6))))) -> 1 | EU6: 1 | EV6: : | EW6: 2 | EX6: =IF(ISBLANK($E6),"",(IF(ISBLANK(EU6),0,IF((($E6=EU6)*($G6=EW6))*NOT(ISBLANK($E6)),1,0)+((($E6>$G6)*(EU6>EW6))+(($E6<$G6)*(EU6<EW6))+(($E6=$G6)*(EU6=EW6)))-ISBLANK($E6)*(EU6=EW6)+(($E6-$G6)=(EU6-EW6))))) -> 1 | FA6: 3 | FB6: : | FC6: 2 | FD6: =IF(ISBLANK($E6),"",(IF(ISBLANK(FA6),0,IF((($E6=FA6)*($G6=FC6))*NOT(ISBLANK($E6)),1,0)+((($E6>$G6)*(FA6>FC6))+(($E6<$G6)*(FA6<FC6))+(($E6=$G6)*(FA6=FC6)))-ISBLANK($E6)*(FA6=FC6)+(($E6-$G6)=(FA6-FC6))))) -> 0 | FG6: 1 | FH6: : | FI6: 1 | FJ6: =IF(ISBLANK($E6),"",(IF(ISBLANK(FG6),0,IF((($E6=FG6)*($G6=FI6))*NOT(ISBLANK($E6)),1,0)+((($E6>$G6)*(FG6>FI6))+(($E6<$G6)*(FG6<FI6))+(($E6=$G6)*(FG6=FI6)))-ISBLANK($E6)*(FG6=FI6)+(($E6-$G6)=(FG6-FI6))))) -> 0 | FM6: 2 | FN6: : | FO6: 1 | FP6: =IF(ISBLANK($E6),"",(IF(ISBLANK(FM6),0,IF((($E6=FM6)*($G6=FO6))*NOT(ISBLANK($E6)),1,0)+((($E6>$G6)*(FM6>FO6))+(($E6<$G6)*(FM6<FO6))+(($E6=$G6)*(FM6=FO6)))-ISBLANK($E6)*(FM6=FO6)+(($E6-$G6)=(FM6-FO6))))) -> 0 | FS6: 1 | FT6: : | FU6: 2 | FV6: =IF(ISBLANK($E6),"",(IF(ISBLANK(FS6),0,IF((($E6=FS6)*($G6=FU6))*NOT(ISBLANK($E6)),1,0)+((($E6>$G6)*(FS6>FU6))+(($E6<$G6)*(FS6<FU6))+(($E6=$G6)*(FS6=FU6)))-ISBLANK($E6)*(FS6=FU6)+(($E6-$G6)=(FS6-FU6))))) -> 1 | FY6: 2 | FZ6: : | GA6: 2 | GB6: =IF(ISBLANK($E6),"",(IF(ISBLANK(FY6),0,IF((($E6=FY6)*($G6=GA6))*NOT(ISBLANK($E6)),1,0)+((($E6>$G6)*(FY6>GA6))+(($E6<$G6)*(FY6<GA6))+(($E6=$G6)*(FY6=GA6)))-ISBLANK($E6)*(FY6=GA6)+(($E6-$G6)=(FY6-GA6))))) -> 0 | GE6: 2 | GF6: : | GG6: 1 | GH6: =IF(ISBLANK($E6),"",(IF(ISBLANK(GE6),0,IF((($E6=GE6)*($G6=GG6))*NOT(ISBLANK($E6)),1,0)+((($E6>$G6)*(GE6>GG6))+(($E6<$G6)*(GE6<GG6))+(($E6=$G6)*(GE6=GG6)))-ISBLANK($E6)*(GE6=GG6)+(($E6-$G6)=(GE6-GG6))))) -> 0 | GK6: 2 | GL6: : | GM6: 1 | GN6: =IF(ISBLANK($E6),"",(IF(ISBLANK(GK6),0,IF((($E6=GK6)*($G6=GM6))*NOT(ISBLANK($E6)),1,0)+((($E6>$G6)*(GK6>GM6))+(($E6<$G6)*(GK6<GM6))+(($E6=$G6)*(GK6=GM6)))-ISBLANK($E6)*(GK6=GM6)+(($E6-$G6)=(GK6-GM6))))) -> 0 | GQ6: 2 | GR6: : | GS6: 2 | GT6: =IF(ISBLANK($E6),"",(IF(ISBLANK(GQ6),0,IF((($E6=GQ6)*($G6=GS6))*NOT(ISBLANK($E6)),1,0)+((($E6>$G6)*(GQ6>GS6))+(($E6<$G6)*(GQ6<GS6))+(($E6=$G6)*(GQ6=GS6)))-ISBLANK($E6)*(GQ6=GS6)+(($E6-$G6)=(GQ6-GS6))))) -> 0
A7: so | B7: Bayern München | C7: : | D7: VfL Wolfsburg | E7: 8 | F7: : | G7: 1 | I7: =COUNTIF(P7,3)+COUNTIF(V7,3)+COUNTIF(AB7,3)+COUNTIF(AH7,3)+COUNTIF(AN7,3)+COUNTIF(AT7,3)+COUNTIF(AZ7,3)+COUNTIF(BF7,3)+COUNTIF(BL7,3)+COUNTIF(BR7,3)+COUNTIF(BX7,3)+COUNTIF(CD7,3)+COUNTIF(CJ7,3)+COUNTIF(CP7,3)+COUNTIF(CV7,3)+COUNTIF(DB7,3)+COUNTIF(DH7,3)+COUNTIF(DN7,3)+COUNTIF(DT7,3)+COUNTIF(DZ7,3)+COUNTIF(EF7,3)+COUNTIF(EL7,3)+COUNTIF(ER7,3)+COUNTIF(EX7,3)+COUNTIF(FD7,3)+COUNTIF(FJ7,3)+COUNTIF(FP7,3)+COUNTIF(FV7,3)+COUNTIF(GB7,3)+COUNTIF(GH7,3)+COUNTIF(GN7,3)+COUNTIF(GT7,3) -> 0 | J7: =COUNTIF(P7,2)+COUNTIF(V7,2)+COUNTIF(AB7,2)+COUNTIF(AH7,2)+COUNTIF(AN7,2)+COUNTIF(AT7,2)+COUNTIF(AZ7,2)+COUNTIF(BF7,2)+COUNTIF(BL7,2)+COUNTIF(BR7,2)+COUNTIF(BX7,2)+COUNTIF(CD7,2)+COUNTIF(CJ7,2)+COUNTIF(CP7,2)+COUNTIF(CV7,2)+COUNTIF(DB7,2)+COUNTIF(DH7,2)+COUNTIF(DN7,2)+COUNTIF(DT7,2)+COUNTIF(DZ7,2)+COUNTIF(EF7,2)+COUNTIF(EL7,2)+COUNTIF(ER7,2)+COUNTIF(EX7,2)+COUNTIF(FD7,2)+COUNTIF(FJ7,2)+COUNTIF(FP7,2)+COUNTIF(FV7,2)+COUNTIF(GB7,2)+COUNTIF(GH7,2)+COUNTIF(GN7,2)+COUNTIF(GT7,2) -> 0 | K7: =COUNTIF(P7,1)+COUNTIF(V7,1)+COUNTIF(AB7,1)+COUNTIF(AH7,1)+COUNTIF(AN7,1)+COUNTIF(AT7,1)+COUNTIF(AZ7,1)+COUNTIF(BF7,1)+COUNTIF(BL7,1)+COUNTIF(BR7,1)+COUNTIF(BX7,1)+COUNTIF(CD7,1)+COUNTIF(CJ7,1)+COUNTIF(CP7,1)+COUNTIF(CV7,1)+COUNTIF(DB7,1)+COUNTIF(DH7,1)+COUNTIF(DN7,1)+COUNTIF(DT7,1)+COUNTIF(DZ7,1)+COUNTIF(EF7,1)+COUNTIF(EL7,1)+COUNTIF(ER7,1)+COUNTIF(EX7,1)+COUNTIF(FD7,1)+COUNTIF(FJ7,1)+COUNTIF(FP7,1)+COUNTIF(FV7,1)+COUNTIF(GB7,1)+COUNTIF(GH7,1)+COUNTIF(GN7,1)+COUNTIF(GT7,1) -> 32 | M7: 2 | N7: : | O7: 0 | P7: =IF(ISBLANK($E7),"",(IF(ISBLANK(M7),0,IF((($E7=M7)*($G7=O7))*NOT(ISBLANK($E7)),1,0)+((($E7>$G7)*(M7>O7))+(($E7<$G7)*(M7<O7))+(($E7=$G7)*(M7=O7)))-ISBLANK($E7)*(M7=O7)+(($E7-$G7)=(M7-O7))))) -> 1 | S7: 3 | T7: : | U7: 0 | V7: =IF(ISBLANK($E7),"",(IF(ISBLANK(S7),0,IF((($E7=S7)*($G7=U7))*NOT(ISBLANK($E7)),1,0)+((($E7>$G7)*(S7>U7))+(($E7<$G7)*(S7<U7))+(($E7=$G7)*(S7=U7)))-ISBLANK($E7)*(S7=U7)+(($E7-$G7)=(S7-U7))))) -> 1 | Y7: 4 | Z7: : | AA7: 1 | AB7: =IF(ISBLANK($E7),"",(IF(ISBLANK(Y7),0,IF((($E7=Y7)*($G7=AA7))*NOT(ISBLANK($E7)),1,0)+((($E7>$G7)*(Y7>AA7))+(($E7<$G7)*(Y7<AA7))+(($E7=$G7)*(Y7=AA7)))-ISBLANK($E7)*(Y7=AA7)+(($E7-$G7)=(Y7-AA7))))) -> 1 | AE7: 3 | AF7: : | AG7: 1 | AH7: =IF(ISBLANK($E7),"",(IF(ISBLANK(AE7),0,IF((($E7=AE7)*($G7=AG7))*NOT(ISBLANK($E7)),1,0)+((($E7>$G7)*(AE7>AG7))+(($E7<$G7)*(AE7<AG7))+(($E7=$G7)*(AE7=AG7)))-ISBLANK($E7)*(AE7=AG7)+(($E7-$G7)=(AE7-AG7))))) -> 1 | AK7: 3 | AL7: : | AM7: 1 | AN7: =IF(ISBLANK($E7),"",(IF(ISBLANK(AK7),0,IF((($E7=AK7)*($G7=AM7))*NOT(ISBLANK($E7)),1,0)+((($E7>$G7)*(AK7>AM7))+(($E7<$G7)*(AK7<AM7))+(($E7=$G7)*(AK7=AM7)))-ISBLANK($E7)*(AK7=AM7)+(($E7-$G7)=(AK7-AM7))))) -> 1 | AQ7: 4 | AR7: : | AS7: 0 | AT7: =IF(ISBLANK($E7),"",(IF(ISBLANK(AQ7),0,IF((($E7=AQ7)*($G7=AS7))*NOT(ISBLANK($E7)),1,0)+((($E7>$G7)*(AQ7>AS7))+(($E7<$G7)*(AQ7<AS7))+(($E7=$G7)*(AQ7=AS7)))-ISBLANK($E7)*(AQ7=AS7)+(($E7-$G7)=(AQ7-AS7))))) -> 1 | AW7: 3 | AX7: : | AY7: 1 | AZ7: =IF(ISBLANK($E7),"",(IF(ISBLANK(AW7),0,IF((($E7=AW7)*($G7=AY7))*NOT(ISBLANK($E7)),1,0)+((($E7>$G7)*(AW7>AY7))+(($E7<$G7)*(AW7<AY7))+(($E7=$G7)*(AW7=AY7)))-ISBLANK($E7)*(AW7=AY7)+(($E7-$G7)=(AW7-AY7))))) -> 1 | BC7: 3 | BD7: : | BE7: 1 | BF7: =IF(ISBLANK($E7),"",(IF(ISBLANK(BC7),0,IF((($E7=BC7)*($G7=BE7))*NOT(ISBLANK($E7)),1,0)+((($E7>$G7)*(BC7>BE7))+(($E7<$G7)*(BC7<BE7))+(($E7=$G7)*(BC7=BE7)))-ISBLANK($E7)*(BC7=BE7)+(($E7-$G7)=(BC7-BE7))))) -> 1 | BI7: 3 | BJ7: : | BK7: 1 | BL7: =IF(ISBLANK($E7),"",(IF(ISBLANK(BI7),0,IF((($E7=BI7)*($G7=BK7))*NOT(ISBLANK($E7)),1,0)+((($E7>$G7)*(BI7>BK7))+(($E7<$G7)*(BI7<BK7))+(($E7=$G7)*(BI7=BK7)))-ISBLANK($E7)*(BI7=BK7)+(($E7-$G7)=(BI7-BK7))))) -> 1 | BO7: 3 | BP7: : | BQ7: 0 | BR7: =IF(ISBLANK($E7),"",(IF(ISBLANK(BO7),0,IF((($E7=BO7)*($G7=BQ7))*NOT(ISBLANK($E7)),1,0)+((($E7>$G7)*(BO7>BQ7))+(($E7<$G7)*(BO7<BQ7))+(($E7=$G7)*(BO7=BQ7)))-ISBLANK($E7)*(BO7=BQ7)+(($E7-$G7)=(BO7-BQ7))))) -> 1 | BU7: 3 | BV7: : | BW7: 0 | BX7: =IF(ISBLANK($E7),"",(IF(ISBLANK(BU7),0,IF((($E7=BU7)*($G7=BW7))*NOT(ISBLANK($E7)),1,0)+((($E7>$G7)*(BU7>BW7))+(($E7<$G7)*(BU7<BW7))+(($E7=$G7)*(BU7=BW7)))-ISBLANK($E7)*(BU7=BW7)+(($E7-$G7)=(BU7-BW7))))) -> 1 | CA7: 3 | CB7: : | CC7: 0 | CD7: =IF(ISBLANK($E7),"",(IF(ISBLANK(CA7),0,IF((($E7=CA7)*($G7=CC7))*NOT(ISBLANK($E7)),1,0)+((($E7>$G7)*(CA7>CC7))+(($E7<$G7)*(CA7<CC7))+(($E7=$G7)*(CA7=CC7)))-ISBLANK($E7)*(CA7=CC7)+(($E7-$G7)=(CA7-CC7))))) -> 1 | CG7: 4 | CH7: : | CI7: 0 | CJ7: =IF(ISBLANK($E7),"",(IF(ISBLANK(CG7),0,IF((($E7=CG7)*($G7=CI7))*NOT(ISBLANK($E7)),1,0)+((($E7>$G7)*(CG7>CI7))+(($E7<$G7)*(CG7<CI7))+(($E7=$G7)*(CG7=CI7)))-ISBLANK($E7)*(CG7=CI7)+(($E7-$G7)=(CG7-CI7))))) -> 1 | CM7: 3 | CN7: : | CO7: 0 | CP7: =IF(ISBLANK($E7),"",(IF(ISBLANK(CM7),0,IF((($E7=CM7)*($G7=CO7))*NOT(ISBLANK($E7)),1,0)+((($E7>$G7)*(CM7>CO7))+(($E7<$G7)*(CM7<CO7))+(($E7=$G7)*(CM7=CO7)))-ISBLANK($E7)*(CM7=CO7)+(($E7-$G7)=(CM7-CO7))))) -> 1 | CS7: 3 | CT7: : | CU7: 0 | CV7: =IF(ISBLANK($E7),"",(IF(ISBLANK(CS7),0,IF((($E7=CS7)*($G7=CU7))*NOT(ISBLANK($E7)),1,0)+((($E7>$G7)*(CS7>CU7))+(($E7<$G7)*(CS7<CU7))+(($E7=$G7)*(CS7=CU7)))-ISBLANK($E7)*(CS7=CU7)+(($E7-$G7)=(CS7-CU7))))) -> 1 | CY7: 3 | CZ7: : | DA7: 1 | DB7: =IF(ISBLANK($E7),"",(IF(ISBLANK(CY7),0,IF((($E7=CY7)*($G7=DA7))*NOT(ISBLANK($E7)),1,0)+((($E7>$G7)*(CY7>DA7))+(($E7<$G7)*(CY7<DA7))+(($E7=$G7)*(CY7=DA7)))-ISBLANK($E7)*(CY7=DA7)+(($E7-$G7)=(CY7-DA7))))) -> 1 | DE7: 4 | DF7: : | DG7: 0 | DH7: =IF(ISBLANK($E7),"",(IF(ISBLANK(DE7),0,IF((($E7=DE7)*($G7=DG7))*NOT(ISBLANK($E7)),1,0)+((($E7>$G7)*(DE7>DG7))+(($E7<$G7)*(DE7<DG7))+(($E7=$G7)*(DE7=DG7)))-ISBLANK($E7)*(DE7=DG7)+(($E7-$G7)=(DE7-DG7))))) -> 1 | DK7: 3 | DL7: : | DM7: 1 | DN7: =IF(ISBLANK($E7),"",(IF(ISBLANK(DK7),0,IF((($E7=DK7)*($G7=DM7))*NOT(ISBLANK($E7)),1,0)+((($E7>$G7)*(DK7>DM7))+(($E7<$G7)*(DK7<DM7))+(($E7=$G7)*(DK7=DM7)))-ISBLANK($E7)*(DK7=DM7)+(($E7-$G7)=(DK7-DM7))))) -> 1 | DQ7: 3 | DR7: : | DS7: 0 | DT7: =IF(ISBLANK($E7),"",(IF(ISBLANK(DQ7),0,IF((($E7=DQ7)*($G7=DS7))*NOT(ISBLANK($E7)),1,0)+((($E7>$G7)*(DQ7>DS7))+(($E7<$G7)*(DQ7<DS7))+(($E7=$G7)*(DQ7=DS7)))-ISBLANK($E7)*(DQ7=DS7)+(($E7-$G7)=(DQ7-DS7))))) -> 1 | DW7: 3 | DX7: : | DY7: 0 | DZ7: =IF(ISBLANK($E7),"",(IF(ISBLANK(DW7),0,IF((($E7=DW7)*($G7=DY7))*NOT(ISBLANK($E7)),1,0)+((($E7>$G7)*(DW7>DY7))+(($E7<$G7)*(DW7<DY7))+(($E7=$G7)*(DW7=DY7)))-ISBLANK($E7)*(DW7=DY7)+(($E7-$G7)=(DW7-DY7))))) -> 1 | EC7: 2 | ED7: : | EE7: 0 | EF7: =IF(ISBLANK($E7),"",(IF(ISBLANK(EC7),0,IF((($E7=EC7)*($G7=EE7))*NOT(ISBLANK($E7)),1,0)+((($E7>$G7)*(EC7>EE7))+(($E7<$G7)*(EC7<EE7))+(($E7=$G7)*(EC7=EE7)))-ISBLANK($E7)*(EC7=EE7)+(($E7-$G7)=(EC7-EE7))))) -> 1 | EI7: 4 | EJ7: : | EK7: 0 | EL7: =IF(ISBLANK($E7),"",(IF(ISBLANK(EI7),0,IF((($E7=EI7)*($G7=EK7))*NOT(ISBLANK($E7)),1,0)+((($E7>$G7)*(EI7>EK7))+(($E7<$G7)*(EI7<EK7))+(($E7=$G7)*(EI7=EK7)))-ISBLANK($E7)*(EI7=EK7)+(($E7-$G7)=(EI7-EK7))))) -> 1 | EO7: 3 | EP7: : | EQ7: 1 | ER7: =IF(ISBLANK($E7),"",(IF(ISBLANK(EO7),0,IF((($E7=EO7)*($G7=EQ7))*NOT(ISBLANK($E7)),1,0)+((($E7>$G7)*(EO7>EQ7))+(($E7<$G7)*(EO7<EQ7))+(($E7=$G7)*(EO7=EQ7)))-ISBLANK($E7)*(EO7=EQ7)+(($E7-$G7)=(EO7-EQ7))))) -> 1 | EU7: 4 | EV7: : | EW7: 1 | EX7: =IF(ISBLANK($E7),"",(IF(ISBLANK(EU7),0,IF((($E7=EU7)*($G7=EW7))*NOT(ISBLANK($E7)),1,0)+((($E7>$G7)*(EU7>EW7))+(($E7<$G7)*(EU7<EW7))+(($E7=$G7)*(EU7=EW7)))-ISBLANK($E7)*(EU7=EW7)+(($E7-$G7)=(EU7-EW7))))) -> 1 | FA7: 6 | FB7: : | FC7: 0 | FD7: =IF(ISBLANK($E7),"",(IF(ISBLANK(FA7),0,IF((($E7=FA7)*($G7=FC7))*NOT(ISBLANK($E7)),1,0)+((($E7>$G7)*(FA7>FC7))+(($E7<$G7)*(FA7<FC7))+(($E7=$G7)*(FA7=FC7)))-ISBLANK($E7)*(FA7=FC7)+(($E7-$G7)=(FA7-FC7))))) -> 1 | FG7: 4 | FH7: : | FI7: 0 | FJ7: =IF(ISBLANK($E7),"",(IF(ISBLANK(FG7),0,IF((($E7=FG7)*($G7=FI7))*NOT(ISBLANK($E7)),1,0)+((($E7>$G7)*(FG7>FI7))+(($E7<$G7)*(FG7<FI7))+(($E7=$G7)*(FG7=FI7)))-ISBLANK($E7)*(FG7=FI7)+(($E7-$G7)=(FG7-FI7))))) -> 1 | FM7: 3 | FN7: : | FO7: 1 | FP7: =IF(ISBLANK($E7),"",(IF(ISBLANK(FM7),0,IF((($E7=FM7)*($G7=FO7))*NOT(ISBLANK($E7)),1,0)+((($E7>$G7)*(FM7>FO7))+(($E7<$G7)*(FM7<FO7))+(($E7=$G7)*(FM7=FO7)))-ISBLANK($E7)*(FM7=FO7)+(($E7-$G7)=(FM7-FO7))))) -> 1 | FS7: 2 | FT7: : | FU7: 0 | FV7: =IF(ISBLANK($E7),"",(IF(ISBLANK(FS7),0,IF((($E7=FS7)*($G7=FU7))*NOT(ISBLANK($E7)),1,0)+((($E7>$G7)*(FS7>FU7))+(($E7<$G7)*(FS7<FU7))+(($E7=$G7)*(FS7=FU7)))-ISBLANK($E7)*(FS7=FU7)+(($E7-$G7)=(FS7-FU7))))) -> 1 | FY7: 4 | FZ7: : | GA7: 1 | GB7: =IF(ISBLANK($E7),"",(IF(ISBLANK(FY7),0,IF((($E7=FY7)*($G7=GA7))*NOT(ISBLANK($E7)),1,0)+((($E7>$G7)*(FY7>GA7))+(($E7<$G7)*(FY7<GA7))+(($E7=$G7)*(FY7=GA7)))-ISBLANK($E7)*(FY7=GA7)+(($E7-$G7)=(FY7-GA7))))) -> 1 | GE7: 5 | GF7: : | GG7: 0 | GH7: =IF(ISBLANK($E7),"",(IF(ISBLANK(GE7),0,IF((($E7=GE7)*($G7=GG7))*NOT(ISBLANK($E7)),1,0)+((($E7>$G7)*(GE7>GG7))+(($E7<$G7)*(GE7<GG7))+(($E7=$G7)*(GE7=GG7)))-ISBLANK($E7)*(GE7=GG7)+(($E7-$G7)=(GE7-GG7))))) -> 1 | GK7: 3 | GL7: : | GM7: 0 | GN7: =IF(ISBLANK($E7),"",(IF(ISBLANK(GK7),0,IF((($E7=GK7)*($G7=GM7))*NOT(ISBLANK($E7)),1,0)+((($E7>$G7)*(GK7>GM7))+(($E7<$G7)*(GK7<GM7))+(($E7=$G7)*(GK7=GM7)))-ISBLANK($E7)*(GK7=GM7)+(($E7-$G7)=(GK7-GM7))))) -> 1 | GQ7: 3 | GR7: : | GS7: 0 | GT7: =IF(ISBLANK($E7),"",(IF(ISBLANK(GQ7),0,IF((($E7=GQ7)*($G7=GS7))*NOT(ISBLANK($E7)),1,0)+((($E7>$G7)*(GQ7>GS7))+(($E7<$G7)*(GQ7<GS7))+(($E7=$G7)*(GQ7=GS7)))-ISBLANK($E7)*(GQ7=GS7)+(($E7-$G7)=(GQ7-GS7))))) -> 1
A8: so | B8: Bor. Mönchengladbach | C8: : | D8: FC Augsburg | E8: 4 | F8: : | G8: 0 | I8: =COUNTIF(P8,3)+COUNTIF(V8,3)+COUNTIF(AB8,3)+COUNTIF(AH8,3)+COUNTIF(AN8,3)+COUNTIF(AT8,3)+COUNTIF(AZ8,3)+COUNTIF(BF8,3)+COUNTIF(BL8,3)+COUNTIF(BR8,3)+COUNTIF(BX8,3)+COUNTIF(CD8,3)+COUNTIF(CJ8,3)+COUNTIF(CP8,3)+COUNTIF(CV8,3)+COUNTIF(DB8,3)+COUNTIF(DH8,3)+COUNTIF(DN8,3)+COUNTIF(DT8,3)+COUNTIF(DZ8,3)+COUNTIF(EF8,3)+COUNTIF(EL8,3)+COUNTIF(ER8,3)+COUNTIF(EX8,3)+COUNTIF(FD8,3)+COUNTIF(FJ8,3)+COUNTIF(FP8,3)+COUNTIF(FV8,3)+COUNTIF(GB8,3)+COUNTIF(GH8,3)+COUNTIF(GN8,3)+COUNTIF(GT8,3) -> 0 | J8: =COUNTIF(P8,2)+COUNTIF(V8,2)+COUNTIF(AB8,2)+COUNTIF(AH8,2)+COUNTIF(AN8,2)+COUNTIF(AT8,2)+COUNTIF(AZ8,2)+COUNTIF(BF8,2)+COUNTIF(BL8,2)+COUNTIF(BR8,2)+COUNTIF(BX8,2)+COUNTIF(CD8,2)+COUNTIF(CJ8,2)+COUNTIF(CP8,2)+COUNTIF(CV8,2)+COUNTIF(DB8,2)+COUNTIF(DH8,2)+COUNTIF(DN8,2)+COUNTIF(DT8,2)+COUNTIF(DZ8,2)+COUNTIF(EF8,2)+COUNTIF(EL8,2)+COUNTIF(ER8,2)+COUNTIF(EX8,2)+COUNTIF(FD8,2)+COUNTIF(FJ8,2)+COUNTIF(FP8,2)+COUNTIF(FV8,2)+COUNTIF(GB8,2)+COUNTIF(GH8,2)+COUNTIF(GN8,2)+COUNTIF(GT8,2) -> 0 | K8: =COUNTIF(P8,1)+COUNTIF(V8,1)+COUNTIF(AB8,1)+COUNTIF(AH8,1)+COUNTIF(AN8,1)+COUNTIF(AT8,1)+COUNTIF(AZ8,1)+COUNTIF(BF8,1)+COUNTIF(BL8,1)+COUNTIF(BR8,1)+COUNTIF(BX8,1)+COUNTIF(CD8,1)+COUNTIF(CJ8,1)+COUNTIF(CP8,1)+COUNTIF(CV8,1)+COUNTIF(DB8,1)+COUNTIF(DH8,1)+COUNTIF(DN8,1)+COUNTIF(DT8,1)+COUNTIF(DZ8,1)+COUNTIF(EF8,1)+COUNTIF(EL8,1)+COUNTIF(ER8,1)+COUNTIF(EX8,1)+COUNTIF(FD8,1)+COUNTIF(FJ8,1)+COUNTIF(FP8,1)+COUNTIF(FV8,1)+COUNTIF(GB8,1)+COUNTIF(GH8,1)+COUNTIF(GN8,1)+COUNTIF(GT8,1) -> 26 | M8: 0 | N8: : | O8: 0 | P8: =IF(ISBLANK($E8),"",(IF(ISBLANK(M8),0,IF((($E8=M8)*($G8=O8))*NOT(ISBLANK($E8)),1,0)+((($E8>$G8)*(M8>O8))+(($E8<$G8)*(M8<O8))+(($E8=$G8)*(M8=O8)))-ISBLANK($E8)*(M8=O8)+(($E8-$G8)=(M8-O8))))) -> 0 | S8: 2 | T8: : | U8: 1 | V8: =IF(ISBLANK($E8),"",(IF(ISBLANK(S8),0,IF((($E8=S8)*($G8=U8))*NOT(ISBLANK($E8)),1,0)+((($E8>$G8)*(S8>U8))+(($E8<$G8)*(S8<U8))+(($E8=$G8)*(S8=U8)))-ISBLANK($E8)*(S8=U8)+(($E8-$G8)=(S8-U8))))) -> 1 | Y8: 2 | Z8: : | AA8: 1 | AB8: =IF(ISBLANK($E8),"",(IF(ISBLANK(Y8),0,IF((($E8=Y8)*($G8=AA8))*NOT(ISBLANK($E8)),1,0)+((($E8>$G8)*(Y8>AA8))+(($E8<$G8)*(Y8<AA8))+(($E8=$G8)*(Y8=AA8)))-ISBLANK($E8)*(Y8=AA8)+(($E8-$G8)=(Y8-AA8))))) -> 1 | AE8: 2 | AF8: : | AG8: 1 | AH8: =IF(ISBLANK($E8),"",(IF(ISBLANK(AE8),0,IF((($E8=AE8)*($G8=AG8))*NOT(ISBLANK($E8)),1,0)+((($E8>$G8)*(AE8>AG8))+(($E8<$G8)*(AE8<AG8))+(($E8=$G8)*(AE8=AG8)))-ISBLANK($E8)*(AE8=AG8)+(($E8-$G8)=(AE8-AG8))))) -> 1 | AK8: 2 | AL8: : | AM8: 1 | AN8: =IF(ISBLANK($E8),"",(IF(ISBLANK(AK8),0,IF((($E8=AK8)*($G8=AM8))*NOT(ISBLANK($E8)),1,0)+((($E8>$G8)*(AK8>AM8))+(($E8<$G8)*(AK8<AM8))+(($E8=$G8)*(AK8=AM8)))-ISBLANK($E8)*(AK8=AM8)+(($E8-$G8)=(AK8-AM8))))) -> 1 | AQ8: 2 | AR8: : | AS8: 1 | AT8: =IF(ISBLANK($E8),"",(IF(ISBLANK(AQ8),0,IF((($E8=AQ8)*($G8=AS8))*NOT(ISBLANK($E8)),1,0)+((($E8>$G8)*(AQ8>AS8))+(($E8<$G8)*(AQ8<AS8))+(($E8=$G8)*(AQ8=AS8)))-ISBLANK($E8)*(AQ8=AS8)+(($E8-$G8)=(AQ8-AS8))))) -> 1 | AW8: 1 | AX8: : | AY8: 1 | AZ8: =IF(ISBLANK($E8),"",(IF(ISBLANK(AW8),0,IF((($E8=AW8)*($G8=AY8))*NOT(ISBLANK($E8)),1,0)+((($E8>$G8)*(AW8>AY8))+(($E8<$G8)*(AW8<AY8))+(($E8=$G8)*(AW8=AY8)))-ISBLANK($E8)*(AW8=AY8)+(($E8-$G8)=(AW8-AY8))))) -> 0 | BC8: 2 | BD8: : | BE8: 1 | BF8: =IF(ISBLANK($E8),"",(IF(ISBLANK(BC8),0,IF((($E8=BC8)*($G8=BE8))*NOT(ISBLANK($E8)),1,0)+((($E8>$G8)*(BC8>BE8))+(($E8<$G8)*(BC8<BE8))+(($E8=$G8)*(BC8=BE8)))-ISBLANK($E8)*(BC8=BE8)+(($E8-$G8)=(BC8-BE8))))) -> 1 | BI8: 1 | BJ8: : | BK8: 0 | BL8: =IF(ISBLANK($E8),"",(IF(ISBLANK(BI8),0,IF((($E8=BI8)*($G8=BK8))*NOT(ISBLANK($E8)),1,0)+((($E8>$G8)*(BI8>BK8))+(($E8<$G8)*(BI8<BK8))+(($E8=$G8)*(BI8=BK8)))-ISBLANK($E8)*(BI8=BK8)+(($E8-$G8)=(BI8-BK8))))) -> 1 | BO8: 2 | BP8: : | BQ8: 1 | BR8: =IF(ISBLANK($E8),"",(IF(ISBLANK(BO8),0,IF((($E8=BO8)*($G8=BQ8))*NOT(ISBLANK($E8)),1,0)+((($E8>$G8)*(BO8>BQ8))+(($E8<$G8)*(BO8<BQ8))+(($E8=$G8)*(BO8=BQ8)))-ISBLANK($E8)*(BO8=BQ8)+(($E8-$G8)=(BO8-BQ8))))) -> 1 | BU8: 2 | BV8: : | BW8: 1 | BX8: =IF(ISBLANK($E8),"",(IF(ISBLANK(BU8),0,IF((($E8=BU8)*($G8=BW8))*NOT(ISBLANK($E8)),1,0)+((($E8>$G8)*(BU8>BW8))+(($E8<$G8)*(BU8<BW8))+(($E8=$G8)*(BU8=BW8)))-ISBLANK($E8)*(BU8=BW8)+(($E8-$G8)=(BU8-BW8))))) -> 1 | CA8: 1 | CB8: : | CC8: 0 | CD8: =IF(ISBLANK($E8),"",(IF(ISBLANK(CA8),0,IF((($E8=CA8)*($G8=CC8))*NOT(ISBLANK($E8)),1,0)+((($E8>$G8)*(CA8>CC8))+(($E8<$G8)*(CA8<CC8))+(($E8=$G8)*(CA8=CC8)))-ISBLANK($E8)*(CA8=CC8)+(($E8-$G8)=(CA8-CC8))))) -> 1 | CG8: 0 | CH8: : | CI8: 0 | CJ8: =IF(ISBLANK($E8),"",(IF(ISBLANK(CG8),0,IF((($E8=CG8)*($G8=CI8))*NOT(ISBLANK($E8)),1,0)+((($E8>$G8)*(CG8>CI8))+(($E8<$G8)*(CG8<CI8))+(($E8=$G8)*(CG8=CI8)))-ISBLANK($E8)*(CG8=CI8)+(($E8-$G8)=(CG8-CI8))))) -> 0 | CM8: 2 | CN8: : | CO8: 1 | CP8: =IF(ISBLANK($E8),"",(IF(ISBLANK(CM8),0,IF((($E8=CM8)*($G8=CO8))*NOT(ISBLANK($E8)),1,0)+((($E8>$G8)*(CM8>CO8))+(($E8<$G8)*(CM8<CO8))+(($E8=$G8)*(CM8=CO8)))-ISBLANK($E8)*(CM8=CO8)+(($E8-$G8)=(CM8-CO8))))) -> 1 | CS8: 2 | CT8: : | CU8: 1 | CV8: =IF(ISBLANK($E8),"",(IF(ISBLANK(CS8),0,IF((($E8=CS8)*($G8=CU8))*NOT(ISBLANK($E8)),1,0)+((($E8>$G8)*(CS8>CU8))+(($E8<$G8)*(CS8<CU8))+(($E8=$G8)*(CS8=CU8)))-ISBLANK($E8)*(CS8=CU8)+(($E8-$G8)=(CS8-CU8))))) -> 1 | CY8: 2 | CZ8: : | DA8: 1 | DB8: =IF(ISBLANK($E8),"",(IF(ISBLANK(CY8),0,IF((($E8=CY8)*($G8=DA8))*NOT(ISBLANK($E8)),1,0)+((($E8>$G8)*(CY8>DA8))+(($E8<$G8)*(CY8<DA8))+(($E8=$G8)*(CY8=DA8)))-ISBLANK($E8)*(CY8=DA8)+(($E8-$G8)=(CY8-DA8))))) -> 1 | DE8: 1 | DF8: : | DG8: 2 | DH8: =IF(ISBLANK($E8),"",(IF(ISBLANK(DE8),0,IF((($E8=DE8)*($G8=DG8))*NOT(ISBLANK($E8)),1,0)+((($E8>$G8)*(DE8>DG8))+(($E8<$G8)*(DE8<DG8))+(($E8=$G8)*(DE8=DG8)))-ISBLANK($E8)*(DE8=DG8)+(($E8-$G8)=(DE8-DG8))))) -> 0 | DK8: 1 | DL8: : | DM8: 1 | DN8: =IF(ISBLANK($E8),"",(IF(ISBLANK(DK8),0,IF((($E8=DK8)*($G8=DM8))*NOT(ISBLANK($E8)),1,0)+((($E8>$G8)*(DK8>DM8))+(($E8<$G8)*(DK8<DM8))+(($E8=$G8)*(DK8=DM8)))-ISBLANK($E8)*(DK8=DM8)+(($E8-$G8)=(DK8-DM8))))) -> 0 | DQ8: 2 | DR8: : | DS8: 1 | DT8: =IF(ISBLANK($E8),"",(IF(ISBLANK(DQ8),0,IF((($E8=DQ8)*($G8=DS8))*NOT(ISBLANK($E8)),1,0)+((($E8>$G8)*(DQ8>DS8))+(($E8<$G8)*(DQ8<DS8))+(($E8=$G8)*(DQ8=DS8)))-ISBLANK($E8)*(DQ8=DS8)+(($E8-$G8)=(DQ8-DS8))))) -> 1 | DW8: 2 | DX8: : | DY8: 1 | DZ8: =IF(ISBLANK($E8),"",(IF(ISBLANK(DW8),0,IF((($E8=DW8)*($G8=DY8))*NOT(ISBLANK($E8)),1,0)+((($E8>$G8)*(DW8>DY8))+(($E8<$G8)*(DW8<DY8))+(($E8=$G8)*(DW8=DY8)))-ISBLANK($E8)*(DW8=DY8)+(($E8-$G8)=(DW8-DY8))))) -> 1 | EC8: 2 | ED8: : | EE8: 1 | EF8: =IF(ISBLANK($E8),"",(IF(ISBLANK(EC8),0,IF((($E8=EC8)*($G8=EE8))*NOT(ISBLANK($E8)),1,0)+((($E8>$G8)*(EC8>EE8))+(($E8<$G8)*(EC8<EE8))+(($E8=$G8)*(EC8=EE8)))-ISBLANK($E8)*(EC8=EE8)+(($E8-$G8)=(EC8-EE8))))) -> 1 | EI8: 2 | EJ8: : | EK8: 1 | EL8: =IF(ISBLANK($E8),"",(IF(ISBLANK(EI8),0,IF((($E8=EI8)*($G8=EK8))*NOT(ISBLANK($E8)),1,0)+((($E8>$G8)*(EI8>EK8))+(($E8<$G8)*(EI8<EK8))+(($E8=$G8)*(EI8=EK8)))-ISBLANK($E8)*(EI8=EK8)+(($E8-$G8)=(EI8-EK8))))) -> 1 | EO8: 2 | EP8: : | EQ8: 1 | ER8: =IF(ISBLANK($E8),"",(IF(ISBLANK(EO8),0,IF((($E8=EO8)*($G8=EQ8))*NOT(ISBLANK($E8)),1,0)+((($E8>$G8)*(EO8>EQ8))+(($E8<$G8)*(EO8<EQ8))+(($E8=$G8)*(EO8=EQ8)))-ISBLANK($E8)*(EO8=EQ8)+(($E8-$G8)=(EO8-EQ8))))) -> 1 | EU8: 2 | EV8: : | EW8: 1 | EX8: =IF(ISBLANK($E8),"",(IF(ISBLANK(EU8),0,IF((($E8=EU8)*($G8=EW8))*NOT(ISBLANK($E8)),1,0)+((($E8>$G8)*(EU8>EW8))+(($E8<$G8)*(EU8<EW8))+(($E8=$G8)*(EU8=EW8)))-ISBLANK($E8)*(EU8=EW8)+(($E8-$G8)=(EU8-EW8))))) -> 1 | FA8: 2 | FB8: : | FC8: 0 | FD8: =IF(ISBLANK($E8),"",(IF(ISBLANK(FA8),0,IF((($E8=FA8)*($G8=FC8))*NOT(ISBLANK($E8)),1,0)+((($E8>$G8)*(FA8>FC8))+(($E8<$G8)*(FA8<FC8))+(($E8=$G8)*(FA8=FC8)))-ISBLANK($E8)*(FA8=FC8)+(($E8-$G8)=(FA8-FC8))))) -> 1 | FG8: 2 | FH8: : | FI8: 1 | FJ8: =IF(ISBLANK($E8),"",(IF(ISBLANK(FG8),0,IF((($E8=FG8)*($G8=FI8))*NOT(ISBLANK($E8)),1,0)+((($E8>$G8)*(FG8>FI8))+(($E8<$G8)*(FG8<FI8))+(($E8=$G8)*(FG8=FI8)))-ISBLANK($E8)*(FG8=FI8)+(($E8-$G8)=(FG8-FI8))))) -> 1 | FM8: 2 | FN8: : | FO8: 1 | FP8: =IF(ISBLANK($E8),"",(IF(ISBLANK(FM8),0,IF((($E8=FM8)*($G8=FO8))*NOT(ISBLANK($E8)),1,0)+((($E8>$G8)*(FM8>FO8))+(($E8<$G8)*(FM8<FO8))+(($E8=$G8)*(FM8=FO8)))-ISBLANK($E8)*(FM8=FO8)+(($E8-$G8)=(FM8-FO8))))) -> 1 | FS8: 1 | FT8: : | FU8: 0 | FV8: =IF(ISBLANK($E8),"",(IF(ISBLANK(FS8),0,IF((($E8=FS8)*($G8=FU8))*NOT(ISBLANK($E8)),1,0)+((($E8>$G8)*(FS8>FU8))+(($E8<$G8)*(FS8<FU8))+(($E8=$G8)*(FS8=FU8)))-ISBLANK($E8)*(FS8=FU8)+(($E8-$G8)=(FS8-FU8))))) -> 1 | FY8: 2 | FZ8: : | GA8: 1 | GB8: =IF(ISBLANK($E8),"",(IF(ISBLANK(FY8),0,IF((($E8=FY8)*($G8=GA8))*NOT(ISBLANK($E8)),1,0)+((($E8>$G8)*(FY8>GA8))+(($E8<$G8)*(FY8<GA8))+(($E8=$G8)*(FY8=GA8)))-ISBLANK($E8)*(FY8=GA8)+(($E8-$G8)=(FY8-GA8))))) -> 1 | GE8: 1 | GF8: : | GG8: 1 | GH8: =IF(ISBLANK($E8),"",(IF(ISBLANK(GE8),0,IF((($E8=GE8)*($G8=GG8))*NOT(ISBLANK($E8)),1,0)+((($E8>$G8)*(GE8>GG8))+(($E8<$G8)*(GE8<GG8))+(($E8=$G8)*(GE8=GG8)))-ISBLANK($E8)*(GE8=GG8)+(($E8-$G8)=(GE8-GG8))))) -> 0 | GK8: 2 | GL8: : | GM8: 1 | GN8: =IF(ISBLANK($E8),"",(IF(ISBLANK(GK8),0,IF((($E8=GK8)*($G8=GM8))*NOT(ISBLANK($E8)),1,0)+((($E8>$G8)*(GK8>GM8))+(($E8<$G8)*(GK8<GM8))+(($E8=$G8)*(GK8=GM8)))-ISBLANK($E8)*(GK8=GM8)+(($E8-$G8)=(GK8-GM8))))) -> 1 | GQ8: 2 | GR8: : | GS8: 1 | GT8: =IF(ISBLANK($E8),"",(IF(ISBLANK(GQ8),0,IF((($E8=GQ8)*($G8=GS8))*NOT(ISBLANK($E8)),1,0)+((($E8>$G8)*(GQ8>GS8))+(($E8<$G8)*(GQ8<GS8))+(($E8=$G8)*(GQ8=GS8)))-ISBLANK($E8)*(GQ8=GS8)+(($E8-$G8)=(GQ8-GS8))))) -> 1
A9: fr | B9: Eintracht Frankfurt | C9: : | D9: Borussia Dortmund | E9: 3 | F9: : | G9: 3 | I9: =COUNTIF(P9,3)+COUNTIF(V9,3)+COUNTIF(AB9,3)+COUNTIF(AH9,3)+COUNTIF(AN9,3)+COUNTIF(AT9,3)+COUNTIF(AZ9,3)+COUNTIF(BF9,3)+COUNTIF(BL9,3)+COUNTIF(BR9,3)+COUNTIF(BX9,3)+COUNTIF(CD9,3)+COUNTIF(CJ9,3)+COUNTIF(CP9,3)+COUNTIF(CV9,3)+COUNTIF(DB9,3)+COUNTIF(DH9,3)+COUNTIF(DN9,3)+COUNTIF(DT9,3)+COUNTIF(DZ9,3)+COUNTIF(EF9,3)+COUNTIF(EL9,3)+COUNTIF(ER9,3)+COUNTIF(EX9,3)+COUNTIF(FD9,3)+COUNTIF(FJ9,3)+COUNTIF(FP9,3)+COUNTIF(FV9,3)+COUNTIF(GB9,3)+COUNTIF(GH9,3)+COUNTIF(GN9,3)+COUNTIF(GT9,3) -> 0 | J9: =COUNTIF(P9,2)+COUNTIF(V9,2)+COUNTIF(AB9,2)+COUNTIF(AH9,2)+COUNTIF(AN9,2)+COUNTIF(AT9,2)+COUNTIF(AZ9,2)+COUNTIF(BF9,2)+COUNTIF(BL9,2)+COUNTIF(BR9,2)+COUNTIF(BX9,2)+COUNTIF(CD9,2)+COUNTIF(CJ9,2)+COUNTIF(CP9,2)+COUNTIF(CV9,2)+COUNTIF(DB9,2)+COUNTIF(DH9,2)+COUNTIF(DN9,2)+COUNTIF(DT9,2)+COUNTIF(DZ9,2)+COUNTIF(EF9,2)+COUNTIF(EL9,2)+COUNTIF(ER9,2)+COUNTIF(EX9,2)+COUNTIF(FD9,2)+COUNTIF(FJ9,2)+COUNTIF(FP9,2)+COUNTIF(FV9,2)+COUNTIF(GB9,2)+COUNTIF(GH9,2)+COUNTIF(GN9,2)+COUNTIF(GT9,2) -> 11 | K9: =COUNTIF(P9,1)+COUNTIF(V9,1)+COUNTIF(AB9,1)+COUNTIF(AH9,1)+COUNTIF(AN9,1)+COUNTIF(AT9,1)+COUNTIF(AZ9,1)+COUNTIF(BF9,1)+COUNTIF(BL9,1)+COUNTIF(BR9,1)+COUNTIF(BX9,1)+COUNTIF(CD9,1)+COUNTIF(CJ9,1)+COUNTIF(CP9,1)+COUNTIF(CV9,1)+COUNTIF(DB9,1)+COUNTIF(DH9,1)+COUNTIF(DN9,1)+COUNTIF(DT9,1)+COUNTIF(DZ9,1)+COUNTIF(EF9,1)+COUNTIF(EL9,1)+COUNTIF(ER9,1)+COUNTIF(EX9,1)+COUNTIF(FD9,1)+COUNTIF(FJ9,1)+COUNTIF(FP9,1)+COUNTIF(FV9,1)+COUNTIF(GB9,1)+COUNTIF(GH9,1)+COUNTIF(GN9,1)+COUNTIF(GT9,1) -> 0 | M9: 0 | N9: : | O9: 1 | P9: =IF(ISBLANK($E9),"",(IF(ISBLANK(M9),0,IF((($E9=M9)*($G9=O9))*NOT(ISBLANK($E9)),1,0)+((($E9>$G9)*(M9>O9))+(($E9<$G9)*(M9<O9))+(($E9=$G9)*(M9=O9)))-ISBLANK($E9)*(M9=O9)+(($E9-$G9)=(M9-O9))))) -> 0 | S9: 2 | T9: : | U9: 1 | V9: =IF(ISBLANK($E9),"",(IF(ISBLANK(S9),0,IF((($E9=S9)*($G9=U9))*NOT(ISBLANK($E9)),1,0)+((($E9>$G9)*(S9>U9))+(($E9<$G9)*(S9<U9))+(($E9=$G9)*(S9=U9)))-ISBLANK($E9)*(S9=U9)+(($E9-$G9)=(S9-U9))))) -> 0 | Y9: 1 | Z9: : | AA9: 2 | AB9: =IF(ISBLANK($E9),"",(IF(ISBLANK(Y9),0,IF((($E9=Y9)*($G9=AA9))*NOT(ISBLANK($E9)),1,0)+((($E9>$G9)*(Y9>AA9))+(($E9<$G9)*(Y9<AA9))+(($E9=$G9)*(Y9=AA9)))-ISBLANK($E9)*(Y9=AA9)+(($E9-$G9)=(Y9-AA9))))) -> 0 | AE9: 1 | AF9: : | AG9: 2 | AH9: =IF(ISBLANK($E9),"",(IF(ISBLANK(AE9),0,IF((($E9=AE9)*($G9=AG9))*NOT(ISBLANK($E9)),1,0)+((($E9>$G9)*(AE9>AG9))+(($E9<$G9)*(AE9<AG9))+(($E9=$G9)*(AE9=AG9)))-ISBLANK($E9)*(AE9=AG9)+(($E9-$G9)=(AE9-AG9))))) -> 0 | AK9: 1 | AL9: : | AM9: 1 | AN9: =IF(ISBLANK($E9),"",(IF(ISBLANK(AK9),0,IF((($E9=AK9)*($G9=AM9))*NOT(ISBLANK($E9)),1,0)+((($E9>$G9)*(AK9>AM9))+(($E9<$G9)*(AK9<AM9))+(($E9=$G9)*(AK9=AM9)))-ISBLANK($E9)*(AK9=AM9)+(($E9-$G9)=(AK9-AM9))))) -> 2 | AQ9: 1 | AR9: : | AS9: 2 | AT9: =IF(ISBLANK($E9),"",(IF(ISBLANK(AQ9),0,IF((($E9=AQ9)*($G9=AS9))*NOT(ISBLANK($E9)),1,0)+((($E9>$G9)*(AQ9>AS9))+(($E9<$G9)*(AQ9<AS9))+(($E9=$G9)*(AQ9=AS9)))-ISBLANK($E9)*(AQ9=AS9)+(($E9-$G9)=(AQ9-AS9))))) -> 0 | AW9: 1 | AX9: : | AY9: 1 | AZ9: =IF(ISBLANK($E9),"",(IF(ISBLANK(AW9),0,IF((($E9=AW9)*($G9=AY9))*NOT(ISBLANK($E9)),1,0)+((($E9>$G9)*(AW9>AY9))+(($E9<$G9)*(AW9<AY9))+(($E9=$G9)*(AW9=AY9)))-ISBLANK($E9)*(AW9=AY9)+(($E9-$G9)=(AW9-AY9))))) -> 2 | BC9: 1 | BD9: : | BE9: 2 | BF9: =IF(ISBLANK($E9),"",(IF(ISBLANK(BC9),0,IF((($E9=BC9)*($G9=BE9))*NOT(ISBLANK($E9)),1,0)+((($E9>$G9)*(BC9>BE9))+(($E9<$G9)*(BC9<BE9))+(($E9=$G9)*(BC9=BE9)))-ISBLANK($E9)*(BC9=BE9)+(($E9-$G9)=(BC9-BE9))))) -> 0 | BI9: 1 | BJ9: : | BK9: 1 | BL9: =IF(ISBLANK($E9),"",(IF(ISBLANK(BI9),0,IF((($E9=BI9)*($G9=BK9))*NOT(ISBLANK($E9)),1,0)+((($E9>$G9)*(BI9>BK9))+(($E9<$G9)*(BI9<BK9))+(($E9=$G9)*(BI9=BK9)))-ISBLANK($E9)*(BI9=BK9)+(($E9-$G9)=(BI9-BK9))))) -> 2 | BO9: 1 | BP9: : | BQ9: 1 | BR9: =IF(ISBLANK($E9),"",(IF(ISBLANK(BO9),0,IF((($E9=BO9)*($G9=BQ9))*NOT(ISBLANK($E9)),1,0)+((($E9>$G9)*(BO9>BQ9))+(($E9<$G9)*(BO9<BQ9))+(($E9=$G9)*(BO9=BQ9)))-ISBLANK($E9)*(BO9=BQ9)+(($E9-$G9)=(BO9-BQ9))))) -> 2 | BU9: 1 | BV9: : | BW9: 2 | BX9: =IF(ISBLANK($E9),"",(IF(ISBLANK(BU9),0,IF((($E9=BU9)*($G9=BW9))*NOT(ISBLANK($E9)),1,0)+((($E9>$G9)*(BU9>BW9))+(($E9<$G9)*(BU9<BW9))+(($E9=$G9)*(BU9=BW9)))-ISBLANK($E9)*(BU9=BW9)+(($E9-$G9)=(BU9-BW9))))) -> 0 | CA9: 1 | CB9: : | CC9: 2 | CD9: =IF(ISBLANK($E9),"",(IF(ISBLANK(CA9),0,IF((($E9=CA9)*($G9=CC9))*NOT(ISBLANK($E9)),1,0)+((($E9>$G9)*(CA9>CC9))+(($E9<$G9)*(CA9<CC9))+(($E9=$G9)*(CA9=CC9)))-ISBLANK($E9)*(CA9=CC9)+(($E9-$G9)=(CA9-CC9))))) -> 0 | CG9: 1 | CH9: : | CI9: 1 | CJ9: =IF(ISBLANK($E9),"",(IF(ISBLANK(CG9),0,IF((($E9=CG9)*($G9=CI9))*NOT(ISBLANK($E9)),1,0)+((($E9>$G9)*(CG9>CI9))+(($E9<$G9)*(CG9<CI9))+(($E9=$G9)*(CG9=CI9)))-ISBLANK($E9)*(CG9=CI9)+(($E9-$G9)=(CG9-CI9))))) -> 2 | CM9: 1 | CN9: : | CO9: 2 | CP9: =IF(ISBLANK($E9),"",(IF(ISBLANK(CM9),0,IF((($E9=CM9)*($G9=CO9))*NOT(ISBLANK($E9)),1,0)+((($E9>$G9)*(CM9>CO9))+(($E9<$G9)*(CM9<CO9))+(($E9=$G9)*(CM9=CO9)))-ISBLANK($E9)*(CM9=CO9)+(($E9-$G9)=(CM9-CO9))))) -> 0 | CS9: 1 | CT9: : | CU9: 1 | CV9: =IF(ISBLANK($E9),"",(IF(ISBLANK(CS9),0,IF((($E9=CS9)*($G9=CU9))*NOT(ISBLANK($E9)),1,0)+((($E9>$G9)*(CS9>CU9))+(($E9<$G9)*(CS9<CU9))+(($E9=$G9)*(CS9=CU9)))-ISBLANK($E9)*(CS9=CU9)+(($E9-$G9)=(CS9-CU9))))) -> 2 | CY9: 1 | CZ9: : | DA9: 2 | DB9: =IF(ISBLANK($E9),"",(IF(ISBLANK(CY9),0,IF((($E9=CY9)*($G9=DA9))*NOT(ISBLANK($E9)),1,0)+((($E9>$G9)*(CY9>DA9))+(($E9<$G9)*(CY9<DA9))+(($E9=$G9)*(CY9=DA9)))-ISBLANK($E9)*(CY9=DA9)+(($E9-$G9)=(CY9-DA9))))) -> 0 | DE9: 2 | DF9: : | DG9: 1 | DH9: =IF(ISBLANK($E9),"",(IF(ISBLANK(DE9),0,IF((($E9=DE9)*($G9=DG9))*NOT(ISBLANK($E9)),1,0)+((($E9>$G9)*(DE9>DG9))+(($E9<$G9)*(DE9<DG9))+(($E9=$G9)*(DE9=DG9)))-ISBLANK($E9)*(DE9=DG9)+(($E9-$G9)=(DE9-DG9))))) -> 0 | DK9: 1 | DL9: : | DM9: 2 | DN9: =IF(ISBLANK($E9),"",(IF(ISBLANK(DK9),0,IF((($E9=DK9)*($G9=DM9))*NOT(ISBLANK($E9)),1,0)+((($E9>$G9)*(DK9>DM9))+(($E9<$G9)*(DK9<DM9))+(($E9=$G9)*(DK9=DM9)))-ISBLANK($E9)*(DK9=DM9)+(($E9-$G9)=(DK9-DM9))))) -> 0 | DQ9: 1 | DR9: : | DS9: 2 | DT9: =IF(ISBLANK($E9),"",(IF(ISBLANK(DQ9),0,IF((($E9=DQ9)*($G9=DS9))*NOT(ISBLANK($E9)),1,0)+((($E9>$G9)*(DQ9>DS9))+(($E9<$G9)*(DQ9<DS9))+(($E9=$G9)*(DQ9=DS9)))-ISBLANK($E9)*(DQ9=DS9)+(($E9-$G9)=(DQ9-DS9))))) -> 0 | DW9: 1 | DX9: : | DY9: 2 | DZ9: =IF(ISBLANK($E9),"",(IF(ISBLANK(DW9),0,IF((($E9=DW9)*($G9=DY9))*NOT(ISBLANK($E9)),1,0)+((($E9>$G9)*(DW9>DY9))+(($E9<$G9)*(DW9<DY9))+(($E9=$G9)*(DW9=DY9)))-ISBLANK($E9)*(DW9=DY9)+(($E9-$G9)=(DW9-DY9))))) -> 0 | EC9: 0 | ED9: : | EE9: 1 | EF9: =IF(ISBLANK($E9),"",(IF(ISBLANK(EC9),0,IF((($E9=EC9)*($G9=EE9))*NOT(ISBLANK($E9)),1,0)+((($E9>$G9)*(EC9>EE9))+(($E9<$G9)*(EC9<EE9))+(($E9=$G9)*(EC9=EE9)))-ISBLANK($E9)*(EC9=EE9)+(($E9-$G9)=(EC9-EE9))))) -> 0 | EI9: 2 | EJ9: : | EK9: 2 | EL9: =IF(ISBLANK($E9),"",(IF(ISBLANK(EI9),0,IF((($E9=EI9)*($G9=EK9))*NOT(ISBLANK($E9)),1,0)+((($E9>$G9)*(EI9>EK9))+(($E9<$G9)*(EI9<EK9))+(($E9=$G9)*(EI9=EK9)))-ISBLANK($E9)*(EI9=EK9)+(($E9-$G9)=(EI9-EK9))))) -> 2 | EO9: 1 | EP9: : | EQ9: 2 | ER9: =IF(ISBLANK($E9),"",(IF(ISBLANK(EO9),0,IF((($E9=EO9)*($G9=EQ9))*NOT(ISBLANK($E9)),1,0)+((($E9>$G9)*(EO9>EQ9))+(($E9<$G9)*(EO9<EQ9))+(($E9=$G9)*(EO9=EQ9)))-ISBLANK($E9)*(EO9=EQ9)+(($E9-$G9)=(EO9-EQ9))))) -> 0 | EU9: 1 | EV9: : | EW9: 3 | EX9: =IF(ISBLANK($E9),"",(IF(ISBLANK(EU9),0,IF((($E9=EU9)*($G9=EW9))*NOT(ISBLANK($E9)),1,0)+((($E9>$G9)*(EU9>EW9))+(($E9<$G9)*(EU9<EW9))+(($E9=$G9)*(EU9=EW9)))-ISBLANK($E9)*(EU9=EW9)+(($E9-$G9)=(EU9-EW9))))) -> 0 | FA9: 1 | FB9: : | FC9: 1 | FD9: =IF(ISBLANK($E9),"",(IF(ISBLANK(FA9),0,IF((($E9=FA9)*($G9=FC9))*NOT(ISBLANK($E9)),1,0)+((($E9>$G9)*(FA9>FC9))+(($E9<$G9)*(FA9<FC9))+(($E9=$G9)*(FA9=FC9)))-ISBLANK($E9)*(FA9=FC9)+(($E9-$G9)=(FA9-FC9))))) -> 2 | FG9: 1 | FH9: : | FI9: 2 | FJ9: =IF(ISBLANK($E9),"",(IF(ISBLANK(FG9),0,IF((($E9=FG9)*($G9=FI9))*NOT(ISBLANK($E9)),1,0)+((($E9>$G9)*(FG9>FI9))+(($E9<$G9)*(FG9<FI9))+(($E9=$G9)*(FG9=FI9)))-ISBLANK($E9)*(FG9=FI9)+(($E9-$G9)=(FG9-FI9))))) -> 0 | FM9: 1 | FN9: : | FO9: 2 | FP9: =IF(ISBLANK($E9),"",(IF(ISBLANK(FM9),0,IF((($E9=FM9)*($G9=FO9))*NOT(ISBLANK($E9)),1,0)+((($E9>$G9)*(FM9>FO9))+(($E9<$G9)*(FM9<FO9))+(($E9=$G9)*(FM9=FO9)))-ISBLANK($E9)*(FM9=FO9)+(($E9-$G9)=(FM9-FO9))))) -> 0 | FS9: 1 | FT9: : | FU9: 1 | FV9: =IF(ISBLANK($E9),"",(IF(ISBLANK(FS9),0,IF((($E9=FS9)*($G9=FU9))*NOT(ISBLANK($E9)),1,0)+((($E9>$G9)*(FS9>FU9))+(($E9<$G9)*(FS9<FU9))+(($E9=$G9)*(FS9=FU9)))-ISBLANK($E9)*(FS9=FU9)+(($E9-$G9)=(FS9-FU9))))) -> 2 | FY9: 1 | FZ9: : | GA9: 2 | GB9: =IF(ISBLANK($E9),"",(IF(ISBLANK(FY9),0,IF((($E9=FY9)*($G9=GA9))*NOT(ISBLANK($E9)),1,0)+((($E9>$G9)*(FY9>GA9))+(($E9<$G9)*(FY9<GA9))+(($E9=$G9)*(FY9=GA9)))-ISBLANK($E9)*(FY9=GA9)+(($E9-$G9)=(FY9-GA9))))) -> 0 | GE9: 3 | GF9: : | GG9: 2 | GH9: =IF(ISBLANK($E9),"",(IF(ISBLANK(GE9),0,IF((($E9=GE9)*($G9=GG9))*NOT(ISBLANK($E9)),1,0)+((($E9>$G9)*(GE9>GG9))+(($E9<$G9)*(GE9<GG9))+(($E9=$G9)*(GE9=GG9)))-ISBLANK($E9)*(GE9=GG9)+(($E9-$G9)=(GE9-GG9))))) -> 0 | GK9: 1 | GL9: : | GM9: 1 | GN9: =IF(ISBLANK($E9),"",(IF(ISBLANK(GK9),0,IF((($E9=GK9)*($G9=GM9))*NOT(ISBLANK($E9)),1,0)+((($E9>$G9)*(GK9>GM9))+(($E9<$G9)*(GK9<GM9))+(($E9=$G9)*(GK9=GM9)))-ISBLANK($E9)*(GK9=GM9)+(($E9-$G9)=(GK9-GM9))))) -> 2 | GQ9: 2 | GR9: : | GS9: 2 | GT9: =IF(ISBLANK($E9),"",(IF(ISBLANK(GQ9),0,IF((($E9=GQ9)*($G9=GS9))*NOT(ISBLANK($E9)),1,0)+((($E9>$G9)*(GQ9>GS9))+(($E9<$G9)*(GQ9<GS9))+(($E9=$G9)*(GQ9=GS9)))-ISBLANK($E9)*(GQ9=GS9)+(($E9-$G9)=(GQ9-GS9))))) -> 2
